Workbook

Sheet 6月分配 
S1: 90天-6月需销售量 | W1: SP | AA1: TK
A3: 主SKU | B3: 商品名称 | D3: 国家 | E3: 品类 | F3: 三级分类 | G3: 销售成本 | H3: 当前库存 | I3: 日销量 | J3: 周转天数 | K3: 月预估超期库存 | L3: 月预估超期金额 | M3: 日销差距（50天） | N3: 预计出清数量（50天） | O3: 出清金额（3月） | P3: 日销差距（90天） | Q3: 预计出清数量（90天） | R3: 出清金额(6月） | S3: 总数量 | T3: 目标日销 | U3: 日销差异 | V3: 总出清金额 | W3: 业绩占比 | X3: 目标日销 | Y3: 总销量 | Z3: 出清额 | AA3: 业绩占比 | AB3: 目标日销 | AC3: 总销量 | AD3: 出清额度 | AE3: TK:备注 | AF3: SP:备注 | AG3: TK:第1周 | AH3: SP:第1周
A4: CC0283 | B4: 3B-便携式储能电源 | C4: 1 | D4: 马来 | E4: 办公安防 | F4: 便携储能电源 | G4: 173.4126 | H4: 1772 | I4: 13 | J4: 136 | K4: 1077 | L4: 232286 | M4: =(H4-(I4*50))/50 -> 22.44 | N4: =31*(M4+I4) -> 1098.64 | O4: =N4*G4 -> 190518.02 | P4: =(H4-(I4*90))/90 -> 6.6888889 | Q4: =31*(P4+I4) -> 610.35556 | R4: =(P4+I4)*31*G4*1.5 -> 158765.02 | S4: =Q4 -> 610.35556 | T4: =S4/31 -> 19.688889 | U4: =T4-I4 -> 6.6888889 | V4: =R4 -> 158765.02 | W4: =_xlfn.XLOOKUP(B4,Sheet5!G:G,Sheet5!H:H) -> 0.585 | X4: =Y4/31 -> 11.518 | Y4: =S4*W4 -> 357.058 | Z4: =Y4*G4*1.5 -> 92877.534 | AA4: =_xlfn.XLOOKUP(B4,Sheet5!G:G,Sheet5!I:I) -> 0.415 | AB4: =AC4/31 -> 8.1708889 | AC4: =S4*AA4 -> 253.29756 | AD4: =G4*AC4*1.5 -> 65887.482 | AE4: 重点： 全组进行推广，预估寄样数量40件，售后过不做降解动作 自营视频：雨前+伟民+罗城+心怡，每日发布数量1 | AF4: 全组重点下费用推品，每日现货开10个搭配光伏板 光伏板到货后补发，每人3条链接推品 | AG4: =$AC4/4 -> 63.324389 | AH4: =$Y4/4 -> 89.2645
A5: CC0282 | B5: 3B-保险箱黑50*35*30 | C5: 1 | D5: 马来 | E5: 办公安防 | F5: 保险箱 | G5: 209.88 | H5: 932 | I5: 6 | J5: 155 | K5: 627 | L5: 171787 | M5: =(H5-(I5*50))/50 -> 12.64 | N5: =31*(M5+I5) -> 577.84 | O5: =N5*G5 -> 121277.06 | P5: =(H5-(I5*90))/90 -> 4.3555556 | Q5: =31*(P5+I5) -> 321.02222 | R5: =(P5+I5)*31*G5*1.5 -> 101064.22 | S5: =Q5 -> 321.02222 | T5: =S5/31 -> 10.355556 | U5: =T5-I5 -> 4.3555556 | V5: =R5 -> 101064.22 | W5: =_xlfn.XLOOKUP(B5,Sheet5!G:G,Sheet5!H:H) -> 0.44 | X5: =Y5/31 -> 4.5564444 | Y5: =S5*W5 -> 141.24978 | Z5: =Y5*G5*1.5 -> 44468.255 | AA5: =_xlfn.XLOOKUP(B5,Sheet5!G:G,Sheet5!I:I) -> 0.56 | AB5: =AC5/31 -> 5.7991111 | AC5: =S5*AA5 -> 179.77244 | AD5: =G5*AC5*1.5 -> 56595.961 | AE5: 重点： 全组进行推广，预估寄样数量30件，售后过不做降解动作 自营视频：雨前+伟民+罗城+心怡，每日发布数量2 | AF5: 全组重点下费用推品，搭配灭款锁呆滞品出清 标价对标竞品下调至42% | AG5: =AC5/4 -> 44.943111 | AH5: =$Y5/4 -> 35.312444
A6: CC0462 | B6: 3B-X1指纹考勤机 | C6: 1 | D6: 马来 | E6: 办公安防 | F6: 考勤机 | G6: 76.15 | H6: 2252 | I6: 13 | J6: 173 | K6: 1557 | L6: 156679 | M6: =(H6-(I6*50))/50 -> 32.04 | N6: =31*(M6+I6) -> 1396.24 | O6: =N6*G6 -> 106323.68 | P6: =(H6-(I6*90))/90 -> 12.022222 | Q6: =31*(P6+I6) -> 775.68889 | R6: =(P6+I6)*31*G6*1.5 -> 88603.063 | S6: =Q6 -> 775.68889 | T6: =S6/31 -> 25.022222 | U6: =T6-I6 -> 12.022222 | V6: =R6 -> 88603.063 | W6: =_xlfn.XLOOKUP(B6,Sheet5!G:G,Sheet5!H:H) -> 0.48125 | X6: =Y6/31 -> 12.041944 | Y6: =S6*W6 -> 373.30028 | Z6: =Y6*G6*1.5 -> 42640.224 | AA6: =_xlfn.XLOOKUP(B6,Sheet5!G:G,Sheet5!I:I) -> 0.51875 | AB6: =AC6/31 -> 12.980278 | AC6: =S6*AA6 -> 402.38861 | AD6: =G6*AC6*1.5 -> 45962.839 | AE6: 重点： 分人进行推广，预估寄样数量50件，广告投入加大 人员：伟民+罗城+心怡 | AF6: 孝鑫+荣锦重点下费用推品 每日对标竞品低价限量4个出清 | AG6: =AC6/4 -> 100.59715 | AH6: =$Y6/4 -> 93.325069
A7: CC0764 | B7: 3C-无弦吉他 | C7: 1 | D7: 马来 | E7: 3C数码 | F7: 未来吉他 | G7: 713.37 | H7: 171 | I7: 1 | J7: 171 | K7: 115 | L7: 107362 | M7: =(H7-(I7*50))/50 -> 2.42 | N7: =31*(M7+I7) -> 106.02 | O7: =N7*G7 -> 75631.487 | P7: =(H7-(I7*90))/90 -> 0.9 | Q7: =31*(P7+I7) -> 58.9 | R7: =(P7+I7)*31*G7*1.5 -> 63026.24 | S7: =Q7 -> 58.9 | T7: =S7/31 -> 1.9 | U7: =T7-I7 -> 0.9 | V7: =R7 -> 63026.24 | W7: =_xlfn.XLOOKUP(B7,Sheet5!G:G,Sheet5!H:H) -> 0.16666667 | X7: =Y7/31 -> 0.31666667 | Y7: =S7*W7 -> 9.8166667 | Z7: =Y7*G7*1.5 -> 10504.373 | AA7: =_xlfn.XLOOKUP(B7,Sheet5!G:G,Sheet5!I:I) -> 0.83333333 | AB7: =AC7/31 -> 1.5833333 | AC7: =S7*AA7 -> 49.083333 | AD7: =G7*AC7*1.5 -> 52521.866 | AE7: 重点： 分人进行推广，预估寄样数量5-8件，广告投入加大，原价进工资活动。 人员：心怡+伟铭 | AF7: 全组下费用推品，市场体量小 联盟佣金方面会上调至12%尝试 | AG7: =AC7/4 -> 12.270833 | AH7: =$Y7/4 -> 2.4541667
A8: CC0711 | B8: 3B-点钞机灰色 | C8: 1 | D8: 马来 | E8: 办公安防 | F8: 点钞机 | G8: 213.2736 | H8: 1075 | I8: 13 | J8: 82 | K8: 390 | L8: 83177 | M8: =(H8-(I8*50))/50 -> 8.5 | N8: =31*(M8+I8) -> 666.5 | O8: =N8*G8 -> 142146.85 | P8: =(H8-(I8*90))/90 -> -1.0555556 | Q8: =31*(P8+I8) -> 370.27778 | R8: =(P8+I8)*31*G8*1.5 -> 118455.71 | S8: =Q8 -> 370.27778 | T8: =S8/31 -> 11.944444 | U8: =T8-I8 -> -1.0555556 | V8: =R8 -> 118455.71 | W8: =_xlfn.XLOOKUP(B8,Sheet5!G:G,Sheet5!H:H) -> 0.33544304 | X8: =Y8/31 -> 4.0066807 | Y8: =S8*W8 -> 124.2071 | Z8: =Y8*G8*1.5 -> 39735.144 | AA8: =_xlfn.XLOOKUP(B8,Sheet5!G:G,Sheet5!I:I) -> 0.66455696 | AB8: =AC8/31 -> 7.9377637 | AC8: =S8*AA8 -> 246.07068 | AD8: =G8*AC8*1.5 -> 78720.568 | AE8: 重点： 分人进行推广，预估寄样数量10-15件，广告投入加大，原价进工资活动。 人员：罗城+伟民 | AG8: =AC8/4 -> 61.517669 | AH8: =$Y8/4 -> 31.051776
A9: CC0780 | B9: 3C-折叠带蓝牙带琴谱架电子琴61键 | C9: 1 | D9: 马来 | E9: 3C数码 | F9: 电子琴 | G9: 163.992 | H9: 276 | I9: 1 | J9: 276 | K9: 218 | L9: 49772 | M9: =(H9-(I9*50))/50 -> 4.52 | N9: =31*(M9+I9) -> 171.12 | O9: =N9*G9 -> 28062.311 | P9: =(H9-(I9*90))/90 -> 2.0666667 | Q9: =31*(P9+I9) -> 95.066667 | R9: =(P9+I9)*31*G9*1.5 -> 23385.259 | S9: =Q9 -> 95.066667 | T9: =S9/31 -> 3.0666667 | U9: =T9-I9 -> 2.0666667 | V9: =R9 -> 23385.259 | W9: =_xlfn.XLOOKUP(B9,Sheet5!G:G,Sheet5!H:H) -> 0.375 | X9: =Y9/31 -> 1.15 | Y9: =S9*W9 -> 35.65 | Z9: =Y9*G9*1.5 -> 8769.4722 | AA9: =_xlfn.XLOOKUP(B9,Sheet5!G:G,Sheet5!I:I) -> 0.625 | AB9: =AC9/31 -> 1.9166667 | AC9: =S9*AA9 -> 59.416667 | AD9: =G9*AC9*1.5 -> 14615.787 | AE9: 重点： 分人进行推广，预估寄样数量10-15件，广告投入加大，原价进工资活动。 人员：雨倩+伟铭 | AF9: 全组下费用推品，培庆每日限量3个对标竞品28%标价 | AG9: =AC9/4 -> 14.854167 | AH9: =$Y9/4 -> 8.9125
A10: CC0514 | B10: 3B-路由器P6000白色 | C10: 1 | D10: 马来 | E10: 办公安防 | F10: 路由器 | G10: 93.44 | H10: 363 | K10: 340 | L10: 46767 | M10: =(H10-(I10*50))/50 -> 7.26 | N10: =31*(M10+I10) -> 225.06 | O10: =N10*G10 -> 21029.606 | P10: =(H10-(I10*90))/90 -> 4.0333333 | Q10: =31*(P10+I10) -> 125.03333 | R10: =(P10+I10)*31*G10*1.5 -> 17524.672 | S10: =Q10 -> 125.03333 | T10: =S10/31 -> 4.0333333 | U10: =T10-I10 -> 4.0333333 | V10: =R10 -> 17524.672 | W10: =_xlfn.XLOOKUP(B10,Sheet5!G:G,Sheet5!H:H) -> 1 | X10: =Y10/31 -> 4.0333333 | Y10: =S10*W10 -> 125.03333 | Z10: =Y10*G10*1.5 -> 17524.672 | AA10: =_xlfn.XLOOKUP(B10,Sheet5!G:G,Sheet5!I:I) -> 0 | AB10: =AC10/31 -> 0 | AC10: =S10*AA10 -> 0 | AD10: =G10*AC10*1.5 -> 0 | AE10: 无法上架，暂不规划，可以送达人5个 | AF10: 无法上架，尝试搭配交换机出清 | AG10: =AC10/4 -> 0 | AH10: =$Y10/4 -> 31.258333
A11: CC0739 | B11: 3B-液晶面板保险柜45cm*38cm*30cm | C11: 1 | D11: 马来 | E11: 办公安防 | F11: 保险箱 | G11: 276.9564 | H11: 197 | I11: 1 | J11: 197 | K11: 126 | L11: 44452 | M11: =(H11-(I11*50))/50 -> 2.94 | N11: =31*(M11+I11) -> 122.14 | O11: =N11*G11 -> 33827.455 | P11: =(H11-(I11*90))/90 -> 1.1888889 | Q11: =31*(P11+I11) -> 67.855556 | R11: =(P11+I11)*31*G11*1.5 -> 28189.546 | S11: =Q11 -> 67.855556 | T11: =S11/31 -> 2.1888889 | U11: =T11-I11 -> 1.1888889 | V11: =R11 -> 28189.546 | W11: =_xlfn.XLOOKUP(B11,Sheet5!G:G,Sheet5!H:H) -> 0.52173913 | X11: =Y11/31 -> 1.142029 | Y11: =S11*W11 -> 35.402899 | Z11: =Y11*G11*1.5 -> 14707.589 | AA11: =_xlfn.XLOOKUP(B11,Sheet5!G:G,Sheet5!I:I) -> 0.47826087 | AB11: =AC11/31 -> 1.0468599 | AC11: =S11*AA11 -> 32.452657 | AD11: =G11*AC11*1.5 -> 13481.957 | AE11: 重点： 全组进行推广，预估寄样数量10件 自营视频：罗城+心怡，每日发布数量1 | AF11: 全组重点下费用推品 | AG11: =AC11/4 -> 8.1131643 | AH11: =$Y11/4 -> 8.8507246
A12: CC1048 | B12: 3C-高亮自动对焦灯带投影仪Z300 | C12: 1 | D12: 马来 | E12: 3C数码 | F12: 家用音视频设备*投影仪 | G12: 404.3828 | H12: 77 | K12: 69 | L12: 40438 | M12: =(H12-(I12*50))/50 -> 1.54 | N12: =31*(M12+I12) -> 47.74 | O12: =N12*G12 -> 19305.235 | P12: =(H12-(I12*90))/90 -> 0.85555556 | Q12: =31*(P12+I12) -> 26.522222 | R12: =(P12+I12)*31*G12*1.5 -> 16087.696 | S12: =Q12 -> 26.522222 | T12: =S12/31 -> 0.85555556 | U12: =T12-I12 -> 0.85555556 | V12: =R12 -> 16087.696 | W12: =_xlfn.XLOOKUP(B12,Sheet5!G:G,Sheet5!H:H) -> 0 | X12: =Y12/31 -> 0 | Y12: =S12*W12 -> 0 | Z12: =Y12*G12*1.5 -> 0 | AA12: =_xlfn.XLOOKUP(B12,Sheet5!G:G,Sheet5!I:I) -> 1 | AB12: =AC12/31 -> 0.85555556 | AC12: =S12*AA12 -> 26.522222 | AD12: =G12*AC12*1.5 -> 16087.696 | AE12: 重点： 全组进行推广，预估寄样数量8件 | AF12: 全组下费用推品，投影仪+幕布+支架组合出售 | AG12: =AC12/4 -> 6.6305556 | AH12: =$Y12/4 -> 0
A13: CC0706 | B13: 3C-32英寸到55英寸带中托可移动电视支架 | C13: 1 | D13: 马来 | E13: 3C数码 | F13: 电视支架 | G13: 123.29 | H13: 463 | I13: 4 | J13: 115 | K13: 263 | L13: 38775 | M13: =(H13-(I13*50))/50 -> 5.26 | N13: =31*(M13+I13) -> 287.06 | O13: =N13*G13 -> 35391.627 | P13: =(H13-(I13*90))/90 -> 1.1444444 | Q13: =31*(P13+I13) -> 159.47778 | R13: =(P13+I13)*31*G13*1.5 -> 29493.023 | S13: =Q13 -> 159.47778 | T13: =S13/31 -> 5.1444444 | U13: =T13-I13 -> 1.1444444 | V13: =R13 -> 29493.023 | W13: 0.45 | X13: =Y13/31 -> 2.315 | Y13: =S13*W13 -> 71.765 | Z13: =Y13*G13*1.5 -> 13271.86 | AA13: 0.55 | AB13: =AC13/31 -> 2.8294444 | AC13: =S13*AA13 -> 87.712778 | AD13: =G13*AC13*1.5 -> 16221.163 | AE13: 重点： 寄样20个，主要是产品售后配件缺失的问题，成本上涨。 人员：伟民+伟铭 | AF13: 该品后续转为平销款，本月重点下调价格 另一款双层移动推车MY1700PJ作为链接主推 鹭燕小店重点给优势扶持 | AG13: =AC13/4 -> 21.928194 | AH13: =$Y13/4 -> 17.94125
A14: CC0979 | B14: 3B-XT保险箱45*38*32cm灰白色密码款 | C14: 1 | D14: 马来 | E14: 办公安防 | F14: 保险柜 | G14: 271.8192 | H14: 96 | K14: 91 | L14: 36560 | M14: =(H14-(I14*50))/50 -> 1.92 | N14: =31*(M14+I14) -> 59.52 | O14: =N14*G14 -> 16178.679 | P14: =(H14-(I14*90))/90 -> 1.0666667 | Q14: =31*(P14+I14) -> 33.066667 | R14: =(P14+I14)*31*G14*1.5 -> 13482.232 | S14: =Q14 -> 33.066667 | T14: =S14/31 -> 1.0666667 | U14: =T14-I14 -> 1.0666667 | V14: =R14 -> 13482.232 | W14: =_xlfn.XLOOKUP(B14,Sheet5!G:G,Sheet5!H:H) -> 0 | X14: =Y14/31 -> 0 | Y14: =S14*W14 -> 0 | Z14: =Y14*G14*1.5 -> 0 | AA14: =_xlfn.XLOOKUP(B14,Sheet5!G:G,Sheet5!I:I) -> 0 | AB14: =AC14/31 -> 0 | AC14: =S14*AA14 -> 0 | AD14: =G14*AC14*1.5 -> 0 | AE14: 重点： 全组进行推广，预估寄样数量5-8件 自营视频：罗城+心怡，每日发布数量1 | AF14: 全组重点下费用推品 | AG14: =AC14/4 -> 0 | AH14: =$Y14/4 -> 0
A15: CC0898 | B15: 3B-液晶面板保险柜密码A15款 | C15: 1 | D15: 马来 | E15: 办公安防 | F15: 保险箱 | G15: 232.7064 | H15: 207 | I15: 1 | J15: 207 | K15: 111 | L15: 29786 | M15: =(H15-(I15*50))/50 -> 3.14 | N15: =31*(M15+I15) -> 128.34 | O15: =N15*G15 -> 29865.539 | P15: =(H15-(I15*90))/90 -> 1.3 | Q15: =31*(P15+I15) -> 71.3 | R15: =(P15+I15)*31*G15*1.5 -> 24887.949 | S15: =Q15 -> 71.3 | T15: =S15/31 -> 2.3 | U15: =T15-I15 -> 1.3 | V15: =R15 -> 24887.949 | W15: =_xlfn.XLOOKUP(B15,Sheet5!G:G,Sheet5!H:H) -> 0.39473684 | X15: =Y15/31 -> 0.90789474 | Y15: =S15*W15 -> 28.144737 | Z15: =Y15*G15*1.5 -> 9824.1906 | AA15: =_xlfn.XLOOKUP(B15,Sheet5!G:G,Sheet5!I:I) -> 0.60526316 | AB15: =AC15/31 -> 1.3921053 | AC15: =S15*AA15 -> 43.155263 | AD15: =G15*AC15*1.5 -> 15063.759 | AE15: 无超期风险： 全组正常推 | AF15: 全组重点下费用推品 | AG15: =AC15/4 -> 10.788816 | AH15: =$Y15/4 -> 7.0361842
A16: CC0980 | B16: 3B-XT保险箱45*38*32cm灰白色指纹款 | C16: 1 | D16: 马来 | E16: 办公安防 | F16: 保险柜 | G16: 333.7692 | H16: 84 | K16: 63 | L16: 28704 | M16: =(H16-(I16*50))/50 -> 1.68 | N16: =31*(M16+I16) -> 52.08 | O16: z | P16: =(H16-(I16*90))/90 -> 0.93333333 | Q16: =31*(P16+I16) -> 28.933333 | R16: =(P16+I16)*31*G16*1.5 -> 14485.583 | S16: =Q16 -> 28.933333 | T16: =S16/31 -> 0.93333333 | U16: =T16-I16 -> 0.93333333 | V16: =R16 -> 14485.583 | W16: =_xlfn.XLOOKUP(B16,Sheet5!G:G,Sheet5!H:H) -> 0.6 | X16: =Y16/31 -> 0.56 | Y16: =S16*W16 -> 17.36 | Z16: =Y16*G16*1.5 -> 8691.35 | AA16: =_xlfn.XLOOKUP(B16,Sheet5!G:G,Sheet5!I:I) -> 0.4 | AB16: =AC16/31 -> 0.37333333 | AC16: =S16*AA16 -> 11.573333 | AD16: =G16*AC16*1.5 -> 5794.2333 | AE16: 目前不会超期，和密码的动作一致 | AF16: 全组重点下费用推品 | AG16: =AC16/4 -> 2.8933333 | AH16: =$Y16/4 -> 4.34
A17: CC0177 | B17: 3B-300CWiFi路由器 | C17: 1 | D17: 马来 | E17: 办公安防 | F17: 路由器 | G17: 127.34 | H17: 136 | K17: 136 | L17: 25977 | M17: =(H17-(I17*50))/50 -> 2.72 | N17: =31*(M17+I17) -> 84.32 | O17: =N17*G17 -> 10737.309 | P17: =(H17-(I17*90))/90 -> 1.5111111 | Q17: =31*(P17+I17) -> 46.844444 | R17: =(P17+I17)*31*G17*1.5 -> 8947.7573 | S17: =Q17 -> 46.844444 | T17: =S17/31 -> 1.5111111 | U17: =T17-I17 -> 1.5111111 | V17: =R17 -> 8947.7573 | W17: =_xlfn.XLOOKUP(B17,Sheet5!G:G,Sheet5!H:H) -> 0 | X17: =Y17/31 -> 0 | Y17: =S17*W17 -> 0 | Z17: =Y17*G17*1.5 -> 0 | AA17: =_xlfn.XLOOKUP(B17,Sheet5!G:G,Sheet5!I:I) -> 0 | AB17: =AC17/31 -> 0 | AC17: =S17*AA17 -> 0 | AD17: =G17*AC17*1.5 -> 0 | AE17: 无法上架，暂不规划，可以送达人5个 | AF17: 无法上架，尝试搭配交换机出清 | AG17: =AC17/4 -> 0 | AH17: =$Y17/4 -> 0
A18: CC0634 | B18: 3C-电子琴61健黑色 | C18: 1 | D18: 马来 | E18: 3C数码 | F18: 电子琴 | G18: 39.9772 | H18: 806 | I18: 6 | J18: 134 | K18: 493 | L18: 24546 | M18: =(H18-(I18*50))/50 -> 10.12 | N18: =31*(M18+I18) -> 499.72 | O18: =N18*G18 -> 19977.406 | P18: =(H18-(I18*90))/90 -> 2.9555556 | Q18: =31*(P18+I18) -> 277.62222 | R18: =(P18+I18)*31*G18*1.5 -> 16647.839 | S18: =Q18 -> 277.62222 | T18: =S18/31 -> 8.9555556 | U18: =T18-I18 -> 2.9555556 | V18: =R18 -> 16647.839 | W18: =_xlfn.XLOOKUP(B18,Sheet5!G:G,Sheet5!H:H) -> 0.61728395 | X18: =Y18/31 -> 5.5281207 | Y18: =S18*W18 -> 171.37174 | Z18: =Y18*G18*1.5 -> 10276.444 | AA18: =_xlfn.XLOOKUP(B18,Sheet5!G:G,Sheet5!I:I) -> 0.38271605 | AB18: =AC18/31 -> 3.4274348 | AC18: =S18*AA18 -> 106.25048 | AD18: =G18*AC18*1.5 -> 6371.395 | AE18: 超期： 导致已经控在22% | AF18: 对标竞品价格36%标价正常销售 | AG18: =AC18/4 -> 26.56262 | AH18: =$Y18/4 -> 42.842936
A19: CC1046 | B19: 3C-电视移动推车支架TG11 | C19: 1 | D19: 马来 | E19: 3C数码 | F19: 电视支架 | G19: 150.11 | H19: 116 | K19: 110 | L19: 24393 | M19: =(H19-(I19*50))/50 -> 2.32 | N19: =31*(M19+I19) -> 71.92 | O19: =N19*G19 -> 10795.911 | P19: =(H19-(I19*90))/90 -> 1.2888889 | Q19: =31*(P19+I19) -> 39.955556 | R19: =(P19+I19)*31*G19*1.5 -> 8996.5927 | S19: =Q19 -> 39.955556 | T19: =S19/31 -> 1.2888889 | U19: =T19-I19 -> 1.2888889 | V19: =R19 -> 8996.5927 | W19: =_xlfn.XLOOKUP(B19,Sheet5!G:G,Sheet5!H:H) -> 0 | X19: =Y19/31 -> 0 | Y19: =S19*W19 -> 0 | Z19: =Y19*G19*1.5 -> 0 | AA19: =_xlfn.XLOOKUP(B19,Sheet5!G:G,Sheet5!I:I) -> 1 | AB19: =AC19/31 -> 1.2888889 | AC19: =S19*AA19 -> 39.955556 | AD19: =G19*AC19*1.5 -> 8996.5927 | AE19: 新品： 寄样10个，正常推品 人员：伟民+伟铭 | AF19: 月底刚到，正常下费用插入老链接推品 鹭燕小店重点给优势扶持 | AG19: =AC19/4 -> 9.9888889 | AH19: =$Y19/4 -> 0
A20: CC0906 | B20: 3B-磁吸白板密度板夹层90cm*150cm | C20: 1 | D20: 马来 | E20: 办公安防 | F20: 白板 | G20: 87.6789 | H20: 516 | I20: 5 | J20: 103 | K20: 250 | L20: 23542 | M20: =(H20-(I20*50))/50 -> 5.32 | N20: =31*(M20+I20) -> 319.92 | O20: =N20*G20 -> 28050.234 | P20: =(H20-(I20*90))/90 -> 0.73333333 | Q20: =31*(P20+I20) -> 177.73333 | R20: =(P20+I20)*31*G20*1.5 -> 23375.195 | S20: =Q20 -> 177.73333 | T20: =S20/31 -> 5.7333333 | U20: =T20-I20 -> 0.73333333 | V20: =R20 -> 23375.195 | W20: =_xlfn.XLOOKUP(B20,Sheet5!G:G,Sheet5!H:H) -> 0.88405797 | X20: =Y20/31 -> 5.068599 | Y20: =S20*W20 -> 157.12657 | Z20: =Y20*G20*1.5 -> 20665.027 | AA20: =_xlfn.XLOOKUP(B20,Sheet5!G:G,Sheet5!I:I) -> 0.11594203 | AB20: =AC20/31 -> 0.6647343 | AC20: =S20*AA20 -> 20.606763 | AD20: =G20*AC20*1.5 -> 2710.1675 | AE20: 占比过小，正常销售 | AG20: =AC20/4 -> 5.1516908 | AH20: =$Y20/4 -> 39.281643
A21: CC0672 | B21: 3B-仿真书银钱盒钥匙款蓝色 | C21: 1 | D21: 马来 | E21: 办公安防 | F21: 银钱盒 | G21: 18.8293 | H21: 1260 | I21: 7 | J21: 180 | K21: 887 | L21: 22237 | M21: =(H21-(I21*50))/50 -> 18.2 | N21: =31*(M21+I21) -> 781.2 | O21: =N21*G21 -> 14709.449 | P21: =(H21-(I21*90))/90 -> 7 | Q21: =31*(P21+I21) -> 434 | R21: =(P21+I21)*31*G21*1.5 -> 12257.874 | S21: =Q21 -> 434 | T21: =S21/31 -> 14 | U21: =T21-I21 -> 7 | V21: =R21 -> 12257.874 | W21: =_xlfn.XLOOKUP(B21,Sheet5!G:G,Sheet5!H:H) -> 0.41558442 | X21: =Y21/31 -> 5.8181818 | Y21: =S21*W21 -> 180.36364 | Z21: 60 | AA21: =_xlfn.XLOOKUP(B21,Sheet5!G:G,Sheet5!I:I) -> 0.58441558 | AB21: =AC21/31 -> 8.1818182 | AC21: =S21*AA21 -> 253.63636 | AD21: =G21*AC21*1.5 -> 7163.6928 | AE21: 重点： 阶段降解消耗，周转控制在60 人员：心怡 | AF21: 小店重点价格扶持起量 孝鑫+鹭燕 | AG21: =AC21/4 -> 63.409091 | AH21: =$Y21/4 -> 45.090909
A22: CC0781 | B22: 3C-折叠带蓝牙带琴谱架电子琴88键 | C22: 1 | D22: 马来 | E22: 3C数码 | F22: 电子琴 | G22: 233.6648 | H22: 241 | I22: 2 | J22: 120 | K22: 95 | L22: 22198 | M22: =(H22-(I22*50))/50 -> 2.82 | N22: =31*(M22+I22) -> 149.42 | O22: =N22*G22 -> 34914.194 | P22: =(H22-(I22*90))/90 -> 0.67777778 | Q22: =31*(P22+I22) -> 83.011111 | R22: =(P22+I22)*31*G22*1.5 -> 29095.162 | S22: =Q22 -> 83.011111 | T22: =S22/31 -> 2.6777778 | U22: =T22-I22 -> 0.67777778 | V22: =R22 -> 29095.162 | W22: =_xlfn.XLOOKUP(B22,Sheet5!G:G,Sheet5!H:H) -> 0.38461538 | X22: =Y22/31 -> 1.0299145 | Y22: =S22*W22 -> 31.92735 | Z22: =Y22*G22*1.5 -> 11190.447 | AA22: =_xlfn.XLOOKUP(B22,Sheet5!G:G,Sheet5!I:I) -> 0.61538462 | AB22: =AC22/31 -> 1.6478632 | AC22: =S22*AA22 -> 51.083761 | AD22: =G22*AC22*1.5 -> 17904.715 | AE22: 无超期风险 | AF22: 对标竞品价格36%标价正常销售 | AG22: =AC22/4 -> 12.77094 | AH22: =$Y22/4 -> 7.9818376
A23: CC0342 | B23: 3B-保险柜100cm*51cm*45cm | C23: 1 | D23: 马来 | E23: 办公安防 | F23: 保险箱 | G23: 896.77 | H23: 33 | K23: 20 | L23: 21971 | M23: =(H23-(I23*50))/50 -> 0.66 | N23: =31*(M23+I23) -> 20.46 | O23: =N23*G23 -> 18347.914 | P23: =(H23-(I23*90))/90 -> 0.36666667 | Q23: =31*(P23+I23) -> 11.366667 | R23: =(P23+I23)*31*G23*1.5 -> 15289.928 | S23: =Q23 -> 11.366667 | T23: =S23/31 -> 0.36666667 | U23: =T23-I23 -> 0.36666667 | V23: =R23 -> 15289.928 | W23: 0.5 | X23: =Y23/31 -> 0.18333333 | Y23: =S23*W23 -> 5.6833333 | Z23: =Y23*G23*1.5 -> 7644.9642 | AA23: 0.5 | AB23: =AC23/31 -> 0.18333333 | AC23: =S23*AA23 -> 5.6833333 | AD23: =G23*AC23*1.5 -> 7644.9642 | AE23: 呆滞品：清除3个 成本价销售进行销售。费用进行寄样 | AF23: 正常出清，标价34%利润出清，预计本月消耗10个 | AG23: =AC23/4 -> 1.4208333 | AH23: =$Y23/4 -> 1.4208333
A24: CC0732 | B24: 3B-橡胶磁白板背胶90cm*180cm | C24: 1 | D24: 马来 | E24: 办公安防 | F24: 白板 | G24: 67.2831 | H24: 351 | I24: 2 | J24: 175 | K24: 241 | L24: 21362 | M24: =(H24-(I24*50))/50 -> 5.02 | N24: =31*(M24+I24) -> 217.62 | O24: =N24*G24 -> 14642.148 | P24: =(H24-(I24*90))/90 -> 1.9 | Q24: =31*(P24+I24) -> 120.9 | R24: =(P24+I24)*31*G24*1.5 -> 12201.79 | S24: =Q24 -> 120.9 | T24: =S24/31 -> 3.9 | U24: =T24-I24 -> 1.9 | V24: =R24 -> 12201.79 | W24: =_xlfn.XLOOKUP(B24,Sheet5!G:G,Sheet5!H:H) -> 0.78125 | X24: =Y24/31 -> 3.046875 | Y24: =S24*W24 -> 94.453125 | Z24: =Y24*G24*1.5 -> 9532.6486 | AA24: =_xlfn.XLOOKUP(B24,Sheet5!G:G,Sheet5!I:I) -> 0.21875 | AB24: =AC24/31 -> 0.853125 | AC24: =S24*AA24 -> 26.446875 | AD24: =G24*AC24*1.5 -> 2669.1416 | AE24: 新品： 降价 | AG24: =AC24/4 -> 6.6117187 | AH24: =$Y24/4 -> 23.613281
A25: CC0278 | B25: 3B-智能指纹门锁X7 | C25: 1 | D25: 马来 | E25: 办公安防 | F25: 指纹锁 | G25: 93.9397 | H25: 708 | I25: 9 | J25: 78 | K25: 225 | L25: 21136 | M25: =(H25-(I25*50))/50 -> 5.16 | N25: =31*(M25+I25) -> 438.96 | O25: =N25*G25 -> 41235.771 | P25: =(H25-(I25*90))/90 -> -1.1333333 | Q25: =31*(P25+I25) -> 243.86667 | R25: =(P25+I25)*31*G25*1.5 -> 34363.142 | S25: =Q25 -> 243.86667 | T25: =S25/31 -> 7.8666667 | U25: =T25-I25 -> -1.1333333 | V25: =R25 -> 34363.142 | W25: =_xlfn.XLOOKUP(B25,Sheet5!G:G,Sheet5!H:H) -> 0.29090909 | X25: =Y25/31 -> 2.2884848 | Y25: =S25*W25 -> 70.94303 | Z25: =Y25*G25*1.5 -> 9996.5505 | AA25: =_xlfn.XLOOKUP(B25,Sheet5!G:G,Sheet5!I:I) -> 0.70909091 | AB25: =AC25/31 -> 5.5781818 | AC25: =S25*AA25 -> 172.92364 | AD25: =G25*AC25*1.5 -> 24366.592 | AE25: 无超期风险 | AG25: =AC25/4 -> 43.230909 | AH25: =$Y25/4 -> 17.735758
A26: CC0860 | B26: 3C-辉光管 | C26: 1 | D26: 马来 | E26: 3C数码 | F26: 辉光管 | G26: 203.25 | H26: 74 | K26: 69 | L26: 20630 | M26: =(H26-(I26*50))/50 -> 1.48 | N26: =31*(M26+I26) -> 45.88 | O26: =N26*G26 -> 9325.11 | P26: =(H26-(I26*90))/90 -> 0.82222222 | Q26: =31*(P26+I26) -> 25.488889 | R26: =(P26+I26)*31*G26*1.5 -> 7770.925 | S26: =Q26 -> 25.488889 | T26: =S26/31 -> 0.82222222 | U26: =T26-I26 -> 0.82222222 | V26: =R26 -> 7770.925 | W26: =_xlfn.XLOOKUP(B26,Sheet5!G:G,Sheet5!H:H) -> 0 | X26: =Y26/31 -> 0 | Y26: =S26*W26 -> 0 | Z26: =Y26*G26*1.5 -> 0 | AA26: =_xlfn.XLOOKUP(B26,Sheet5!G:G,Sheet5!I:I) -> 1 | AB26: =AC26/31 -> 0.82222222 | AC26: =S26*AA26 -> 25.488889 | AD26: =G26*AC26*1.5 -> 7770.925 | AE26: 呆滞品：消耗15个 毛利15%销售。 人员：罗城+心怡 | AF26: 暂不规划 | AG26: =AC26/4 -> 6.3722222 | AH26: =$Y26/4 -> 0
A27: CC0904 | B27: 3B-磁吸白板密度板夹层70cm*100cm | C27: 1 | D27: 马来 | E27: 办公安防 | F27: 白板 | G27: 43.1968 | H27: 1825 | I27: 27 | J27: 67 | K27: 465 | L27: 20087 | M27: =(H27-(I27*50))/50 -> 9.5 | N27: =31*(M27+I27) -> 1131.5 | O27: =N27*G27 -> 48877.179 | P27: =(H27-(I27*90))/90 -> -6.7222222 | Q27: =31*(P27+I27) -> 628.61111 | R27: =(P27+I27)*31*G27*1.5 -> 40730.983 | S27: =Q27 -> 628.61111 | T27: =S27/31 -> 20.277778 | U27: =T27-I27 -> -6.7222222 | V27: =R27 -> 40730.983 | W27: =_xlfn.XLOOKUP(B27,Sheet5!G:G,Sheet5!H:H) -> 0.71549296 | X27: =Y27/31 -> 14.508607 | Y27: =S27*W27 -> 449.76682 | Z27: =Y27*G27*1.5 -> 29142.731 | AA27: =_xlfn.XLOOKUP(B27,Sheet5!G:G,Sheet5!I:I) -> 0.28450704 | AB27: =AC27/31 -> 5.7691706 | AC27: =S27*AA27 -> 178.84429 | AD27: =G27*AC27*1.5 -> 11588.251 | AE27: 无超期风险 | AG27: =AC27/4 -> 44.711072 | AH27: =$Y27/4 -> 112.44171
A28: CC0176 | B28: 3C-手卷电子7垫鼓 | C28: 1 | D28: 马来 | E28: 3C数码 | F28: 电子鼓 | G28: 94.0561 | H28: 457 | I28: 5 | J28: 91 | K28: 205 | L28: 19470 | M28: =(H28-(I28*50))/50 -> 4.14 | N28: =31*(M28+I28) -> 283.34 | O28: =N28*G28 -> 26649.855 | P28: =(H28-(I28*90))/90 -> 0.077777778 | Q28: =31*(P28+I28) -> 157.41111 | R28: =(P28+I28)*31*G28*1.5 -> 22208.213 | S28: =Q28 -> 157.41111 | T28: =S28/31 -> 5.0777778 | U28: =T28-I28 -> 0.077777778 | V28: =R28 -> 22208.213 | W28: =_xlfn.XLOOKUP(B28,Sheet5!G:G,Sheet5!H:H) -> 0.43137255 | X28: =Y28/31 -> 2.1904139 | Y28: =S28*W28 -> 67.902832 | Z28: =Y28*G28*1.5 -> 9580.0134 | AA28: =_xlfn.XLOOKUP(B28,Sheet5!G:G,Sheet5!I:I) -> 0.56862745 | AB28: =AC28/31 -> 2.8873638 | AC28: =S28*AA28 -> 89.508279 | AD28: =G28*AC28*1.5 -> 12628.199 | AE28: 无超期风险 | AF28: 正常销售 | AG28: =AC28/4 -> 22.37707 | AH28: =$Y28/4 -> 16.975708
A29: CC0673 | B29: 3B-仿真书银钱盒密码款蓝色 | C29: 1 | D29: 马来 | E29: 办公安防 | F29: 银钱盒 | G29: 19.7793 | H29: 1014 | I29: 5 | J29: 202 | K29: 724 | L29: 19186 | M29: =(H29-(I29*50))/50 -> 15.28 | N29: =31*(M29+I29) -> 628.68 | O29: =N29*G29 -> 12434.85 | P29: =(H29-(I29*90))/90 -> 6.2666667 | Q29: =31*(P29+I29) -> 349.26667 | R29: =(P29+I29)*31*G29*1.5 -> 10362.375 | S29: =Q29 -> 349.26667 | T29: =S29/31 -> 11.266667 | U29: =T29-I29 -> 6.2666667 | V29: =R29 -> 10362.375 | W29: =_xlfn.XLOOKUP(B29,Sheet5!G:G,Sheet5!H:H) -> 0.58333333 | X29: =Y29/31 -> 6.5722222 | Y29: =S29*W29 -> 203.73889 | Z29: =Y29*G29*1.5 -> 6044.7189 | AA29: =_xlfn.XLOOKUP(B29,Sheet5!G:G,Sheet5!I:I) -> 0.41666667 | AB29: =AC29/31 -> 4.6944444 | AC29: =S29*AA29 -> 145.52778 | AD29: =G29*AC29*1.5 -> 4317.6564 | AE29: 重点： 阶段降解消耗，周转控制在60 人员：心怡 | AF29: 小店重点价格扶持起量 孝鑫+鹭燕 | AG29: =AC29/4 -> 36.381944 | AH29: =$Y29/4 -> 50.934722
A30: CC0142 | B30: 3B-手提收银箱双层黑色 | C30: 1 | D30: 马来 | E30: 办公安防 | F30: 收银箱 | G30: 38.5262 | H30: 1934 | I30: 28 | J30: 69 | K30: 495 | L30: 19070 | M30: =(H30-(I30*50))/50 -> 10.68 | N30: =31*(M30+I30) -> 1199.08 | O30: =N30*G30 -> 46195.996 | P30: =(H30-(I30*90))/90 -> -6.5111111 | Q30: =31*(P30+I30) -> 666.15556 | R30: =(P30+I30)*31*G30*1.5 -> 38496.663 | S30: =Q30 -> 666.15556 | T30: =S30/31 -> 21.488889 | U30: =T30-I30 -> -6.5111111 | V30: =R30 -> 38496.663 | W30: =_xlfn.XLOOKUP(B30,Sheet5!G:G,Sheet5!H:H) -> 0.39622642 | X30: =Y30/31 -> 8.5144654 | Y30: =S30*W30 -> 263.94843 | Z30: =Y30*G30*1.5 -> 15253.395 | AA30: =_xlfn.XLOOKUP(B30,Sheet5!G:G,Sheet5!I:I) -> 0.60377358 | AB30: =AC30/31 -> 12.974423 | AC30: =S30*AA30 -> 402.20713 | AD30: =G30*AC30*1.5 -> 23243.268 | AE30: 无超期风险 | AG30: =AC30/4 -> 100.55178 | AH30: =$Y30/4 -> 65.987107
A31: CC1044 | B31: 3B-可充电不锈钢球形锁K06 | C31: 1 | D31: 马来 | E31: 办公安防 | F31: 球型智能门锁 | G31: 98.3411 | H31: 120 | K31: 120 | L31: 17701 | M31: =(H31-(I31*50))/50 -> 2.4 | N31: =31*(M31+I31) -> 74.4 | O31: =N31*G31 -> 7316.5778 | P31: =(H31-(I31*90))/90 -> 1.3333333 | Q31: =31*(P31+I31) -> 41.333333 | R31: =(P31+I31)*31*G31*1.5 -> 6097.1482 | S31: =Q31 -> 41.333333 | T31: =S31/31 -> 1.3333333 | U31: =T31-I31 -> 1.3333333 | V31: =R31 -> 6097.1482 | W31: 0.5 | X31: =Y31/31 -> 0.66666667 | Y31: =S31*W31 -> 20.666667 | Z31: =Y31*G31*1.5 -> 3048.5741 | AA31: 0.5 | AB31: =AC31/31 -> 0.66666667 | AC31: =S31*AA31 -> 20.666667 | AD31: =G31*AC31*1.5 -> 3048.5741 | AE31: 新品： 寄样5，加入老链接本月销售21单 | AF31: 月底刚到，正常下费用推品，每人至少上架三条链接，插入一条老链接 | AG31: =AC31/4 -> 5.1666667 | AH31: =$Y31/4 -> 5.1666667
A32: CC0903 | B32: 3B-磁吸白板密度板夹层60cm*90cm | C32: 1 | D32: 马来 | E32: 办公安防 | F32: 白板 | G32: 33.6968 | H32: 1821 | I32: 26 | J32: 70 | K32: 508 | L32: 17118 | M32: =(H32-(I32*50))/50 -> 10.42 | N32: =31*(M32+I32) -> 1129.02 | O32: =N32*G32 -> 38044.361 | P32: =(H32-(I32*90))/90 -> -5.7666667 | Q32: =31*(P32+I32) -> 627.23333 | R32: =(P32+I32)*31*G32*1.5 -> 31703.634 | S32: =Q32 -> 627.23333 | T32: =S32/31 -> 20.233333 | U32: =T32-I32 -> -5.7666667 | V32: =R32 -> 31703.634 | W32: =_xlfn.XLOOKUP(B32,Sheet5!G:G,Sheet5!H:H) -> 0.69830508 | X32: =Y32/31 -> 14.12904 | Y32: =S32*W32 -> 438.00023 | Z32: =Y32*G32*1.5 -> 22138.809 | AA32: =_xlfn.XLOOKUP(B32,Sheet5!G:G,Sheet5!I:I) -> 0.30169492 | AB32: =AC32/31 -> 6.1042938 | AC32: =S32*AA32 -> 189.23311 | AD32: =G32*AC32*1.5 -> 9564.8253 | AE32: 无超期风险 | AG32: =AC32/4 -> 47.308277 | AH32: =$Y32/4 -> 109.50006
A33: CC0852 | B33: 3B-启动电源N20 | C33: 1 | D33: 马来 | E33: 办公安防 | F33: 启动电源 | G33: 215.7607 | H33: 53 | K33: 50 | L33: 15858 | M33: =(H33-(I33*50))/50 -> 1.06 | N33: =31*(M33+I33) -> 32.86 | O33: =N33*G33 -> 7089.8966 | P33: =(H33-(I33*90))/90 -> 0.58888889 | Q33: =31*(P33+I33) -> 18.255556 | R33: =(P33+I33)*31*G33*1.5 -> 5908.2472 | S33: =Q33 -> 18.255556 | T33: =S33/31 -> 0.58888889 | U33: =T33-I33 -> 0.58888889 | V33: =R33 -> 5908.2472 | W33: =_xlfn.XLOOKUP(B33,Sheet5!G:G,Sheet5!H:H) -> 0 | X33: =Y33/31 -> 0 | Y33: =S33*W33 -> 0 | Z33: =Y33*G33*1.5 -> 0 | AA33: =_xlfn.XLOOKUP(B33,Sheet5!G:G,Sheet5!I:I) -> 0 | AB33: =AC33/31 -> 0 | AC33: =S33*AA33 -> 0 | AD33: =G33*AC33*1.5 -> 0 | AE33: 呆滞品： 寄样：5单 | AF33: 正常出清，当前标价28%，插入原有JY链接尝试 | AG33: =AC33/4 -> 0 | AH33: =$Y33/4 -> 0
A34: CC0876 | B34: 3B-B1A五功能断桥铝锁带APP | C34: 1 | D34: 马来 | E34: 办公安防 | F34: 密码锁 | G34: 177.0938 | H34: 88 | K34: 65 | L34: 15584 | M34: =(H34-(I34*50))/50 -> 1.76 | N34: =31*(M34+I34) -> 54.56 | O34: =N34*G34 -> 9662.2377 | P34: =(H34-(I34*90))/90 -> 0.97777778 | Q34: =31*(P34+I34) -> 30.311111 | R34: =(P34+I34)*31*G34*1.5 -> 8051.8648 | S34: =Q34 -> 30.311111 | T34: =S34/31 -> 0.97777778 | U34: =T34-I34 -> 0.97777778 | V34: =R34 -> 8051.8648 | W34: 0.6 | X34: =Y34/31 -> 0.58666667 | Y34: =S34*W34 -> 18.186667 | Z34: =Y34*G34*1.5 -> 4831.1189 | AA34: 0.4 | AB34: =AC34/31 -> 0.39111111 | AC34: =S34*AA34 -> 12.124444 | AD34: =G34*AC34*1.5 -> 3220.7459 | AE34: 新品： 寄样8，价格进行调整 人员：伟民+罗城+心怡 | AG34: =AC34/4 -> 3.0311111 | AH34: =$Y34/4 -> 4.5466667
A35: CC0758 | B35: 3B-碎纸机7L | C35: 1 | D35: 马来 | E35: 办公安防 | F35: 碎纸机 | G35: 74.8418 | H35: 383 | I35: 3 | J35: 127 | K35: 189 | L35: 15417 | M35: =(H35-(I35*50))/50 -> 4.66 | N35: =31*(M35+I35) -> 237.46 | O35: =N35*G35 -> 17771.934 | P35: =(H35-(I35*90))/90 -> 1.2555556 | Q35: =31*(P35+I35) -> 131.92222 | R35: =(P35+I35)*31*G35*1.5 -> 14809.945 | S35: =Q35 -> 131.92222 | T35: =S35/31 -> 4.2555556 | U35: =T35-I35 -> 1.2555556 | V35: =R35 -> 14809.945 | W35: =_xlfn.XLOOKUP(B35,Sheet5!G:G,Sheet5!H:H) -> 0.65217391 | X35: =Y35/31 -> 2.7753623 | Y35: =S35*W35 -> 86.036232 | Z35: =Y35*G35*1.5 -> 9658.6597 | AA35: =_xlfn.XLOOKUP(B35,Sheet5!G:G,Sheet5!I:I) -> 0.34782609 | AB35: =AC35/31 -> 1.4801932 | AC35: =S35*AA35 -> 45.88599 | AD35: =G35*AC35*1.5 -> 5151.2852 | AE35: 进行调价，控合理周转 | AF35: 全组消耗，竞品价格过低，标价利润13%，已每日安排10个库存对标竞品销售 后续不当主推，主推新款 | AG35: =AC35/4 -> 11.471498 | AH35: =$Y35/4 -> 21.509058
A36: CC0807 | B36: 3C-显示器桌面支架3屏 | C36: 1 | D36: 马来 | E36: 3C数码 | F36: 显示器支架 | G36: 89.55 | H36: 143 | K36: 120 | L36: 15268 | M36: =(H36-(I36*50))/50 -> 2.86 | N36: =31*(M36+I36) -> 88.66 | O36: =N36*G36 -> 7939.503 | P36: =(H36-(I36*90))/90 -> 1.5888889 | Q36: =31*(P36+I36) -> 49.255556 | R36: =(P36+I36)*31*G36*1.5 -> 6616.2525 | S36: =Q36 -> 49.255556 | T36: =S36/31 -> 1.5888889 | U36: =T36-I36 -> 1.5888889 | V36: =R36 -> 6616.2525 | W36: =_xlfn.XLOOKUP(B36,Sheet5!G:G,Sheet5!H:H) -> 1 | X36: =Y36/31 -> 1.5888889 | Y36: =S36*W36 -> 49.255556 | Z36: =Y36*G36*1.5 -> 6616.2525 | AA36: =_xlfn.XLOOKUP(B36,Sheet5!G:G,Sheet5!I:I) -> 0 | AB36: =AC36/31 -> 0 | AC36: =S36*AA36 -> 0 | AD36: =G36*AC36*1.5 -> 0 | AE36: 暂不规划 | AG36: =AC36/4 -> 0 | AH36: =$Y36/4 -> 12.313889
A37: CC1057 | B37: 3C-单柱旋转移动推车MY01 | C37: 1 | D37: 马来 | E37: 3C数码 | F37: 电视支架 | G37: 135.44 | H37: 107 | K37: 81 | L37: 15034 | M37: =(H37-(I37*50))/50 -> 2.14 | N37: =31*(M37+I37) -> 66.34 | O37: =N37*G37 -> 8985.0896 | P37: =(H37-(I37*90))/90 -> 1.1888889 | Q37: =31*(P37+I37) -> 36.855556 | R37: =(P37+I37)*31*G37*1.5 -> 7487.5747 | S37: =Q37 -> 36.855556 | T37: =S37/31 -> 1.1888889 | U37: =T37-I37 -> 1.1888889 | V37: =R37 -> 7487.5747 | W37: =_xlfn.XLOOKUP(B37,Sheet5!G:G,Sheet5!H:H) -> 0.5 | X37: =Y37/31 -> 0.59444444 | Y37: =S37*W37 -> 18.427778 | Z37: =Y37*G37*1.5 -> 3743.7873 | AA37: =_xlfn.XLOOKUP(B37,Sheet5!G:G,Sheet5!I:I) -> 0.5 | AB37: =AC37/31 -> 0.59444444 | AC37: =S37*AA37 -> 18.427778 | AD37: =G37*AC37*1.5 -> 3743.7873 | AE37: 月底刚到，正常下费用插入老链接推品 | AF37: 月底刚到，正常下费用插入老链接推品 鹭燕小店重点给优势扶持 | AG37: =AC37/4 -> 4.6069444 | AH37: =$Y37/4 -> 4.6069444
A38: CC0859 | B38: 3B-广告架kt板斜面3.5kg | C38: 1 | D38: 马来 | E38: 办公安防 | F38: 广告架 | G38: 49.17 | H38: 209 | K38: 201 | L38: 14653 | M38: =(H38-(I38*50))/50 -> 4.18 | N38: =31*(M38+I38) -> 129.58 | O38: =N38*G38 -> 6371.4486 | P38: =(H38-(I38*90))/90 -> 2.3222222 | Q38: =31*(P38+I38) -> 71.988889 | R38: =(P38+I38)*31*G38*1.5 -> 5309.5405 | S38: =Q38 -> 71.988889 | T38: =S38/31 -> 2.3222222 | U38: =T38-I38 -> 2.3222222 | V38: =R38 -> 5309.5405 | W38: =_xlfn.XLOOKUP(B38,Sheet5!G:G,Sheet5!H:H) -> 0.4 | X38: =Y38/31 -> 0.92888889 | Y38: =S38*W38 -> 28.795556 | Z38: =Y38*G38*1.5 -> 2123.8162 | AA38: =_xlfn.XLOOKUP(B38,Sheet5!G:G,Sheet5!I:I) -> 0.6 | AB38: =AC38/31 -> 1.3933333 | AC38: =S38*AA38 -> 43.193333 | AD38: =G38*AC38*1.5 -> 3185.7243 | AE38: 呆滞品： 样品送出10个 | AF38: 正常出清，当前标价28% | AG38: =AC38/4 -> 10.798333 | AH38: =$Y38/4 -> 7.1988889
A39: CC0315 | B39: 3B-密码保险箱黑 | C39: 1 | D39: 马来 | E39: 办公安防 | F39: 保险箱 | G39: 124.73 | H39: 362 | I39: 4 | J39: 90 | K39: 117 | L39: 14593 | M39: =(H39-(I39*50))/50 -> 3.24 | N39: =31*(M39+I39) -> 224.44 | O39: =N39*G39 -> 27994.401 | P39: =(H39-(I39*90))/90 -> 0.022222222 | Q39: =31*(P39+I39) -> 124.68889 | R39: =(P39+I39)*31*G39*1.5 -> 23328.668 | S39: =Q39 -> 124.68889 | T39: =S39/31 -> 4.0222222 | U39: =T39-I39 -> 0.022222222 | V39: =R39 -> 23328.668 | W39: =_xlfn.XLOOKUP(B39,Sheet5!G:G,Sheet5!H:H) -> 0.5 | X39: =Y39/31 -> 2.0111111 | Y39: =S39*W39 -> 62.344444 | Z39: 50 | AA39: =_xlfn.XLOOKUP(B39,Sheet5!G:G,Sheet5!I:I) -> 0.5 | AB39: =AC39/31 -> 2.0111111 | AC39: =S39*AA39 -> 62.344444 | AD39: =G39*AC39*1.5 -> 11664.334 | AE39: 无超期风险 | AG39: =AC39/4 -> 15.586111 | AH39: =$Y39/4 -> 15.586111
A40: CC0905 | B40: 3B-磁吸白板密度板夹层90cm*120cm | C40: 1 | D40: 马来 | E40: 办公安防 | F40: 白板 | G40: 78.7257 | H40: 849 | I40: 13 | J40: 65 | K40: 181 | L40: 14249 | M40: =(H40-(I40*50))/50 -> 3.98 | N40: =31*(M40+I40) -> 526.38 | O40: =N40*G40 -> 41439.634 | P40: =(H40-(I40*90))/90 -> -3.5666667 | Q40: =31*(P40+I40) -> 292.43333 | R40: =(P40+I40)*31*G40*1.5 -> 34533.028 | S40: =Q40 -> 292.43333 | T40: =S40/31 -> 9.4333333 | U40: =T40-I40 -> -3.5666667 | V40: =R40 -> 34533.028 | W40: =_xlfn.XLOOKUP(B40,Sheet5!G:G,Sheet5!H:H) -> 0.86451613 | X40: =Y40/31 -> 8.1552688 | Y40: =S40*W40 -> 252.81333 | Z40: =Y40*G40*1.5 -> 29854.36 | AA40: =_xlfn.XLOOKUP(B40,Sheet5!G:G,Sheet5!I:I) -> 0.13548387 | AB40: =AC40/31 -> 1.2780645 | AC40: =S40*AA40 -> 39.62 | AD40: =G40*AC40*1.5 -> 4678.6684 | AE40: 无超期风险 | AG40: =AC40/4 -> 9.905 | AH40: =$Y40/4 -> 63.203333
A41: CC0996 | B41: 3C-专业播客动圈麦克风 | C41: 1 | D41: 马来 | E41: 3C数码 | F41: 有线麦克风 | G41: 152.62 | H41: 65 | K41: 57 | L41: 12515 | M41: =(H41-(I41*50))/50 -> 1.3 | N41: =31*(M41+I41) -> 40.3 | O41: =N41*G41 -> 6150.586 | P41: =(H41-(I41*90))/90 -> 0.72222222 | Q41: =31*(P41+I41) -> 22.388889 | R41: =(P41+I41)*31*G41*1.5 -> 5125.4883 | S41: =Q41 -> 22.388889 | T41: =S41/31 -> 0.72222222 | U41: =T41-I41 -> 0.72222222 | V41: =R41 -> 5125.4883 | W41: =_xlfn.XLOOKUP(B41,Sheet5!G:G,Sheet5!H:H) -> 0 | X41: =Y41/31 -> 0 | Y41: =S41*W41 -> 0 | Z41: =Y41*G41*1.5 -> 0 | AA41: =_xlfn.XLOOKUP(B41,Sheet5!G:G,Sheet5!I:I) -> 1 | AB41: =AC41/31 -> 0.72222222 | AC41: =S41*AA41 -> 22.388889 | AD41: =G41*AC41*1.5 -> 5125.4883 | AE41: 新品：麦系列TK为主达人推广 寄样5 人员：郑雨倩+罗城+伟铭 | AF41: 暂不规划，需重新对标竞品价格 | AG41: =AC41/4 -> 5.5972222 | AH41: =$Y41/4 -> 0
...

Sheet 5月分配 
R1: 90天-4月需销售量 | V1: SP | Z1: TK
A3: 主SKU | B3: 商品名称 | C3: 国家 | D3: 品类 | E3: 三级分类 | F3: 销售成本 | G3: 当前库存 | H3: 日销量 | I3: 周转天数 | J3: 月预估超期库存 | K3: 月预估超期金额 | L3: 日销差距（50天） | M3: 预计出清数量（50天） | N3: 出清金额（3月） | O3: 日销差距（90天） | P3: 预计出清数量（90天） | Q3: 出清金额(3月） | R3: 总数量 | S3: 目标日销 | T3: 日销差异 | U3: 总出清金额 | V3: 业绩占比 | W3: 目标日销 | X3: 总销量 | Y3: 出清额 | Z3: 业绩占比 | AA3: 目标日销 | AB3: 总销量 | AC3: 出清额度 | AD3: 策略方向
A4: CC0904 | B4: 3C-无弦吉他 | C4: 马来 | D4: 3C数码 | E4: 未来吉他 | F4: 712.84 | G4: 191 | H4: 1 | I4: 191 | J4: 111 | K4: 95877 | L4: =(G4-(H4*50))/50 -> 2.82 | M4: =31*(L4+H4) -> 118.42 | N4: =M4*F4 -> 84414.513 | O4: =(G4-(H4*90))/90 -> 1.1222222 | P4: =31*(O4+H4) -> 65.788889 | Q4: =(O4+H4)*31*F4*1.5 -> 70345.427 | R4: =P4 -> 65.788889 | S4: =R4/31 -> 2.1222222 | T4: =S4-H4 -> 1.1222222 | U4: =Q4 -> 70345.427 | V4: =_xlfn.XLOOKUP(B4,[1]Sheet1!$B:$B,[1]Sheet1!$P:$P) -> 0.11764706 | W4: =X4/31 -> 0.2496732 | X4: =R4*V4 -> 7.7398693 | Y4: =X4*F4*1.5 -> 8275.9326 | Z4: =_xlfn.XLOOKUP(B4,[1]Sheet1!$B:$B,[1]Sheet1!$Q:$Q) -> 0.88235294 | AA4: =AB4/31 -> 1.872549 | AB4: =R4*Z4 -> 58.04902 | AC4: =F4*AB4*1.5 -> 62069.495 | AD4: 主推产品，重点降解
A5: CC0517 | B5: 3B-功勋仓保险箱45*38*32cm红色密码款 | C5: 马来 | D5: 办公安防 | E5: 保险柜 | F5: 298.3692 | G5: 120 | J5: 120 | K5: 53706 | L5: =(G5-(H5*50))/50 -> 2.4 | M5: =31*(L5+H5) -> 74.4 | N5: =M5*F5 -> 22198.668 | O5: =(G5-(H5*90))/90 -> 1.3333333 | P5: =31*(O5+H5) -> 41.333333 | Q5: =(O5+H5)*31*F5*1.5 -> 18498.89 | R5: =P5 -> 41.333333 | S5: =R5/31 -> 1.3333333 | T5: =S5-H5 -> 1.3333333 | U5: =Q5 -> 18498.89 | V5: =_xlfn.XLOOKUP(B5,[1]Sheet1!$B:$B,[1]Sheet1!$P:$P) -> 0 | W5: =X5/31 -> 0 | X5: =R5*V5 -> 0 | Y5: =X5*F5*1.5 -> 0 | Z5: =_xlfn.XLOOKUP(B5,[1]Sheet1!$B:$B,[1]Sheet1!$Q:$Q) -> 0 | AA5: =AB5/31 -> 0 | AB5: =R5*Z5 -> 0 | AC5: =F5*AB5*1.5 -> 0 | AD5: 新品主推产品，重点降解
A6: CC0903 | B6: 3B-硬币清分机5188 | C6: 马来 | D6: 办公安防 | E6: 硬币清分机 | F6: 379.8 | G6: 80 | J6: 80 | K6: 45576 | L6: =(G6-(H6*50))/50 -> 1.6 | M6: =31*(L6+H6) -> 49.6 | N6: =M6*F6 -> 18838.08 | O6: =(G6-(H6*90))/90 -> 0.88888889 | P6: =31*(O6+H6) -> 27.555556 | Q6: =(O6+H6)*31*F6*1.5 -> 15698.4 | R6: =P6 -> 27.555556 | S6: =R6/31 -> 0.88888889 | T6: =S6-H6 -> 0.88888889 | U6: =Q6 -> 15698.4 | V6: =_xlfn.XLOOKUP(B6,[1]Sheet1!$B:$B,[1]Sheet1!$P:$P) -> 0 | W6: =X6/31 -> 0 | X6: =R6*V6 -> 0 | Y6: =X6*F6*1.5 -> 0 | Z6: =_xlfn.XLOOKUP(B6,[1]Sheet1!$B:$B,[1]Sheet1!$Q:$Q) -> 0 | AA6: =AB6/31 -> 0 | AB6: =R6*Z6 -> 0 | AC6: =F6*AB6*1.5 -> 0 | AD6: 新品主推产品，重点降解
A7: CC0711 | B7: 3B-58mm手持蓝牙标签打印机 | C7: 马来 | D7: 办公安防 | E7: 打印机 | F7: 52.89 | G7: 2002 | H7: 23 | I7: 87 | J7: 836 | K7: 44216 | L7: =(G7-(H7*50))/50 -> 17.04 | M7: =31*(L7+H7) -> 1241.24 | N7: =M7*F7 -> 65649.184 | O7: =(G7-(H7*90))/90 -> -0.75555556 | P7: =31*(O7+H7) -> 689.57778 | Q7: =(O7+H7)*31*F7*1.5 -> 54707.653 | R7: =P7 -> 689.57778 | S7: =R7/31 -> 22.244444 | T7: =S7-H7 -> -0.75555556 | U7: =Q7 -> 54707.653 | V7: =_xlfn.XLOOKUP(B7,[1]Sheet1!$B:$B,[1]Sheet1!$P:$P) -> 0.97515528 | W7: =X7/31 -> 21.691787 | X7: =R7*V7 -> 672.44541 | Y7: =X7*F7*1.5 -> 53348.457 | Z7: =_xlfn.XLOOKUP(B7,[1]Sheet1!$B:$B,[1]Sheet1!$Q:$Q) -> 0.02484472 | AA7: =AB7/31 -> 0.552657 | AB7: =R7*Z7 -> 17.132367 | AC7: =F7*AB7*1.5 -> 1359.1963 | AD7: 主推产品，重点降解
A8: CC0516 | B8: 3B-路由器P6000白色 | C8: 马来 | D8: 办公安防 | E8: 路由器 | F8: 93.44 | G8: 370 | H8: 1 | I8: 370 | J8: 317 | K8: 42422 | L8: =(G8-(H8*50))/50 -> 6.4 | M8: =31*(L8+H8) -> 229.4 | N8: =M8*F8 -> 21435.136 | O8: =(G8-(H8*90))/90 -> 3.1111111 | P8: =31*(O8+H8) -> 127.44444 | Q8: =(O8+H8)*31*F8*1.5 -> 17862.613 | R8: =P8 -> 127.44444 | S8: =R8/31 -> 4.1111111 | T8: =S8-H8 -> 3.1111111 | U8: =Q8 -> 17862.613 | V8: =_xlfn.XLOOKUP(B8,[1]Sheet1!$B:$B,[1]Sheet1!$P:$P) -> 1 | W8: =X8/31 -> 4.1111111 | X8: =R8*V8 -> 127.44444 | Y8: =X8*F8*1.5 -> 17862.613 | Z8: =_xlfn.XLOOKUP(B8,[1]Sheet1!$B:$B,[1]Sheet1!$Q:$Q) -> 0 | AA8: =AB8/31 -> 0 | AB8: =R8*Z8 -> 0 | AC8: =F8*AB8*1.5 -> 0 | AD8: 呆滞品，定向清理
A9: CC0706 | B9: 3B-收银箱405金属黑色固定版 | C9: 马来 | D9: 办公安防 | E9: 收银箱 | F9: 95.44 | G9: 1502 | H9: 21 | I9: 71 | J9: 439 | K9: 41898 | L9: =(G9-(H9*50))/50 -> 9.04 | M9: =31*(L9+H9) -> 931.24 | N9: =M9*F9 -> 88877.546 | O9: =(G9-(H9*90))/90 -> -4.3111111 | P9: =31*(O9+H9) -> 517.35556 | Q9: =(O9+H9)*31*F9*1.5 -> 74064.621 | R9: =P9 -> 517.35556 | S9: =R9/31 -> 16.688889 | T9: =S9-H9 -> -4.3111111 | U9: =Q9 -> 74064.621 | V9: =_xlfn.XLOOKUP(B9,[1]Sheet1!$B:$B,[1]Sheet1!$P:$P) -> 0.79099678 | W9: =X9/31 -> 13.200857 | X9: =R9*V9 -> 409.22658 | Y9: =X9*F9*1.5 -> 58584.877 | Z9: =_xlfn.XLOOKUP(B9,[1]Sheet1!$B:$B,[1]Sheet1!$Q:$Q) -> 0.20900322 | AA9: =AB9/31 -> 3.4880314 | AB9: =R9*Z9 -> 108.12897 | AC9: =F9*AB9*1.5 -> 15479.744 | AD9: 重点降解
A10: CC0906 | B10: 3B-功勋仓保险箱45*38*32cm红色指纹款 | C10: 马来 | D10: 办公安防 | E10: 保险柜 | F10: 369.1592 | G10: 77 | J10: 72 | K10: 39131 | L10: =(G10-(H10*50))/50 -> 1.54 | M10: =31*(L10+H10) -> 47.74 | N10: =M10*F10 -> 17623.66 | O10: =(G10-(H10*90))/90 -> 0.85555556 | P10: =31*(O10+H10) -> 26.522222 | Q10: =(O10+H10)*31*F10*1.5 -> 14686.384 | R10: =P10 -> 26.522222 | S10: =R10/31 -> 0.85555556 | T10: =S10-H10 -> 0.85555556 | U10: =Q10 -> 14686.384 | V10: =_xlfn.XLOOKUP(B10,[1]Sheet1!$B:$B,[1]Sheet1!$P:$P) -> 1 | W10: =X10/31 -> 0.85555556 | X10: =R10*V10 -> 26.522222 | Y10: =X10*F10*1.5 -> 14686.384 | Z10: =_xlfn.XLOOKUP(B10,[1]Sheet1!$B:$B,[1]Sheet1!$Q:$Q) -> 0 | AA10: =AB10/31 -> 0 | AB10: =R10*Z10 -> 0 | AC10: =F10*AB10*1.5 -> 0 | AD10: 新品主推产品，重点降解
A11: CC0228 | B11: 3B-磁吸白板密度板夹层70cm*100cm | C11: 马来 | D11: 办公安防 | E11: 白板 | F11: 44.98 | G11: 2254 | H11: 28 | I11: 80 | J11: 828 | K11: 37243 | L11: =(G11-(H11*50))/50 -> 17.08 | M11: =31*(L11+H11) -> 1397.48 | N11: =M11*F11 -> 62858.65 | O11: =(G11-(H11*90))/90 -> -2.9555556 | P11: =31*(O11+H11) -> 776.37778 | Q11: =(O11+H11)*31*F11*1.5 -> 52382.209 | R11: =P11 -> 776.37778 | S11: =R11/31 -> 25.044444 | T11: =S11-H11 -> -2.9555556 | U11: =Q11 -> 52382.209 | V11: =_xlfn.XLOOKUP(B11,[1]Sheet1!$B:$B,[1]Sheet1!$P:$P) -> 0.63111111 | W11: =X11/31 -> 15.805827 | X11: =R11*V11 -> 489.98064 | Y11: =X11*F11*1.5 -> 33058.994 | Z11: =_xlfn.XLOOKUP(B11,[1]Sheet1!$B:$B,[1]Sheet1!$Q:$Q) -> 0.36888889 | AA11: =AB11/31 -> 9.2386173 | AB11: =R11*Z11 -> 286.39714 | AC11: =F11*AB11*1.5 -> 19323.215 | AD11: 业绩大头，重点降解
A12: CC0764 | B12: 3B-智能指纹门锁X7 | C12: 马来 | D12: 办公安防 | E12: 指纹锁 | F12: 94.05 | G12: 973 | H12: 12 | I12: 81 | J12: 368 | K12: 34610 | L12: =(G12-(H12*50))/50 -> 7.46 | M12: =31*(L12+H12) -> 603.26 | N12: =M12*F12 -> 56736.603 | O12: =(G12-(H12*90))/90 -> -1.1888889 | P12: =31*(O12+H12) -> 335.14444 | Q12: =(O12+H12)*31*F12*1.5 -> 47280.503 | R12: =P12 -> 335.14444 | S12: =R12/31 -> 10.811111 | T12: =S12-H12 -> -1.1888889 | U12: =Q12 -> 47280.503 | V12: =_xlfn.XLOOKUP(B12,[1]Sheet1!$B:$B,[1]Sheet1!$P:$P) -> 0.21153846 | W12: =X12/31 -> 2.2869658 | X12: =R12*V12 -> 70.89594 | Y12: =X12*F12*1.5 -> 10001.645 | Z12: =_xlfn.XLOOKUP(B12,[1]Sheet1!$B:$B,[1]Sheet1!$Q:$Q) -> 0.78846154 | AA12: =AB12/31 -> 8.5241453 | AB12: =R12*Z12 -> 264.2485 | AC12: =F12*AB12*1.5 -> 37278.858 | AD12: 主推产品，重点降解
A13: CC0278 | B13: 3B-橡胶磁白板背胶90cm*180cm | C13: 马来 | D13: 办公安防 | E13: 白板 | F13: 67.79 | G13: 413 | H13: 1 | I13: 413 | J13: 325 | K13: 30641 | L13: =(G13-(H13*50))/50 -> 7.26 | M13: =31*(L13+H13) -> 256.06 | N13: z | O13: =(G13-(H13*90))/90 -> 3.5888889 | P13: =31*(O13+H13) -> 142.25556 | Q13: =(O13+H13)*31*F13*1.5 -> 14465.256 | R13: =P13 -> 142.25556 | S13: =R13/31 -> 4.5888889 | T13: =S13-H13 -> 3.5888889 | U13: =Q13 -> 14465.256 | V13: =_xlfn.XLOOKUP(B13,[1]Sheet1!$B:$B,[1]Sheet1!$P:$P) -> 0.81481481 | W13: =X13/31 -> 3.7390947 | X13: =R13*V13 -> 115.91193 | Y13: =X13*F13*1.5 -> 11786.505 | Z13: =_xlfn.XLOOKUP(B13,[1]Sheet1!$B:$B,[1]Sheet1!$Q:$Q) -> 0.18518519 | AA13: =AB13/31 -> 0.84979424 | AB13: =R13*Z13 -> 26.343621 | AC13: =F13*AB13*1.5 -> 2678.7511 | AD13: 业绩大头，重点降解
A14: CC0634 | B14: 3C-电子琴61健黑色 | C14: 马来 | D14: 3C数码 | E14: 电子琴 | F14: 37.88 | G14: 985 | H14: 8 | I14: 123 | J14: 579 | K14: 26743 | L14: =(G14-(H14*50))/50 -> 11.7 | M14: =31*(L14+H14) -> 610.7 | N14: =M14*F14 -> 23133.316 | O14: =(G14-(H14*90))/90 -> 2.9444444 | P14: =31*(O14+H14) -> 339.27778 | Q14: =(O14+H14)*31*F14*1.5 -> 19277.763 | R14: =P14 -> 339.27778 | S14: =R14/31 -> 10.944444 | T14: =S14-H14 -> 2.9444444 | U14: =Q14 -> 19277.763 | V14: =_xlfn.XLOOKUP(B14,[1]Sheet1!$B:$B,[1]Sheet1!$P:$P) -> 0.48760331 | W14: =X14/31 -> 5.3365473 | X14: =R14*V14 -> 165.43297 | Y14: =X14*F14*1.5 -> 9399.9011 | Z14: =_xlfn.XLOOKUP(B14,[1]Sheet1!$B:$B,[1]Sheet1!$Q:$Q) -> 0.51239669 | AA14: =AB14/31 -> 5.6078972 | AB14: =R14*Z14 -> 173.84481 | AC14: =F14*AB14*1.5 -> 9877.8622 | AD14: 重点降解
A15: CC0342 | B15: 3B-6088型号外币点钞机 | C15: 马来 | D15: 办公安防 | E15: 点钞机 | F15: 329.025 | G15: 58 | J15: 55 | K15: 26651 | L15: =(G15-(H15*50))/50 -> 1.16 | M15: =31*(L15+H15) -> 35.96 | N15: =M15*F15 -> 11831.739 | O15: =(G15-(H15*90))/90 -> 0.64444444 | P15: =31*(O15+H15) -> 19.977778 | Q15: =(O15+H15)*31*F15*1.5 -> 9859.7825 | R15: =P15 -> 19.977778 | S15: =R15/31 -> 0.64444444 | T15: =S15-H15 -> 0.64444444 | U15: =Q15 -> 9859.7825 | V15: =_xlfn.XLOOKUP(B15,[1]Sheet1!$B:$B,[1]Sheet1!$P:$P) -> 0 | W15: =X15/31 -> 0 | X15: =R15*V15 -> 0 | Y15: =X15*F15*1.5 -> 0 | Z15: =_xlfn.XLOOKUP(B15,[1]Sheet1!$B:$B,[1]Sheet1!$Q:$Q) -> 0 | AA15: =AB15/31 -> 0 | AB15: =R15*Z15 -> 0 | AC15: =F15*AB15*1.5 -> 0 | AD15: 新品主推产品，重点降解
A16: CC0686 | B16: 3B-300CWiFi路由器 | C16: 马来 | D16: 办公安防 | E16: 路由器 | F16: 127.34 | G16: 136 | J16: 136 | K16: 25977 | L16: =(G16-(H16*50))/50 -> 2.72 | M16: =31*(L16+H16) -> 84.32 | N16: =M16*F16 -> 10737.309 | O16: =(G16-(H16*90))/90 -> 1.5111111 | P16: =31*(O16+H16) -> 46.844444 | Q16: =(O16+H16)*31*F16*1.5 -> 8947.7573 | R16: =P16 -> 46.844444 | S16: =R16/31 -> 1.5111111 | T16: =S16-H16 -> 1.5111111 | U16: =Q16 -> 8947.7573 | V16: =_xlfn.XLOOKUP(B16,[1]Sheet1!$B:$B,[1]Sheet1!$P:$P) -> 0 | W16: =X16/31 -> 0 | X16: =R16*V16 -> 0 | Y16: =X16*F16*1.5 -> 0 | Z16: =_xlfn.XLOOKUP(B16,[1]Sheet1!$B:$B,[1]Sheet1!$Q:$Q) -> 0 | AA16: =AB16/31 -> 0 | AB16: =R16*Z16 -> 0 | AC16: =F16*AB16*1.5 -> 0 | AD16: 呆滞品，定向清理
A17: CC0907 | B17: 3C-X400电视壁挂架送膨胀丝等安装螺丝 | C17: 马来 | D17: 3C数码 | E17: 电视支架 | F17: 19.5121 | G17: 1577 | H17: 11 | I17: 143 | J17: 1001 | K17: 24819 | L17: =(G17-(H17*50))/50 -> 20.54 | M17: =31*(L17+H17) -> 977.74 | N17: =M17*F17 -> 19077.761 | O17: =(G17-(H17*90))/90 -> 6.5222222 | P17: =31*(O17+H17) -> 543.18889 | Q17: =(O17+H17)*31*F17*1.5 -> 15898.134 | R17: =P17 -> 543.18889 | S17: =R17/31 -> 17.522222 | T17: =S17-H17 -> 6.5222222 | U17: =Q17 -> 15898.134 | V17: =_xlfn.XLOOKUP(B17,[1]Sheet1!$B:$B,[1]Sheet1!$P:$P) -> 0.23943662 | W17: =X17/31 -> 4.1954617 | X17: =R17*V17 -> 130.05931 | Y17: =X17*F17*1.5 -> 3806.5954 | Z17: =_xlfn.XLOOKUP(B17,[1]Sheet1!$B:$B,[1]Sheet1!$Q:$Q) -> 0.76056338 | AA17: =AB17/31 -> 13.326761 | AB17: =R17*Z17 -> 413.12958 | AC17: =F17*AB17*1.5 -> 12091.538 | AD17: 重点降解
A18: CC0514 | B18: 3B-保险柜80cm*44cm*40cm | C18: 马来 | D18: 办公安防 | E18: 保险箱 | F18: 616.96 | G18: 30 | J18: 24 | K18: 20668 | L18: =(G18-(H18*50))/50 -> 0.6 | M18: =31*(L18+H18) -> 18.6 | N18: =M18*F18 -> 11475.456 | O18: =(G18-(H18*90))/90 -> 0.33333333 | P18: =31*(O18+H18) -> 10.333333 | Q18: =(O18+H18)*31*F18*1.5 -> 9562.88 | R18: =P18 -> 10.333333 | S18: =R18/31 -> 0.33333333 | T18: =S18-H18 -> 0.33333333 | U18: =Q18 -> 9562.88 | V18: =_xlfn.XLOOKUP(B18,[1]Sheet1!$B:$B,[1]Sheet1!$P:$P) -> 0 | W18: =X18/31 -> 0 | X18: =R18*V18 -> 0 | Y18: =X18*F18*1.5 -> 0 | Z18: =_xlfn.XLOOKUP(B18,[1]Sheet1!$B:$B,[1]Sheet1!$Q:$Q) -> 1 | AA18: =AB18/31 -> 0.33333333 | AB18: =R18*Z18 -> 10.333333 | AC18: =F18*AB18*1.5 -> 9562.88 | AD18: 呆滞品，定向清理
A19: CC0688 | B19: 3B-保险柜100cm*51cm*45cm | C19: 马来 | D19: 办公安防 | E19: 保险箱 | F19: 823.74 | G19: 39 | J19: 21 | K19: 19770 | L19: =(G19-(H19*50))/50 -> 0.78 | M19: =31*(L19+H19) -> 24.18 | N19: =M19*F19 -> 19918.033 | O19: =(G19-(H19*90))/90 -> 0.43333333 | P19: =31*(O19+H19) -> 13.433333 | Q19: =(O19+H19)*31*F19*1.5 -> 16598.361 | R19: =P19 -> 13.433333 | S19: =R19/31 -> 0.43333333 | T19: =S19-H19 -> 0.43333333 | U19: =Q19 -> 16598.361 | V19: =_xlfn.XLOOKUP(B19,[1]Sheet1!$B:$B,[1]Sheet1!$P:$P) -> 0.2 | W19: =X19/31 -> 0.086666667 | X19: =R19*V19 -> 2.6866667 | Y19: =X19*F19*1.5 -> 3319.6722 | Z19: =_xlfn.XLOOKUP(B19,[1]Sheet1!$B:$B,[1]Sheet1!$Q:$Q) -> 0.8 | AA19: =AB19/31 -> 0.34666667 | AB19: =R19*Z19 -> 10.746667 | AC19: =F19*AB19*1.5 -> 13278.689 | AD19: 呆滞品，定向清理
A20: CC0732 | B20: 3C-32至70寸电视移动支架的单支架 | C20: 马来 | D20: 3C数码 | E20: 电视支架 | F20: 99.81 | G20: 547 | H20: 6 | I20: 91 | J20: 198 | K20: 19762 | L20: =(G20-(H20*50))/50 -> 4.94 | M20: =31*(L20+H20) -> 339.14 | N20: =M20*F20 -> 33849.563 | O20: =(G20-(H20*90))/90 -> 0.077777778 | P20: =31*(O20+H20) -> 188.41111 | Q20: =(O20+H20)*31*F20*1.5 -> 28207.969 | R20: =P20 -> 188.41111 | S20: =R20/31 -> 6.0777778 | T20: =S20-H20 -> 0.077777778 | U20: =Q20 -> 28207.969 | V20: =_xlfn.XLOOKUP(B20,[1]Sheet1!$B:$B,[1]Sheet1!$P:$P) -> 0.6043956 | W20: =X20/31 -> 3.6733822 | X20: =R20*V20 -> 113.87485 | Y20: =X20*F20*1.5 -> 17048.773 | Z20: =_xlfn.XLOOKUP(B20,[1]Sheet1!$B:$B,[1]Sheet1!$Q:$Q) -> 0.3956044 | AA20: =AB20/31 -> 2.4043956 | AB20: =R20*Z20 -> 74.536264 | AC20: =F20*AB20*1.5 -> 11159.197 | AD20: 重点降解
A21: CC0315 | B21: 3C-辉光管 | C21: 马来 | D21: 3C数码 | E21: 辉光管 | F21: 203.25 | G21: 77 | J21: 67 | K21: 19614 | L21: =(G21-(H21*50))/50 -> 1.54 | M21: =31*(L21+H21) -> 47.74 | N21: =M21*F21 -> 9703.155 | O21: =(G21-(H21*90))/90 -> 0.85555556 | P21: =31*(O21+H21) -> 26.522222 | Q21: =(O21+H21)*31*F21*1.5 -> 8085.9625 | R21: =P21 -> 26.522222 | S21: =R21/31 -> 0.85555556 | T21: =S21-H21 -> 0.85555556 | U21: =Q21 -> 8085.9625 | V21: =_xlfn.XLOOKUP(B21,[1]Sheet1!$B:$B,[1]Sheet1!$P:$P) -> 0.5 | W21: =X21/31 -> 0.42777778 | X21: =R21*V21 -> 13.261111 | Y21: 60 | Z21: =_xlfn.XLOOKUP(B21,[1]Sheet1!$B:$B,[1]Sheet1!$Q:$Q) -> 0.5 | AA21: =AB21/31 -> 0.42777778 | AB21: =R21*Z21 -> 13.261111 | AC21: =F21*AB21*1.5 -> 4042.9812 | AD21: 呆滞品，定向清理
A22: CC0277 | B22: 3B-交换机机柜60cm | C22: 马来 | D22: 办公安防 | E22: 金属制品机柜 | F22: 124.39 | G22: 100 | J22: 100 | K22: 18659 | L22: =(G22-(H22*50))/50 -> 2 | M22: =31*(L22+H22) -> 62 | N22: =M22*F22 -> 7712.18 | O22: =(G22-(H22*90))/90 -> 1.1111111 | P22: =31*(O22+H22) -> 34.444444 | Q22: =(O22+H22)*31*F22*1.5 -> 6426.8167 | R22: =P22 -> 34.444444 | S22: =R22/31 -> 1.1111111 | T22: =S22-H22 -> 1.1111111 | U22: =Q22 -> 6426.8167 | V22: =_xlfn.XLOOKUP(B22,[1]Sheet1!$B:$B,[1]Sheet1!$P:$P) -> 0 | W22: =X22/31 -> 0 | X22: =R22*V22 -> 0 | Y22: =X22*F22*1.5 -> 0 | Z22: =_xlfn.XLOOKUP(B22,[1]Sheet1!$B:$B,[1]Sheet1!$Q:$Q) -> 0 | AA22: =AB22/31 -> 0 | AB22: =R22*Z22 -> 0 | AC22: =F22*AB22*1.5 -> 0 | AD22: 主推产品，重点降解
A23: CC0377 | B23: 3B-仿真书银钱盒钥匙款蓝色 | C23: 马来 | D23: 办公安防 | E23: 银钱盒 | F23: 18.36 | G23: 1466 | H23: 12 | I23: 122 | J23: 828 | K23: 18112 | L23: =(G23-(H23*50))/50 -> 17.32 | M23: =31*(L23+H23) -> 908.92 | N23: =M23*F23 -> 16687.771 | O23: =(G23-(H23*90))/90 -> 4.2888889 | P23: =31*(O23+H23) -> 504.95556 | Q23: =(O23+H23)*31*F23*1.5 -> 13906.476 | R23: =P23 -> 504.95556 | S23: =R23/31 -> 16.288889 | T23: =S23-H23 -> 4.2888889 | U23: =Q23 -> 13906.476 | V23: =_xlfn.XLOOKUP(B23,[1]Sheet1!$B:$B,[1]Sheet1!$P:$P) -> 0.3375 | W23: =X23/31 -> 5.4975 | X23: =R23*V23 -> 170.4225 | Y23: =X23*F23*1.5 -> 4693.4357 | Z23: =_xlfn.XLOOKUP(B23,[1]Sheet1!$B:$B,[1]Sheet1!$Q:$Q) -> 0.6625 | AA23: =AB23/31 -> 10.791389 | AB23: =R23*Z23 -> 334.53306 | AC23: =F23*AB23*1.5 -> 9213.0403 | AD23: 主推产品，重点降解
A24: CC0768 | B24: 3B-可充电不锈钢球形锁K06 | C24: 马来 | D24: 办公安防 | E24: 球型智能门锁 | F24: 98.3251 | G24: 120 | J24: 120 | K24: 17699 | L24: =(G24-(H24*50))/50 -> 2.4 | M24: =31*(L24+H24) -> 74.4 | N24: =M24*F24 -> 7315.3874 | O24: =(G24-(H24*90))/90 -> 1.3333333 | P24: =31*(O24+H24) -> 41.333333 | Q24: =(O24+H24)*31*F24*1.5 -> 6096.1562 | R24: =P24 -> 41.333333 | S24: =R24/31 -> 1.3333333 | T24: =S24-H24 -> 1.3333333 | U24: =Q24 -> 6096.1562 | V24: =_xlfn.XLOOKUP(B24,[1]Sheet1!$B:$B,[1]Sheet1!$P:$P) -> #N/A | W24: =X24/31 -> #N/A | X24: =R24*V24 -> #N/A | Y24: =X24*F24*1.5 -> #N/A | Z24: =_xlfn.XLOOKUP(B24,[1]Sheet1!$B:$B,[1]Sheet1!$Q:$Q) -> #N/A | AA24: =AB24/31 -> #N/A | AB24: =R24*Z24 -> #N/A | AC24: =F24*AB24*1.5 -> #N/A | AD24: 新品降解
A25: CC0181 | B25: 3C-显示器桌面支架3屏 | C25: 马来 | D25: 3C数码 | E25: 显示器支架 | F25: 89.55 | G25: 157 | J25: 136 | K25: 17507 | L25: =(G25-(H25*50))/50 -> 3.14 | M25: =31*(L25+H25) -> 97.34 | N25: =M25*F25 -> 8716.797 | O25: =(G25-(H25*90))/90 -> 1.7444444 | P25: =31*(O25+H25) -> 54.077778 | Q25: =(O25+H25)*31*F25*1.5 -> 7263.9975 | R25: =P25 -> 54.077778 | S25: =R25/31 -> 1.7444444 | T25: =S25-H25 -> 1.7444444 | U25: =Q25 -> 7263.9975 | V25: =_xlfn.XLOOKUP(B25,[1]Sheet1!$B:$B,[1]Sheet1!$P:$P) -> 1 | W25: =X25/31 -> 1.7444444 | X25: =R25*V25 -> 54.077778 | Y25: =X25*F25*1.5 -> 7263.9975 | Z25: =_xlfn.XLOOKUP(B25,[1]Sheet1!$B:$B,[1]Sheet1!$Q:$Q) -> 0 | AA25: =AB25/31 -> 0 | AB25: =R25*Z25 -> 0 | AC25: =F25*AB25*1.5 -> 0 | AD25: 长期日销偏低，系列降解
A26: CC0876 | B26: 3B-仿真书银钱盒密码款蓝色 | C26: 马来 | D26: 办公安防 | E26: 银钱盒 | F26: 19.31 | G26: 1179 | H26: 9 | I26: 131 | J26: 709 | K26: 16906 | L26: =(G26-(H26*50))/50 -> 14.58 | M26: =31*(L26+H26) -> 730.98 | N26: =M26*F26 -> 14115.224 | O26: =(G26-(H26*90))/90 -> 4.1 | P26: =31*(O26+H26) -> 406.1 | Q26: =(O26+H26)*31*F26*1.5 -> 11762.686 | R26: =P26 -> 406.1 | S26: =R26/31 -> 13.1 | T26: =S26-H26 -> 4.1 | U26: =Q26 -> 11762.686 | V26: =_xlfn.XLOOKUP(B26,[1]Sheet1!$B:$B,[1]Sheet1!$P:$P) -> 0.51041667 | W26: =X26/31 -> 6.6864583 | X26: =R26*V26 -> 207.28021 | Y26: =X26*F26*1.5 -> 6003.8712 | Z26: =_xlfn.XLOOKUP(B26,[1]Sheet1!$B:$B,[1]Sheet1!$Q:$Q) -> 0.48958333 | AA26: =AB26/31 -> 6.4135417 | AB26: =R26*Z26 -> 198.81979 | AC26: =F26*AB26*1.5 -> 5758.8153 | AD26: 主推产品，重点降解
A27: CC0678 | B27: 3B-碎纸机7L | C27: 马来 | D27: 办公安防 | E27: 碎纸机 | F27: 74.34 | G27: 491 | H27: 5 | I27: 98 | J27: 223 | K27: 16875 | L27: =(G27-(H27*50))/50 -> 4.82 | M27: =31*(L27+H27) -> 304.42 | N27: =M27*F27 -> 22630.583 | O27: =(G27-(H27*90))/90 -> 0.45555556 | P27: =31*(O27+H27) -> 169.12222 | Q27: =(O27+H27)*31*F27*1.5 -> 18858.819 | R27: =P27 -> 169.12222 | S27: =R27/31 -> 5.4555556 | T27: =S27-H27 -> 0.45555556 | U27: =Q27 -> 18858.819 | V27: =_xlfn.XLOOKUP(B27,[1]Sheet1!$B:$B,[1]Sheet1!$P:$P) -> 0.6 | W27: =X27/31 -> 3.2733333 | X27: =R27*V27 -> 101.47333 | Y27: =X27*F27*1.5 -> 11315.291 | Z27: =_xlfn.XLOOKUP(B27,[1]Sheet1!$B:$B,[1]Sheet1!$Q:$Q) -> 0.4 | AA27: =AB27/31 -> 2.1822222 | AB27: =R27*Z27 -> 67.648889 | AC27: =F27*AB27*1.5 -> 7543.5276 | AD27: 主推产品，重点降解
A28: CC0177 | B28: 3B-收银箱335金属黑色固定版 | C28: 马来 | D28: 办公安防 | E28: 收银箱 | F28: 78.76 | G28: 1061 | H28: 16 | I28: 66 | J28: 212 | K28: 16697 | L28: =(G28-(H28*50))/50 -> 5.22 | M28: =31*(L28+H28) -> 657.82 | N28: =M28*F28 -> 51809.903 | O28: =(G28-(H28*90))/90 -> -4.2111111 | P28: =31*(O28+H28) -> 365.45556 | Q28: =(O28+H28)*31*F28*1.5 -> 43174.919 | R28: =P28 -> 365.45556 | S28: =R28/31 -> 11.788889 | T28: =S28-H28 -> -4.2111111 | U28: =Q28 -> 43174.919 | V28: =_xlfn.XLOOKUP(B28,[1]Sheet1!$B:$B,[1]Sheet1!$P:$P) -> 0.79090909 | W28: =X28/31 -> 9.3239394 | X28: =R28*V28 -> 289.04212 | Y28: =X28*F28*1.5 -> 34147.436 | Z28: =_xlfn.XLOOKUP(B28,[1]Sheet1!$B:$B,[1]Sheet1!$Q:$Q) -> 0.20909091 | AA28: =AB28/31 -> 2.4649495 | AB28: =R28*Z28 -> 76.413434 | AC28: =F28*AB28*1.5 -> 9027.4831 | AD28: 主推产品，重点降解
A29: CC0860 | B29: 3B-新A6保险箱指纹款35cm*26cm*25cm | C29: 马来 | D29: 办公安防 | E29: 保险箱 | F29: 228.17 | G29: 48 | J29: 45 | K29: 15059 | L29: =(G29-(H29*50))/50 -> 0.96 | M29: =31*(L29+H29) -> 29.76 | N29: =M29*F29 -> 6790.3392 | O29: =(G29-(H29*90))/90 -> 0.53333333 | P29: =31*(O29+H29) -> 16.533333 | Q29: =(O29+H29)*31*F29*1.5 -> 5658.616 | R29: =P29 -> 16.533333 | S29: =R29/31 -> 0.53333333 | T29: =S29-H29 -> 0.53333333 | U29: =Q29 -> 5658.616 | V29: =_xlfn.XLOOKUP(B29,[1]Sheet1!$B:$B,[1]Sheet1!$P:$P) -> 1 | W29: =X29/31 -> 0.53333333 | X29: =R29*V29 -> 16.533333 | Y29: =X29*F29*1.5 -> 5658.616 | Z29: =_xlfn.XLOOKUP(B29,[1]Sheet1!$B:$B,[1]Sheet1!$Q:$Q) -> 0 | AA29: =AB29/31 -> 0 | AB29: =R29*Z29 -> 0 | AC29: =F29*AB29*1.5 -> 0 | AD29: 新品主推产品，重点降解
A30: CC0850 | B30: 3B-广告架kt板斜面3.5kg | C30: 马来 | D30: 办公安防 | E30: 广告架 | F30: 49.17 | G30: 214 | J30: 206 | K30: 15021 | L30: =(G30-(H30*50))/50 -> 4.28 | M30: =31*(L30+H30) -> 132.68 | N30: =M30*F30 -> 6523.8756 | O30: =(G30-(H30*90))/90 -> 2.3777778 | P30: =31*(O30+H30) -> 73.711111 | Q30: =(O30+H30)*31*F30*1.5 -> 5436.563 | R30: =P30 -> 73.711111 | S30: =R30/31 -> 2.3777778 | T30: =S30-H30 -> 2.3777778 | U30: =Q30 -> 5436.563 | V30: =_xlfn.XLOOKUP(B30,[1]Sheet1!$B:$B,[1]Sheet1!$P:$P) -> 0 | W30: =X30/31 -> 0 | X30: =R30*V30 -> 0 | Y30: =X30*F30*1.5 -> 0 | Z30: =_xlfn.XLOOKUP(B30,[1]Sheet1!$B:$B,[1]Sheet1!$Q:$Q) -> 1 | AA30: =AB30/31 -> 2.3777778 | AB30: =R30*Z30 -> 73.711111 | AC30: =F30*AB30*1.5 -> 5436.563 | AD30: 呆滞品，定向清理
A31: CC0807 | B31: 3B-B1A五功能断桥铝锁带APP | C31: 马来 | D31: 办公安防 | E31: 密码锁 | F31: 176.53 | G31: 102 | J31: 66 | K31: 14917 | L31: =(G31-(H31*50))/50 -> 2.04 | M31: =31*(L31+H31) -> 63.24 | N31: =M31*F31 -> 11163.757 | O31: =(G31-(H31*90))/90 -> 1.1333333 | P31: =31*(O31+H31) -> 35.133333 | Q31: =(O31+H31)*31*F31*1.5 -> 9303.131 | R31: =P31 -> 35.133333 | S31: =R31/31 -> 1.1333333 | T31: =S31-H31 -> 1.1333333 | U31: =Q31 -> 9303.131 | V31: =_xlfn.XLOOKUP(B31,[1]Sheet1!$B:$B,[1]Sheet1!$P:$P) -> 0.69230769 | W31: =X31/31 -> 0.78461538 | X31: =R31*V31 -> 24.323077 | Y31: =X31*F31*1.5 -> 6440.6292 | Z31: =_xlfn.XLOOKUP(B31,[1]Sheet1!$B:$B,[1]Sheet1!$Q:$Q) -> 0.30769231 | AA31: =AB31/31 -> 0.34871795 | AB31: =R31*Z31 -> 10.810256 | AC31: =F31*AB31*1.5 -> 2862.5018 | AD31: 重点降解
A32: CC0905 | B32: 3B-宽57cm热敏打印纸5卷 | C32: 马来 | D32: 办公安防 | E32: 标签打印纸 | F32: 4.1901 | G32: 7560 | H32: 82 | I32: 92 | J32: 3432 | K32: 14655 | L32: =(G32-(H32*50))/50 -> 69.2 | M32: =31*(L32+H32) -> 4687.2 | N32: =M32*F32 -> 19639.837 | O32: =(G32-(H32*90))/90 -> 2 | P32: =31*(O32+H32) -> 2604 | Q32: =(O32+H32)*31*F32*1.5 -> 16366.531 | R32: =P32 -> 2604 | S32: =R32/31 -> 84 | T32: =S32-H32 -> 2 | U32: =Q32 -> 16366.531 | V32: =_xlfn.XLOOKUP(B32,[1]Sheet1!$B:$B,[1]Sheet1!$P:$P) -> 0.89295039 | W32: =X32/31 -> 75.007833 | X32: =R32*V32 -> 2325.2428 | Y32: =X32*F32*1.5 -> 14614.5 | Z32: =_xlfn.XLOOKUP(B32,[1]Sheet1!$B:$B,[1]Sheet1!$Q:$Q) -> 0.10704961 | AA32: =AB32/31 -> 8.9921671 | AB32: =R32*Z32 -> 278.75718 | AC32: =F32*AB32*1.5 -> 1752.0307 | AD32: 主推配套，降解打印机
A33: CC0763 | B33: 3B-智能指纹门锁M20 | C33: 马来 | D33: 办公安防 | E33: 指纹锁 | F33: 74.88 | G33: 396 | H33: 4 | I33: 99 | J33: 184 | K33: 14340 | L33: =(G33-(H33*50))/50 -> 3.92 | M33: =31*(L33+H33) -> 245.52 | N33: =M33*F33 -> 18384.538 | O33: =(G33-(H33*90))/90 -> 0.4 | P33: =31*(O33+H33) -> 136.4 | Q33: =(O33+H33)*31*F33*1.5 -> 15320.448 | R33: =P33 -> 136.4 | S33: =R33/31 -> 4.4 | T33: =S33-H33 -> 0.4 | U33: =Q33 -> 15320.448 | V33: =_xlfn.XLOOKUP(B33,[1]Sheet1!$B:$B,[1]Sheet1!$P:$P) -> 0.26530612 | W33: =X33/31 -> 1.1673469 | X33: =R33*V33 -> 36.187755 | Y33: =X33*F33*1.5 -> 4064.6087 | Z33: =_xlfn.XLOOKUP(B33,[1]Sheet1!$B:$B,[1]Sheet1!$Q:$Q) -> 0.73469388 | AA33: =AB33/31 -> 3.2326531 | AB33: =R33*Z33 -> 100.21224 | AC33: =F33*AB33*1.5 -> 11255.839 | AD33: 主推产品，重点降解
A34: CC0339 | B34: 3B-密码保险箱黑 | C34: 马来 | D34: 办公安防 | E34: 保险箱 | F34: 124.73 | G34: 500 | H34: 7 | I34: 71 | J34: 112 | K34: 13970 | L34: =(G34-(H34*50))/50 -> 3 | M34: =31*(L34+H34) -> 310 | N34: =M34*F34 -> 38666.3 | O34: =(G34-(H34*90))/90 -> -1.4444444 | P34: =31*(O34+H34) -> 172.22222 | Q34: =(O34+H34)*31*F34*1.5 -> 32221.917 | R34: =P34 -> 172.22222 | S34: =R34/31 -> 5.5555556 | T34: =S34-H34 -> -1.4444444 | U34: =Q34 -> 32221.917 | V34: =_xlfn.XLOOKUP(B34,[1]Sheet1!$B:$B,[1]Sheet1!$P:$P) -> 0.41304348 | W34: =X34/31 -> 2.294686 | X34: =R34*V34 -> 71.135266 | Y34: =X34*F34*1.5 -> 13309.053 | Z34: =_xlfn.XLOOKUP(B34,[1]Sheet1!$B:$B,[1]Sheet1!$Q:$Q) -> 0.58695652 | AA34: =AB34/31 -> 3.2608696 | AB34: =R34*Z34 -> 101.08696 | AC34: =F34*AB34*1.5 -> 18912.864 | AD34: 主推产品，重点降解
A35: CC0730 | B35: 3C-专业播客动圈麦克风 | C35: 马来 | D35: 3C数码 | E35: 有线麦克风 | F35: 152.62 | G35: 70 | J35: 62 | K35: 13659 | L35: =(G35-(H35*50))/50 -> 1.4 | M35: =31*(L35+H35) -> 43.4 | N35: =M35*F35 -> 6623.708 | O35: =(G35-(H35*90))/90 -> 0.77777778 | P35: =31*(O35+H35) -> 24.111111 | Q35: =(O35+H35)*31*F35*1.5 -> 5519.7567 | R35: =P35 -> 24.111111 | S35: =R35/31 -> 0.77777778 | T35: =S35-H35 -> 0.77777778 | U35: =Q35 -> 5519.7567 | V35: =_xlfn.XLOOKUP(B35,[1]Sheet1!$B:$B,[1]Sheet1!$P:$P) -> 0 | W35: =X35/31 -> 0 | X35: =R35*V35 -> 0 | Y35: =X35*F35*1.5 -> 0 | Z35: =_xlfn.XLOOKUP(B35,[1]Sheet1!$B:$B,[1]Sheet1!$Q:$Q) -> 1 | AA35: =AB35/31 -> 0.77777778 | AB35: =R35*Z35 -> 24.111111 | AC35: =F35*AB35*1.5 -> 5519.7567 | AD35: 新品长期动销不住
A36: CC0733 | B36: 3C-显示器支架单臂铁塑款 | C36: 马来 | D36: 3C数码 | E36: 显示器支架 | F36: 44.2577 | G36: 808 | H36: 10 | I36: 80 | J36: 303 | K36: 13410 | L36: =(G36-(H36*50))/50 -> 6.16 | M36: =31*(L36+H36) -> 500.96 | N36: =M36*F36 -> 22171.337 | O36: =(G36-(H36*90))/90 -> -1.0222222 | P36: =31*(O36+H36) -> 278.31111 | Q36: =(O36+H36)*31*F36*1.5 -> 18476.114 | R36: =P36 -> 278.31111 | S36: =R36/31 -> 8.9777778 | T36: =S36-H36 -> -1.0222222 | U36: =Q36 -> 18476.114 | V36: =_xlfn.XLOOKUP(B36,[1]Sheet1!$B:$B,[1]Sheet1!$P:$P) -> 0.22857143 | W36: =X36/31 -> 2.0520635 | X36: =R36*V36 -> 63.613968 | Y36: =X36*F36*1.5 -> 4223.1119 | Z36: =_xlfn.XLOOKUP(B36,[1]Sheet1!$B:$B,[1]Sheet1!$Q:$Q) -> 0.77142857 | AA36: =AB36/31 -> 6.9257143 | AB36: =R36*Z36 -> 214.69714 | AC36: =F36*AB36*1.5 -> 14253.003 | AD36: 主推产品，重点降解
A37: CC0731 | B37: 3C-32英寸到55英寸带中托可移动电视支架 | C37: 马来 | D37: 3C数码 | E37: 电视支架 | F37: 123.29 | G37: 570 | H37: 9 | I37: 63 | J37: 108 | K37: 13315 | L37: =(G37-(H37*50))/50 -> 2.4 | M37: =31*(L37+H37) -> 353.4 | N37: =M37*F37 -> 43570.686 | O37: =(G37-(H37*90))/90 -> -2.6666667 | P37: =31*(O37+H37) -> 196.33333 | Q37: =(O37+H37)*31*F37*1.5 -> 36308.905 | R37: =P37 -> 196.33333 | S37: =R37/31 -> 6.3333333 | T37: =S37-H37 -> -2.6666667 | U37: =Q37 -> 36308.905 | V37: =_xlfn.XLOOKUP(B37,[1]Sheet1!$B:$B,[1]Sheet1!$P:$P) -> 0.19672131 | W37: =X37/31 -> 1.2459016 | X37: =R37*V37 -> 38.622951 | Y37: =X37*F37*1.5 -> 7142.7354 | Z37: =_xlfn.XLOOKUP(B37,[1]Sheet1!$B:$B,[1]Sheet1!$Q:$Q) -> 0.80327869 | AA37: =AB37/31 -> 5.0874317 | AB37: =R37*Z37 -> 157.71038 | AC37: =F37*AB37*1.5 -> 29166.17 | AD37: 重点降解
A38: CC0433 | B38: 3C-双层移动推车MY1700PJ | C38: 马来 | D38: 3C数码 | E38: 电视支架 | F38: 120.02 | G38: 78 | J38: 73 | K38: 12902 | L38: =(G38-(H38*50))/50 -> 1.56 | M38: =31*(L38+H38) -> 48.36 | N38: =M38*F38 -> 5804.1672 | O38: =(G38-(H38*90))/90 -> 0.86666667 | P38: =31*(O38+H38) -> 26.866667 | Q38: =(O38+H38)*31*F38*1.5 -> 4836.806 | R38: =P38 -> 26.866667 | S38: =R38/31 -> 0.86666667 | T38: =S38-H38 -> 0.86666667 | U38: =Q38 -> 4836.806 | V38: =_xlfn.XLOOKUP(B38,[1]Sheet1!$B:$B,[1]Sheet1!$P:$P) -> 1 | W38: =X38/31 -> 0.86666667 | X38: =R38*V38 -> 26.866667 | Y38: =X38*F38*1.5 -> 4836.806 | Z38: =_xlfn.XLOOKUP(B38,[1]Sheet1!$B:$B,[1]Sheet1!$Q:$Q) -> 0 | AA38: =AB38/31 -> 0 | AB38: =R38*Z38 -> 0 | AC38: =F38*AB38*1.5 -> 0 | AD38: 新品降解
A39: CC0727 | B39: 3C-黑色吉他套装 | C39: 马来 | D39: 3C数码 | E39: 吉他套装 | F39: 83.02 | G39: 606 | H39: 8 | I39: 75 | J39: 155 | K39: 12868 | L39: =(G39-(H39*50))/50 -> 4.12 | M39: =31*(L39+H39) -> 375.72 | N39: =M39*F39 -> 31192.274 | O39: =(G39-(H39*90))/90 -> -1.2666667 | P39: =31*(O39+H39) -> 208.73333 | Q39: =(O39+H39)*31*F39*1.5 -> 25993.562 | R39: =P39 -> 208.73333 | S39: =R39/31 -> 6.7333333 | T39: =S39-H39 -> -1.2666667 | U39: =Q39 -> 25993.562 | V39: =_xlfn.XLOOKUP(B39,[1]Sheet1!$B:$B,[1]Sheet1!$P:$P) -> 0.42372881 | W39: =X39/31 -> 2.8531073 | X39: =R39*V39 -> 88.446328 | Y39: =X39*F39*1.5 -> 11014.221 | Z39: =_xlfn.XLOOKUP(B39,[1]Sheet1!$B:$B,[1]Sheet1!$Q:$Q) -> 0.57627119 | AA39: =AB39/31 -> 3.880226 | AB39: =R39*Z39 -> 120.28701 | AC39: =F39*AB39*1.5 -> 14979.341 | AD39: 主推产品，重点降解
