Workbook

Sheet 6月调整栏
A1: 调整时间 | B1: 商品名称 | C1: SKU | D1: 提价25%特殊控价 | E1: 特殊优惠卷 | F1: 截至时间 | G1: 人员 | H1: 特殊原因
A2: 46176 | B2: 3C-折叠带蓝牙带琴谱架电子琴61键 | C2: M4CC2450780 | D2: / | E2: 30%最高减免25RM 每日两张 | F2: 46180 | G2: 曾伟铭 | H2: 其余人未销售
A3: 46176 | B3: 3C-32英寸到55英寸带中托可移动电视支架 | C3: T4CC1120706 | D3: / | E3: 27%最高减免27RM 每日两张 | F3: 46180 | G3: 曾伟铭+饶伟铭 | H3: 其余人未销售
A4: 46176 | B4: 3B-仿真书银钱盒钥匙款蓝色 | C4: T3CC1220672 | D4: 28 | E4: / | F4: 46203 | G4: 王心怡 | H4: 超期扶持
A5: 46176 | B5: 3B-仿真书银钱盒密码款蓝色 | C5: T3CC1220673 | D5: 28 | E5: / | F5: 46203 | G5: 王心怡 | H5: 超期扶持
A6: 46176 | B6: 3B-仿真书银钱盒钥匙款蓝色 | C6: T3CC1220672 | D6: 28 | E6: / | F6: 46203 | G6: 王心怡 | H6: 超期扶持
A7: 46176 | B7: 3B-仿真书银钱盒钥匙款蓝色 | C7: T4CC2660672 | D7: 28 | E7: / | F7: 46203 | G7: 王心怡 | H7: 超期扶持
A8: 46176 | B8: 3B-仿真书银钱盒密码款蓝色 | C8: T3CC1220673 | D8: 28 | E8: / | F8: 46203 | G8: 王心怡 | H8: 超期扶持
A9: 46176 | B9: 3B-仿真书银钱盒密码款蓝色 | C9: T4CC2660673 | D9: 28 | E9: / | F9: 46203 | G9: 王心怡 | H9: 超期扶持
A10: 46176 | B10: 3B-仿真书银钱盒钥匙款红色 | C10: T4CC2660965 | D10: 28 | E10: / | F10: 46203 | G10: 王心怡 | H10: 超期扶持

Sheet 6月达人佣金特殊申请
A1: 店铺 | B1: 调整时间 | C1: 申请达人佣金 | D1: 链接ID | E1: SKU | F1: 产品中文名 | G1: 25%折扣价 | H1: 20%到手价 | I1: 控价调整项 | J1: 优惠卷调整项 | K1: 实际到手价 | L1: 达人佣金
A2: EXPSOE TK | B2: 46148 | C2: 0.12 | D2: 1731131393182042075 | E2: M4CC3300653 | F2: =_xlfn.XLOOKUP(E2,'6月控价 '!F:F,'6月控价 '!E:E) -> 3B-JY004便携式储能电源4KG | G2: =_xlfn.XLOOKUP(E2,'6月控价 '!F:F,'6月控价 '!T:T) -> 499 | H2: =_xlfn.XLOOKUP(E2,'6月控价 '!F:F,'6月控价 '!U:U) -> 399.2 | I2: / | J2: 0.19 | K2: =G2*(1-0.19) -> 404.19
A3: EXPSOE TK | B3: 46148 | C3: 0.12 | D3: 1735418725005952987 | E3: M4CC3300283 | F3: =_xlfn.XLOOKUP(E3,'6月控价 '!F:F,'6月控价 '!E:E) -> 3B-便携式储能电源 | G3: =_xlfn.XLOOKUP(E3,'6月控价 '!F:F,'6月控价 '!T:T) -> 244 | H3: =_xlfn.XLOOKUP(E3,'6月控价 '!F:F,'6月控价 '!U:U) -> 195.2 | I3: / | J3: 0.12 | K3: =G3*(1-0.12) -> 214.72
A4: EXPSOE TK | B4: 46148 | C4: 0.1 | D4: 1734938035338381275 | E4: M4CC3300653 | F4: =_xlfn.XLOOKUP(E4,'6月控价 '!F:F,'6月控价 '!E:E) -> 3B-JY004便携式储能电源4KG | G4: =_xlfn.XLOOKUP(E4,'6月控价 '!F:F,'6月控价 '!T:T) -> 499 | H4: =_xlfn.XLOOKUP(E4,'6月控价 '!F:F,'6月控价 '!U:U) -> 399.2 | I4: / | J4: 0.21 | K4: =G4*(1-0.21) -> 394.21
A5: EXPSOE TK | B5: 46148 | C5: 0.1 | D5: 1735418725005952987 | E5: M4CC3300283 | F5: =_xlfn.XLOOKUP(E5,'6月控价 '!F:F,'6月控价 '!E:E) -> 3B-便携式储能电源 | G5: =_xlfn.XLOOKUP(E5,'6月控价 '!F:F,'6月控价 '!T:T) -> 244 | H5: =_xlfn.XLOOKUP(E5,'6月控价 '!F:F,'6月控价 '!U:U) -> 195.2 | I5: / | J5: 0.14 | K5: =G5*(1-0.14) -> 209.84
A6: EXPOSE.Tech Wealth | B6: 46148 | C6: 0.12 | D6: 1734983983228290729 | E6: M4CC3300653 | F6: =_xlfn.XLOOKUP(E6,'6月控价 '!F:F,'6月控价 '!E:E) -> 3B-JY004便携式储能电源4KG | G6: =_xlfn.XLOOKUP(E6,'6月控价 '!F:F,'6月控价 '!T:T) -> 499 | H6: =_xlfn.XLOOKUP(E6,'6月控价 '!F:F,'6月控价 '!U:U) -> 399.2 | I6: / | J6: 0.19 | K6: =G6*(1-0.19) -> 404.19
A7: TechWave & EXPOSE | B7: 46148 | C7: 0.2 | D7: 1733108275034490485 | E7: M4CC2500589X9 | F7: =_xlfn.XLOOKUP(E7,'6月控价 '!F:F,'6月控价 '!E:E) -> #N/A | G7: 235 | H7: 188 | I7: /
A8: TechWave & EXPOSE | B8: 46148 | C8: 0.1 | D8: 1730401820766799477 | E8: M4CC2500589X9 | F8: =_xlfn.XLOOKUP(E8,'6月控价 '!F:F,'6月控价 '!E:E) -> #N/A | G8: 235 | H8: 188 | I8: /
A9: TechWave & EXPOSE | B9: 46148 | C9: 0.1 | D9: 1729782181369120373 | E9: T3CC1120605 | F9: =_xlfn.XLOOKUP(E9,'6月控价 '!F:F,'6月控价 '!E:E) -> 3C-32至70寸电视移动支架的单支架 | G9: 147 | H9: =_xlfn.XLOOKUP(E9,'6月控价 '!F:F,'6月控价 '!U:U) -> 102.4 | I9: / | J9: 0.14 | K9: =G9*(1-0.14) -> 126.42
A10: TechWave & EXPOSE | B10: 46150 | C10: 0.1 | E10: M4CC3300283 | F10: =_xlfn.XLOOKUP(E10,'6月控价 '!F:F,'6月控价 '!E:E) -> 3B-便携式储能电源 | G10: 244 | H10: 195.2 | I10: /
A11: EXPOSE.Tech Wealth | B11: 46168 | C11: 0.1 | D11: 1734914291005818537 | E11: M5CC1721048 | F11: 3C-高亮自动对焦灯带投影仪Z300 | G11: 624 | H11: 499 | I11: / | J11: 0.2 | K11: 499 | L11: 0.1

Sheet 6月控价 
A1: 产品信息 | J1: 拓展信息 | R1: 控价信息 | AB1: 0.54 | AH1: 8% off Capped at RM20.00, on orders ≥ RM50.00 All customers Co-funding ratio: Platform 70 % / Seller 30 % Maximum funding from seller: RM6.00 | AI1: 18% off Capped at RM70.00, on orders ≥ RM200.00 All customers Co-funding ratio: Platform 70 % / Seller 30 % Maximum funding from seller: RM21.00 | AJ1: 28% off Capped at RM350.00, on orders ≥ RM380.00 All customers Co-funding ratio: Platform 70 % / Seller 30 % Maximum funding from seller: RM105.00 | AK1: 25% off Capped at RM350.00, on orders ≥ RM380.00 All customers Co-funding ratio: Platform 70 % / Seller 30 % Maximum funding from seller: RM105.00 | AL1: 22% off Capped at RM300.00, on orders ≥ RM380.00 All customers Co-funding ratio: Platform 70 % / Seller 30 % Maximum funding from seller: RM90.00 | AM1: 18% off Capped at RM120.00, on orders ≥ RM250.00 All customers Co-funding ratio: Platform 70 % / Seller 30 % Maximum funding from seller: RM36.00 | AN1: 15% off Capped at RM60.00, on orders ≥ RM180.00 All customers Co-funding ratio: Platform 70 % / Seller 30 % Maximum funding from seller: RM18.00
A2: 一级品类 | B2: 二级品类 | C2: 三级品类 | D2: 款名 | E2: 商品名称 | F2: SKU | G2: 推品定位 | H2: 清关方式 | I2: SKU状态 | J2: 交期时长/天 | K2: 是否超期 | L2: 是否超期 | M2: 新款年月 | N2: 是否新品 | O2: 库存深度 | P2: 毛重 | Q2: 体积重 | R2: 6月成本 | S2: 6月控价 | T2: 提价25% （折扣价） | U2: 降价20% (到手价） | V2: 实际优惠卷 | W2: 标价利润 | X2: 到账利润 | Y2: 交易费 抽点 | Z2: 手续费 抽点 | AA2: 返现服务费 抽点 | AB2: 订单处理费 | AC2: 达人佣金 抽点 | AD2: 公开佣金 | AE2: 广告佣金 | AF2: 活动期间优惠卷 | AH2: 需要承担的金额 | AI2: 需要承担的金额
A3: 办公安防 | B3: 智能安防 | C3: =_xlfn.XLOOKUP(F3,'6月产品包'!B:B,'6月产品包'!H:H) -> 智能锁 | D3: =_xlfn.XLOOKUP(F3,'6月产品包'!B:B,'6月产品包'!O:O) -> 手柄门锁 | E3: 3B-四功能智能门锁 | F3: T4CC2120433 | G3: 平销款 | H3: ZQ | I3: =_xlfn.XLOOKUP($F3,'6月库存'!A:A,'6月库存'!B:B) -> 正常销售 | K3: =_xlfn.XLOOKUP(E3,'[1]6月分配 '!$B:$B,'[1]6月分配 '!$K:$K) -> #N/A | L3: =IF(ISNUMBER(K3),"是",IF(ISNA(K3),"否","")) -> 否 | M3: =_xlfn.XLOOKUP(F3,'6月产品包'!B:B,'6月产品包'!J:J) -> 2025-02-25 | N3: =IF(DATEDIF(M3,TODAY(),"m")<6,"新品","老品") -> 老品 | O3: =_xlfn.XLOOKUP(F3,'6月库存'!A:A,'6月库存'!R:R) -> 270 | P3: =_xlfn.XLOOKUP(F3,'6月产品包'!B:B,'6月产品包'!S:S) -> 1950 | R3: =_xlfn.XLOOKUP(F3,'6月产品包'!B:B,'6月产品包'!AD:AD) -> 55.448 | S3: 106 | T3: =ROUND(S3*(1+0.25),0) -> 133 | U3: =$T3*(1-0.18) -> 109.06 | V3: 0.18 | W3: =(U3-R3)/U3 -> 0.49158262 | X3: =(U3*(1-Y3-Z3-AA3-AC3-AB3)-R3)/(U3*(1-Y3-Z3-AA3-AC3-AB3)) -> 0.30643427 | Y3: 0.038 | Z3: 0.115 | AA3: 0.049 | AB3: =$AB$1/U3 -> 0.0049514029 | AC3: 0.06 | AF3: 不进 | AG3: =MAX(AH3:AN3) -> 6 | AH3: =IF(U3>=50,MIN(MIN(U3*0.2,20)*0.3,6),0) -> 6 | AI3: =IF(U3>=200,MIN(MIN(U3*0.18,70)*0.3,21),0) -> 0 | AJ3: =IF(U3>=380,MIN(MIN(U3*0.28,350)*0.3,105),0) -> 0 | AK3: =IF(U3>=380,MIN(MIN(U3*0.25,350)*0.3,105),0) -> 0 | AL3: =IF(U3>=380,MIN(MIN(U3*0.22,300)*0.3,90),0) -> 0 | AM3: =IF(U3>=250,MIN(MIN(U3*0.18,120)*0.3,36),0) -> 0 | AN3: =IF(U3>=180,MIN(MIN(U3*0.15,60)*0.3,18),0) -> 0
A4: 办公安防 | B4: 储能设备 | C4: =_xlfn.XLOOKUP(F4,'6月产品包'!B:B,'6月产品包'!H:H) -> 便携储能电源 | D4: =_xlfn.XLOOKUP(F4,'6月产品包'!B:B,'6月产品包'!O:O) -> JY004电源 | E4: 3B-JY004便携式储能电源8KG | F4: M4CC3300655 | G4: 利润款 | H4: MD | I4: =_xlfn.XLOOKUP($F4,'6月库存'!A:A,'6月库存'!B:B) -> 商品清仓 | K4: =_xlfn.XLOOKUP(E4,'[1]6月分配 '!$B:$B,'[1]6月分配 '!$K:$K) -> #N/A | L4: =IF(ISNUMBER(K4),"是",IF(ISNA(K4),"否","")) -> 否 | M4: =_xlfn.XLOOKUP(F4,'6月产品包'!B:B,'6月产品包'!J:J) -> 2025-09-11 | N4: =IF(DATEDIF(M4,TODAY(),"m")<6,"新品","老品") -> 老品 | O4: =_xlfn.XLOOKUP(F4,'6月库存'!A:A,'6月库存'!R:R) -> 0 | P4: =_xlfn.XLOOKUP(F4,'6月产品包'!B:B,'6月产品包'!S:S) -> 10750 | Q4: 11000 | R4: =_xlfn.XLOOKUP(F4,'6月产品包'!B:B,'6月产品包'!AD:AD) -> 511.9573 | S4: 1099 | T4: =ROUND(S4*(1+0.25),0) -> 1374 | U4: =$T4*(1-0.2) -> 1099.2 | V4: 0.2 | W4: =(U4-R4)/U4 -> 0.53424554 | X4: =(U4*(1-Y4-Z4-AA4-AC4-AB4)-R4)/(U4*(1-Y4-Z4-AA4-AC4-AB4)) -> 0.37692439 | Y4: 0.038 | Z4: 0.105 | AA4: 0.049 | AB4: =$AB$1/U4 -> 0.00049126638 | AC4: 0.06 | AF4: 不进 | AG4: =MAX(AH4:AN4) -> 92.3328 | AH4: =IF(U4>=50,MIN(MIN(U4*0.2,20)*0.3,6),0) -> 6 | AI4: =IF(U4>=200,MIN(MIN(U4*0.18,70)*0.3,21),0) -> 21 | AJ4: =IF(U4>=380,MIN(MIN(U4*0.28,350)*0.3,105),0) -> 92.3328 | AK4: =IF(U4>=380,MIN(MIN(U4*0.25,350)*0.3,105),0) -> 82.44 | AL4: =IF(U4>=380,MIN(MIN(U4*0.22,300)*0.3,90),0) -> 72.5472 | AM4: =IF(U4>=250,MIN(MIN(U4*0.18,120)*0.3,36),0) -> 36 | AN4: =IF(U4>=180,MIN(MIN(U4*0.15,60)*0.3,18),0) -> 18
A5: 3C数码 | B5: 电脑周边 | C5: =_xlfn.XLOOKUP(F5,'6月产品包'!B:B,'6月产品包'!H:H) -> 显示器 | D5: =_xlfn.XLOOKUP(F5,'6月产品包'!B:B,'6月产品包'!O:O) -> 15.6寸便携显示器非触摸款 | E5: 3C-15.6寸60Hz直面1K便携式显示器黑色 | F5: T3CC1910583 | G5: 平销 | H5: MD | I5: =_xlfn.XLOOKUP($F5,'6月库存'!A:A,'6月库存'!B:B) -> 正常销售 | K5: =_xlfn.XLOOKUP(E5,'[1]6月分配 '!$B:$B,'[1]6月分配 '!$K:$K) -> #N/A | L5: =IF(ISNUMBER(K5),"是",IF(ISNA(K5),"否","")) -> 否 | M5: =_xlfn.XLOOKUP(F5,'6月产品包'!B:B,'6月产品包'!J:J) -> 2024-04-01 | N5: =IF(DATEDIF(M5,TODAY(),"m")<6,"新品","老品") -> 老品 | O5: =_xlfn.XLOOKUP(F5,'6月库存'!A:A,'6月库存'!R:R) -> 1 | P5: =_xlfn.XLOOKUP(F5,'6月产品包'!B:B,'6月产品包'!S:S) -> 1378 | R5: =_xlfn.XLOOKUP(F5,'6月产品包'!B:B,'6月产品包'!AD:AD) -> 144.014 | S5: 310 | T5: =ROUND(S5*(1+0.25),0) -> 388 | U5: =$T5*(1-0.2) -> 310.4 | V5: 0.2 | W5: =(U5-R5)/U5 -> 0.53603737 | X5: =(U5*(1-Y5-Z5-AA5-AC5-AB5)-R5)/(U5*(1-Y5-Z5-AA5-AC5-AB5)) -> 0.39053354 | Y5: 0.038 | Z5: 0.09 | AA5: 0.049 | AB5: =$AB$1/U5 -> 0.0017396907 | AC5: 0.06 | AF5: 不进 | AG5: =MAX(AH5:AN5) -> 16.7616 | AH5: =IF(U5>=50,MIN(MIN(U5*0.2,20)*0.3,6),0) -> 6 | AI5: =IF(U5>=200,MIN(MIN(U5*0.18,70)*0.3,21),0) -> 16.7616 | AJ5: =IF(U5>=380,MIN(MIN(U5*0.28,350)*0.3,105),0) -> 0 | AK5: =IF(U5>=380,MIN(MIN(U5*0.25,350)*0.3,105),0) -> 0 | AL5: =IF(U5>=380,MIN(MIN(U5*0.22,300)*0.3,90),0) -> 0 | AM5: =IF(U5>=250,MIN(MIN(U5*0.18,120)*0.3,36),0) -> 16.7616 | AN5: =IF(U5>=180,MIN(MIN(U5*0.15,60)*0.3,18),0) -> 13.968
A6: 办公安防 | B6: 储能设备 | C6: =_xlfn.XLOOKUP(F6,'6月产品包'!B:B,'6月产品包'!H:H) -> 便携储能电源 | D6: =_xlfn.XLOOKUP(F6,'6月产品包'!B:B,'6月产品包'!O:O) -> 便携电源 | E6: 3B-便携式储能电源 | F6: M4CC3300283 | G6: 平销款 | H6: MD | I6: =_xlfn.XLOOKUP($F6,'6月库存'!A:A,'6月库存'!B:B) -> 商品清仓 | K6: =_xlfn.XLOOKUP(E6,'[1]6月分配 '!$B:$B,'[1]6月分配 '!$K:$K) -> 232286 | L6: =IF(ISNUMBER(K6),"是",IF(ISNA(K6),"否","")) -> 是 | M6: =_xlfn.XLOOKUP(F6,'6月产品包'!B:B,'6月产品包'!J:J) -> 2025-06-03 | N6: =IF(DATEDIF(M6,TODAY(),"m")<6,"新品","老品") -> 老品 | O6: =_xlfn.XLOOKUP(F6,'6月库存'!A:A,'6月库存'!R:R) -> 1753 | P6: =_xlfn.XLOOKUP(F6,'6月产品包'!B:B,'6月产品包'!S:S) -> 1800 | R6: =_xlfn.XLOOKUP(F6,'6月产品包'!B:B,'6月产品包'!AD:AD) -> 100.576 | S6: 195 | T6: =ROUND(S6*(1+0.25),0) -> 244 | U6: =$T6*(1-0.2) -> 195.2 | V6: 0.2 | W6: =(U6-R6)/U6 -> 0.4847541 | X6: =(U6*(1-Y6-Z6-AA6-AC6-AB6)-R6)/(U6*(1-Y6-Z6-AA6-AC6-AB6)) -> 0.30861156 | Y6: 0.038 | Z6: 0.105 | AA6: 0.049 | AB6: =$AB$1/U6 -> 0.0027663934 | AC6: 0.06 | AD6: 0.05 | AE6: 0.03 | AF6: 原价进 | AG6: =MAX(AH6:AN6) -> 8.784 | AH6: =IF(U6>=50,MIN(MIN(U6*0.2,20)*0.3,6),0) -> 6 | AI6: =IF(U6>=200,MIN(MIN(U6*0.18,70)*0.3,21),0) -> 0 | AJ6: =IF(U6>=380,MIN(MIN(U6*0.28,350)*0.3,105),0) -> 0 | AK6: =IF(U6>=380,MIN(MIN(U6*0.25,350)*0.3,105),0) -> 0 | AL6: =IF(U6>=380,MIN(MIN(U6*0.22,300)*0.3,90),0) -> 0 | AM6: =IF(U6>=250,MIN(MIN(U6*0.18,120)*0.3,36),0) -> 0 | AN6: =IF(U6>=180,MIN(MIN(U6*0.15,60)*0.3,18),0) -> 8.784
A7: 办公安防 | B7: 办公周边 | C7: =_xlfn.XLOOKUP(F7,'6月产品包'!B:B,'6月产品包'!H:H) -> 打印机 | D7: =_xlfn.XLOOKUP(F7,'6月产品包'!B:B,'6月产品包'!O:O) -> 面单打印机 | E7: 3B-快递面单打印机白色 | F7: M4CC0200477 | G7: #N/A | H7: ZQ | I7: =_xlfn.XLOOKUP($F7,'6月库存'!A:A,'6月库存'!B:B) -> 正常销售 | K7: =_xlfn.XLOOKUP(E7,'[1]6月分配 '!$B:$B,'[1]6月分配 '!$K:$K) -> #N/A | L7: =IF(ISNUMBER(K7),"是",IF(ISNA(K7),"否","")) -> 否 | M7: =_xlfn.XLOOKUP(F7,'6月产品包'!B:B,'6月产品包'!J:J) -> 2025-03-29 | N7: =IF(DATEDIF(M7,TODAY(),"m")<6,"新品","老品") -> 老品 | O7: =_xlfn.XLOOKUP(F7,'6月库存'!A:A,'6月库存'!R:R) -> 0 | P7: =_xlfn.XLOOKUP(F7,'6月产品包'!B:B,'6月产品包'!S:S) -> 2375 | R7: =_xlfn.XLOOKUP(F7,'6月产品包'!B:B,'6月产品包'!AD:AD) -> 122.177 | S7: 227 | T7: =ROUND(S7*(1+0.25),0) -> 284 | U7: =$T7*(1-0.2) -> 227.2 | V7: 0.2 | W7: =(U7-R7)/U7 -> 0.46224912 | X7: =(U7*(1-Y7-Z7-AA7-AC7-AB7)-R7)/(U7*(1-Y7-Z7-AA7-AC7-AB7)) -> 0.28168022 | Y7: 0.04 | Z7: 0.1 | AA7: 0.049 | AB7: =$AB$1/U7 -> 0.0023767606 | AC7: 0.06 | AF7: 不进 | AG7: =MAX(AH7:AN7) -> 12.2688 | AH7: =IF(U7>=50,MIN(MIN(U7*0.2,20)*0.3,6),0) -> 6 | AI7: =IF(U7>=200,MIN(MIN(U7*0.18,70)*0.3,21),0) -> 12.2688 | AJ7: =IF(U7>=380,MIN(MIN(U7*0.28,350)*0.3,105),0) -> 0 | AK7: =IF(U7>=380,MIN(MIN(U7*0.25,350)*0.3,105),0) -> 0 | AL7: =IF(U7>=380,MIN(MIN(U7*0.22,300)*0.3,90),0) -> 0 | AM7: =IF(U7>=250,MIN(MIN(U7*0.18,120)*0.3,36),0) -> 0 | AN7: =IF(U7>=180,MIN(MIN(U7*0.15,60)*0.3,18),0) -> 10.224
A8: 办公安防 | B8: 办公周边 | C8: =_xlfn.XLOOKUP(F8,'6月产品包'!B:B,'6月产品包'!H:H) -> 打印机 | D8: =_xlfn.XLOOKUP(F8,'6月产品包'!B:B,'6月产品包'!O:O) -> 面单打印机 | E8: 3B-快递面单打印机白色 | F8: M4CC2500477 | G8: #N/A | H8: ZQ | I8: =_xlfn.XLOOKUP($F8,'6月库存'!A:A,'6月库存'!B:B) -> 正常销售 | K8: =_xlfn.XLOOKUP(E8,'[1]6月分配 '!$B:$B,'[1]6月分配 '!$K:$K) -> #N/A | L8: =IF(ISNUMBER(K8),"是",IF(ISNA(K8),"否","")) -> 否 | M8: =_xlfn.XLOOKUP(F8,'6月产品包'!B:B,'6月产品包'!J:J) -> 2025-09-27 | N8: =IF(DATEDIF(M8,TODAY(),"m")<6,"新品","老品") -> 老品 | O8: =_xlfn.XLOOKUP(F8,'6月库存'!A:A,'6月库存'!R:R) -> 12 | P8: =_xlfn.XLOOKUP(F8,'6月产品包'!B:B,'6月产品包'!S:S) -> 1688 | R8: =_xlfn.XLOOKUP(F8,'6月产品包'!B:B,'6月产品包'!AD:AD) -> 108.6688 | S8: 207 | T8: =ROUND(S8*(1+0.25),0) -> 259 | U8: =$T8*(1-0.2) -> 207.2 | V8: 0.2 | W8: =(U8-R8)/U8 -> 0.47553668 | X8: =(U8*(1-Y8-Z8-AA8-AC8-AB8)-R8)/(U8*(1-Y8-Z8-AA8-AC8-AB8)) -> 0.29921479 | Y8: 0.04 | Z8: 0.1 | AA8: 0.049 | AB8: =$AB$1/U8 -> 0.0026061776 | AC8: 0.06 | AF8: 不进 | AG8: =MAX(AH8:AN8) -> 11.1888 | AH8: =IF(U8>=50,MIN(MIN(U8*0.2,20)*0.3,6),0) -> 6 | AI8: =IF(U8>=200,MIN(MIN(U8*0.18,70)*0.3,21),0) -> 11.1888 | AJ8: =IF(U8>=380,MIN(MIN(U8*0.28,350)*0.3,105),0) -> 0 | AK8: =IF(U8>=380,MIN(MIN(U8*0.25,350)*0.3,105),0) -> 0 | AL8: =IF(U8>=380,MIN(MIN(U8*0.22,300)*0.3,90),0) -> 0 | AM8: =IF(U8>=250,MIN(MIN(U8*0.18,120)*0.3,36),0) -> 0 | AN8: =IF(U8>=180,MIN(MIN(U8*0.15,60)*0.3,18),0) -> 9.324
A9: 3C数码 | B9: 电脑周边 | C9: =_xlfn.XLOOKUP(F9,'6月产品包'!B:B,'6月产品包'!H:H) -> 显示器 | D9: =_xlfn.XLOOKUP(F9,'6月产品包'!B:B,'6月产品包'!O:O) -> 15.6寸便携显示器触摸款 | E9: 3C-15.6寸60Hz直面1K便携式触摸显示器黑色 | F9: T3CC1910582 | G9: 平销 | H9: MD | I9: =_xlfn.XLOOKUP($F9,'6月库存'!A:A,'6月库存'!B:B) -> 正常销售 | K9: =_xlfn.XLOOKUP(E9,'[1]6月分配 '!$B:$B,'[1]6月分配 '!$K:$K) -> #N/A | L9: =IF(ISNUMBER(K9),"是",IF(ISNA(K9),"否","")) -> 否 | M9: =_xlfn.XLOOKUP(F9,'6月产品包'!B:B,'6月产品包'!J:J) -> 2024-03-19 | N9: =IF(DATEDIF(M9,TODAY(),"m")<6,"新品","老品") -> 老品 | O9: =_xlfn.XLOOKUP(F9,'6月库存'!A:A,'6月库存'!R:R) -> 0 | P9: =_xlfn.XLOOKUP(F9,'6月产品包'!B:B,'6月产品包'!S:S) -> 1480 | R9: =_xlfn.XLOOKUP(F9,'6月产品包'!B:B,'6月产品包'!AD:AD) -> 200.9874 | S9: 420 | T9: =ROUND(S9*(1+0.25),0) -> 525 | U9: =$T9*(1-0.2) -> 420 | V9: 0.2 | W9: =(U9-R9)/U9 -> 0.52145857 | X9: =(U9*(1-Y9-Z9-AA9-AC9-AB9)-R9)/(U9*(1-Y9-Z9-AA9-AC9-AB9)) -> 0.37175731 | Y9: 0.038 | Z9: 0.09 | AA9: 0.049 | AB9: =$AB$1/U9 -> 0.0012857143 | AC9: 0.06 | AF9: 不进 | AG9: =MAX(AH9:AN9) -> 35.28 | AH9: =IF(U9>=50,MIN(MIN(U9*0.2,20)*0.3,6),0) -> 6 | AI9: =IF(U9>=200,MIN(MIN(U9*0.18,70)*0.3,21),0) -> 21 | AJ9: =IF(U9>=380,MIN(MIN(U9*0.28,350)*0.3,105),0) -> 35.28 | AK9: =IF(U9>=380,MIN(MIN(U9*0.25,350)*0.3,105),0) -> 31.5 | AL9: =IF(U9>=380,MIN(MIN(U9*0.22,300)*0.3,90),0) -> 27.72 | AM9: =IF(U9>=250,MIN(MIN(U9*0.18,120)*0.3,36),0) -> 22.68 | AN9: =IF(U9>=180,MIN(MIN(U9*0.15,60)*0.3,18),0) -> 18
A10: 办公安防 | B10: 智能安防 | C10: =_xlfn.XLOOKUP(F10,'6月产品包'!B:B,'6月产品包'!H:H) -> 智能锁 | D10: =_xlfn.XLOOKUP(F10,'6月产品包'!B:B,'6月产品包'!O:O) -> 球型门锁 | E10: 3B-球型门锁Q7豪华款 | F10: T4CC2120715 | G10: 平销款 | H10: ZQ | I10: =_xlfn.XLOOKUP($F10,'6月库存'!A:A,'6月库存'!B:B) -> 正常销售 | K10: =_xlfn.XLOOKUP(E10,'[1]6月分配 '!$B:$B,'[1]6月分配 '!$K:$K) -> #N/A | L10: =IF(ISNUMBER(K10),"是",IF(ISNA(K10),"否","")) -> 否 | M10: =_xlfn.XLOOKUP(F10,'6月产品包'!B:B,'6月产品包'!J:J) -> 2025-05-24 | N10: =IF(DATEDIF(M10,TODAY(),"m")<6,"新品","老品") -> 老品 | O10: =_xlfn.XLOOKUP(F10,'6月库存'!A:A,'6月库存'!R:R) -> 63 | P10: =_xlfn.XLOOKUP(F10,'6月产品包'!B:B,'6月产品包'!S:S) -> 797 | R10: =_xlfn.XLOOKUP(F10,'6月产品包'!B:B,'6月产品包'!AD:AD) -> 73.95 | S10: 150 | T10: =ROUND(S10*(1+0.25),0) -> 188 | U10: =$T10*(1-0.2) -> 150.4 | V10: 0.2 | W10: =(U10-R10)/U10 -> 0.50831117 | X10: =(U10*(1-Y10-Z10-AA10-AC10-AB10)-R10)/(U10*(1-Y10-Z10-AA10-AC10-AB10)) -> 0.33049779 | Y10: 0.038 | Z10: 0.115 | AA10: 0.049 | AB10: =$AB$1/U10 -> 0.0035904255 | AC10: 0.06 | AF10: 不进 | AG10: =MAX(AH10:AN10) -> 6 | AH10: =IF(U10>=50,MIN(MIN(U10*0.2,20)*0.3,6),0) -> 6 | AI10: =IF(U10>=200,MIN(MIN(U10*0.18,70)*0.3,21),0) -> 0 | AJ10: =IF(U10>=380,MIN(MIN(U10*0.28,350)*0.3,105),0) -> 0 | AK10: =IF(U10>=380,MIN(MIN(U10*0.25,350)*0.3,105),0) -> 0 | AL10: =IF(U10>=380,MIN(MIN(U10*0.22,300)*0.3,90),0) -> 0 | AM10: =IF(U10>=250,MIN(MIN(U10*0.18,120)*0.3,36),0) -> 0 | AN10: =IF(U10>=180,MIN(MIN(U10*0.15,60)*0.3,18),0) -> 0
A11: =_xlfn.XLOOKUP(F11,'6月产品包'!B:B,'6月产品包'!F:F) -> 3C数码 | B11: =_xlfn.XLOOKUP(F11,'6月产品包'!B:B,'6月产品包'!G:G) -> 影像摄影 | C11: =_xlfn.XLOOKUP(F11,'6月产品包'!B:B,'6月产品包'!H:H) -> 口袋运动相机 | D11: =_xlfn.XLOOKUP(F11,'6月产品包'!B:B,'6月产品包'!O:O) -> 运动相机 | E11: =_xlfn.XLOOKUP(F11,'6月产品包'!B:B,'6月产品包'!C:C) -> 3C-口袋运动相机11.7cm*3.4cm | F11: T4CC2310722 | G11: 平销款 | H11: MD | I11: =_xlfn.XLOOKUP($F11,'6月库存'!A:A,'6月库存'!B:B) -> 正常销售 | K11: =_xlfn.XLOOKUP(E11,'[1]6月分配 '!$B:$B,'[1]6月分配 '!$K:$K) -> #N/A | L11: =IF(ISNUMBER(K11),"是",IF(ISNA(K11),"否","")) -> 否 | M11: =_xlfn.XLOOKUP(F11,'6月产品包'!B:B,'6月产品包'!J:J) -> 2025-07-10 | N11: =IF(DATEDIF(M11,TODAY(),"m")<6,"新品","老品") -> 老品 | O11: =_xlfn.XLOOKUP(F11,'6月库存'!A:A,'6月库存'!R:R) -> 1 | P11: =_xlfn.XLOOKUP(F11,'6月产品包'!B:B,'6月产品包'!S:S) -> 335 | R11: =_xlfn.XLOOKUP(F11,'6月产品包'!B:B,'6月产品包'!AD:AD) -> 100.5952 | S11: 185 | T11: =ROUND(S11*(1+0.25),0) -> 231 | U11: =$T11*(1-0.2) -> 184.8 | V11: 0.2 | W11: =(U11-R11)/U11 -> 0.45565368 | X11: =(U11*(1-Y11-Z11-AA11-AC11-AB11)-R11)/(U11*(1-Y11-Z11-AA11-AC11-AB11)) -> 0.28382827 | Y11: 0.038 | Z11: 0.09 | AA11: 0.049 | AB11: =$AB$1/U11 -> 0.0029220779 | AC11: 0.06 | AF11: 不进 | AG11: =MAX(AH11:AN11) -> 8.316 | AH11: =IF(U11>=50,MIN(MIN(U11*0.2,20)*0.3,6),0) -> 6 | AI11: =IF(U11>=200,MIN(MIN(U11*0.18,70)*0.3,21),0) -> 0 | AJ11: =IF(U11>=380,MIN(MIN(U11*0.28,350)*0.3,105),0) -> 0 | AK11: =IF(U11>=380,MIN(MIN(U11*0.25,350)*0.3,105),0) -> 0 | AL11: =IF(U11>=380,MIN(MIN(U11*0.22,300)*0.3,90),0) -> 0 | AM11: =IF(U11>=250,MIN(MIN(U11*0.18,120)*0.3,36),0) -> 0 | AN11: =IF(U11>=180,MIN(MIN(U11*0.15,60)*0.3,18),0) -> 8.316
A12: 办公安防 | B12: 办公周边 | C12: =_xlfn.XLOOKUP(F12,'6月产品包'!B:B,'6月产品包'!H:H) -> 标签打印纸 | D12: =_xlfn.XLOOKUP(F12,'6月产品包'!B:B,'6月产品包'!O:O) -> 热敏打印纸 | E12: 3B-宽57cm热敏打印纸5卷 | F12: T4CC0200377 | G12: 引流款 | H12: ZQ | I12: =_xlfn.XLOOKUP($F12,'6月库存'!A:A,'6月库存'!B:B) -> 正常销售 | K12: =_xlfn.XLOOKUP(E12,'[1]6月分配 '!$B:$B,'[1]6月分配 '!$K:$K) -> #N/A | L12: =IF(ISNUMBER(K12),"是",IF(ISNA(K12),"否","")) -> 否 | M12: =_xlfn.XLOOKUP(F12,'6月产品包'!B:B,'6月产品包'!J:J) -> 2025-02-11 | N12: =IF(DATEDIF(M12,TODAY(),"m")<6,"新品","老品") -> 老品 | O12: =_xlfn.XLOOKUP(F12,'6月库存'!A:A,'6月库存'!R:R) -> 4730 | P12: =_xlfn.XLOOKUP(F12,'6月产品包'!B:B,'6月产品包'!S:S) -> 88 | R12: =_xlfn.XLOOKUP(F12,'6月产品包'!B:B,'6月产品包'!AD:AD) -> 2.4535 | S12: 6.5 | T12: =ROUND(S12*(1+0.25),0) -> 8 | U12: =$T12*(1-0.2) -> 6.4 | V12: 0.2 | W12: =(U12-R12)/U12 -> 0.61664063 | X12: =(U12*(1-Y12-Z12-AA12-AC12-AB12)-R12)/(U12*(1-Y12-Z12-AA12-AC12-AB12)) -> 0.424925 | Y12: 0.04 | Z12: 0.1 | AA12: 0.049 | AB12: =$AB$1/U12 -> 0.084375 | AC12: 0.06 | AF12: 不进 | AG12: =MAX(AH12:AN12) -> 0 | AH12: =IF(U12>=50,MIN(MIN(U12*0.2,20)*0.3,6),0) -> 0 | AI12: =IF(U12>=200,MIN(MIN(U12*0.18,70)*0.3,21),0) -> 0 | AJ12: =IF(U12>=380,MIN(MIN(U12*0.28,350)*0.3,105),0) -> 0 | AK12: =IF(U12>=380,MIN(MIN(U12*0.25,350)*0.3,105),0) -> 0 | AL12: =IF(U12>=380,MIN(MIN(U12*0.22,300)*0.3,90),0) -> 0 | AM12: =IF(U12>=250,MIN(MIN(U12*0.18,120)*0.3,36),0) -> 0 | AN12: =IF(U12>=180,MIN(MIN(U12*0.15,60)*0.3,18),0) -> 0
A13: 办公安防 | B13: 安防存储 | C13: =_xlfn.XLOOKUP(F13,'6月产品包'!B:B,'6月产品包'!H:H) -> 保险箱 | D13: =_xlfn.XLOOKUP(F13,'6月产品包'!B:B,'6月产品包'!O:O) -> 大尺寸保险箱 | E13: 3B-保险箱黑50*35*30 | F13: T4CC1200282 | G13: 平销款 | H13: ZQ | I13: =_xlfn.XLOOKUP($F13,'6月库存'!A:A,'6月库存'!B:B) -> 正常销售 | K13: =_xlfn.XLOOKUP(E13,'[1]6月分配 '!$B:$B,'[1]6月分配 '!$K:$K) -> 171787 | L13: =IF(ISNUMBER(K13),"是",IF(ISNA(K13),"否","")) -> 是 | M13: =_xlfn.XLOOKUP(F13,'6月产品包'!B:B,'6月产品包'!J:J) -> 2025-09-01 | N13: =IF(DATEDIF(M13,TODAY(),"m")<6,"新品","老品") -> 老品 | O13: =_xlfn.XLOOKUP(F13,'6月库存'!A:A,'6月库存'!R:R) -> 0 | P13: =_xlfn.XLOOKUP(F13,'6月产品包'!B:B,'6月产品包'!S:S) -> 12500 | Q13: 12500 | R13: =_xlfn.XLOOKUP(F13,'6月产品包'!B:B,'6月产品包'!AD:AD) -> 114.695 | S13: 235 | T13: =ROUND(S13*(1+0.25),0) -> 294 | U13: =$T13*(1-0.2) -> 235.2 | V13: 0.2 | W13: =(U13-R13)/U13 -> 0.51235119 | X13: =(U13*(1-Y13-Z13-AA13-AC13-AB13)-R13)/(U13*(1-Y13-Z13-AA13-AC13-AB13)) -> 0.34867617 | Y13: 0.04 | Z13: 0.1 | AA13: 0.049 | AB13: =$AB$1/U13 -> 0.0022959184 | AC13: 0.06 | AF13: 原价进 | AG13: =MAX(AH13:AN13) -> 12.7008 | AH13: =IF(U13>=50,MIN(MIN(U13*0.2,20)*0.3,6),0) -> 6 | AI13: =IF(U13>=200,MIN(MIN(U13*0.18,70)*0.3,21),0) -> 12.7008 | AJ13: =IF(U13>=380,MIN(MIN(U13*0.28,350)*0.3,105),0) -> 0 | AK13: =IF(U13>=380,MIN(MIN(U13*0.25,350)*0.3,105),0) -> 0 | AL13: =IF(U13>=380,MIN(MIN(U13*0.22,300)*0.3,90),0) -> 0 | AM13: =IF(U13>=250,MIN(MIN(U13*0.18,120)*0.3,36),0) -> 0 | AN13: =IF(U13>=180,MIN(MIN(U13*0.15,60)*0.3,18),0) -> 10.584
A14: 3C数码 | B14: 电脑周边 | C14: =_xlfn.XLOOKUP(F14,'6月产品包'!B:B,'6月产品包'!H:H) -> 显示器 | D14: =_xlfn.XLOOKUP(F14,'6月产品包'!B:B,'6月产品包'!O:O) -> 11.6寸便携显示器非触摸款 | E14: 3C-11.6寸60Hz直面1K便携式显示器无触摸黑色 | F14: T3CC1910678 | G14: 引流款 | H14: MD | I14: =_xlfn.XLOOKUP($F14,'6月库存'!A:A,'6月库存'!B:B) -> 正常销售 | K14: =_xlfn.XLOOKUP(E14,'[1]6月分配 '!$B:$B,'[1]6月分配 '!$K:$K) -> #N/A | L14: =IF(ISNUMBER(K14),"是",IF(ISNA(K14),"否","")) -> 否 | M14: =_xlfn.XLOOKUP(F14,'6月产品包'!B:B,'6月产品包'!J:J) -> 2024-06-04 | N14: =IF(DATEDIF(M14,TODAY(),"m")<6,"新品","老品") -> 老品 | O14: =_xlfn.XLOOKUP(F14,'6月库存'!A:A,'6月库存'!R:R) -> 406 | P14: =_xlfn.XLOOKUP(F14,'6月产品包'!B:B,'6月产品包'!S:S) -> 940 | R14: =_xlfn.XLOOKUP(F14,'6月产品包'!B:B,'6月产品包'!AD:AD) -> 89.9232 | S14: 176 | T14: =ROUND(S14*(1+0.25),0) -> 220 | U14: =$T14*(1-0.2) -> 176 | V14: 0.2 | W14: =(U14-R14)/U14 -> 0.48907273 | X14: =(U14*(1-Y14-Z14-AA14-AC14-AB14)-R14)/(U14*(1-Y14-Z14-AA14-AC14-AB14)) -> 0.32766696 | Y14: 0.038 | Z14: 0.09 | AA14: 0.049 | AB14: =$AB$1/U14 -> 0.0030681818 | AC14: 0.06 | AF14: 不进 | AG14: =MAX(AH14:AN14) -> 6 | AH14: =IF(U14>=50,MIN(MIN(U14*0.2,20)*0.3,6),0) -> 6 | AI14: =IF(U14>=200,MIN(MIN(U14*0.18,70)*0.3,21),0) -> 0 | AJ14: =IF(U14>=380,MIN(MIN(U14*0.28,350)*0.3,105),0) -> 0 | AK14: =IF(U14>=380,MIN(MIN(U14*0.25,350)*0.3,105),0) -> 0 | AL14: =IF(U14>=380,MIN(MIN(U14*0.22,300)*0.3,90),0) -> 0 | AM14: =IF(U14>=250,MIN(MIN(U14*0.18,120)*0.3,36),0) -> 0 | AN14: =IF(U14>=180,MIN(MIN(U14*0.15,60)*0.3,18),0) -> 0
A15: 办公安防 | B15: 储能设备 | C15: =_xlfn.XLOOKUP(F15,'6月产品包'!B:B,'6月产品包'!H:H) -> #N/A | D15: =_xlfn.XLOOKUP(F15,'6月产品包'!B:B,'6月产品包'!O:O) -> #N/A | E15: 3B-JY004便携式储能电源5KG | F15: M4CC3300654 | G15: 利润款 | H15: MD | I15: =_xlfn.XLOOKUP($F15,'6月库存'!A:A,'6月库存'!B:B) -> 停止销售 | K15: =_xlfn.XLOOKUP(E15,'[1]6月分配 '!$B:$B,'[1]6月分配 '!$K:$K) -> #N/A | L15: =IF(ISNUMBER(K15),"是",IF(ISNA(K15),"否","")) -> 否 | M15: =_xlfn.XLOOKUP(F15,'6月产品包'!B:B,'6月产品包'!J:J) -> #N/A | N15: =IF(DATEDIF(M15,TODAY(),"m")<6,"新品","老品") -> #N/A | O15: =_xlfn.XLOOKUP(F15,'6月库存'!A:A,'6月库存'!R:R) -> 0 | P15: =_xlfn.XLOOKUP(F15,'6月产品包'!B:B,'6月产品包'!S:S) -> #N/A | R15: =_xlfn.XLOOKUP(F15,'6月产品包'!B:B,'6月产品包'!AD:AD) -> #N/A | S15: 659 | T15: =ROUND(S15*(1+0.25),0) -> 824 | U15: =$T15*(1-0.2) -> 659.2 | V15: 0.2 | W15: =(U15-R15)/U15 -> #N/A | X15: =(U15*(1-Y15-Z15-AA15-AC15-AB15)-R15)/(U15*(1-Y15-Z15-AA15-AC15-AB15)) -> #N/A | Y15: 0.038 | Z15: 0.105 | AA15: 0.049 | AB15: =$AB$1/U15 -> 0.00081917476 | AC15: 0.06 | AF15: 不进 | AG15: =MAX(AH15:AN15) -> 55.3728 | AH15: =IF(U15>=50,MIN(MIN(U15*0.2,20)*0.3,6),0) -> 6 | AI15: =IF(U15>=200,MIN(MIN(U15*0.18,70)*0.3,21),0) -> 21 | AJ15: =IF(U15>=380,MIN(MIN(U15*0.28,350)*0.3,105),0) -> 55.3728 | AK15: =IF(U15>=380,MIN(MIN(U15*0.25,350)*0.3,105),0) -> 49.44 | AL15: =IF(U15>=380,MIN(MIN(U15*0.22,300)*0.3,90),0) -> 43.5072 | AM15: =IF(U15>=250,MIN(MIN(U15*0.18,120)*0.3,36),0) -> 35.5968 | AN15: =IF(U15>=180,MIN(MIN(U15*0.15,60)*0.3,18),0) -> 18
A16: 办公安防 | B16: 安防存储 | C16: =_xlfn.XLOOKUP(F16,'6月产品包'!B:B,'6月产品包'!H:H) -> 保险箱 | D16: =_xlfn.XLOOKUP(F16,'6月产品包'!B:B,'6月产品包'!O:O) -> 大尺寸保险箱 | E16: 3B-保险箱黑50*35*30 | F16: T4CC2610282 | G16: 平销款 | H16: ZQ | I16: =_xlfn.XLOOKUP($F16,'6月库存'!A:A,'6月库存'!B:B) -> 正常销售 | K16: =_xlfn.XLOOKUP(E16,'[1]6月分配 '!$B:$B,'[1]6月分配 '!$K:$K) -> 171787 | L16: =IF(ISNUMBER(K16),"是",IF(ISNA(K16),"否","")) -> 是 | M16: =_xlfn.XLOOKUP(F16,'6月产品包'!B:B,'6月产品包'!J:J) -> 2025-12-02 | N16: =IF(DATEDIF(M16,TODAY(),"m")<6,"新品","老品") -> 老品 | O16: =_xlfn.XLOOKUP(F16,'6月库存'!A:A,'6月库存'!R:R) -> 918 | P16: =_xlfn.XLOOKUP(F16,'6月产品包'!B:B,'6月产品包'!S:S) -> 12500 | Q16: 12500 | R16: =_xlfn.XLOOKUP(F16,'6月产品包'!B:B,'6月产品包'!AD:AD) -> 121.7304 | S16: 235 | T16: =ROUND(S16*(1+0.25),0) -> 294 | U16: =$T16*(1-0.2) -> 235.2 | V16: 0.2 | W16: =(U16-R16)/U16 -> 0.48243878 | X16: =(U16*(1-Y16-Z16-AA16-AC16-AB16)-R16)/(U16*(1-Y16-Z16-AA16-AC16-AB16)) -> 0.30872392 | Y16: 0.04 | Z16: 0.1 | AA16: 0.049 | AB16: =$AB$1/U16 -> 0.0022959184 | AC16: 0.06 | AF16: 原价进 | AG16: =MAX(AH16:AN16) -> 12.7008 | AH16: =IF(U16>=50,MIN(MIN(U16*0.2,20)*0.3,6),0) -> 6 | AI16: =IF(U16>=200,MIN(MIN(U16*0.18,70)*0.3,21),0) -> 12.7008 | AJ16: =IF(U16>=380,MIN(MIN(U16*0.28,350)*0.3,105),0) -> 0 | AK16: =IF(U16>=380,MIN(MIN(U16*0.25,350)*0.3,105),0) -> 0 | AL16: =IF(U16>=380,MIN(MIN(U16*0.22,300)*0.3,90),0) -> 0 | AM16: =IF(U16>=250,MIN(MIN(U16*0.18,120)*0.3,36),0) -> 0 | AN16: =IF(U16>=180,MIN(MIN(U16*0.15,60)*0.3,18),0) -> 10.584
A17: 办公安防 | B17: 安防存储 | C17: =_xlfn.XLOOKUP(F17,'6月产品包'!B:B,'6月产品包'!H:H) -> 保险箱 | D17: =_xlfn.XLOOKUP(F17,'6月产品包'!B:B,'6月产品包'!O:O) -> 大尺寸保险箱 | E17: 3B-保险箱黑50*35*30 | F17: T3CC2160282 | G17: 平销款 | H17: ZQ | I17: =_xlfn.XLOOKUP($F17,'6月库存'!A:A,'6月库存'!B:B) -> 正常销售 | K17: =_xlfn.XLOOKUP(E17,'[1]6月分配 '!$B:$B,'[1]6月分配 '!$K:$K) -> 171787 | L17: =IF(ISNUMBER(K17),"是",IF(ISNA(K17),"否","")) -> 是 | M17: =_xlfn.XLOOKUP(F17,'6月产品包'!B:B,'6月产品包'!J:J) -> 2024-11-21 | N17: =IF(DATEDIF(M17,TODAY(),"m")<6,"新品","老品") -> 老品 | O17: =_xlfn.XLOOKUP(F17,'6月库存'!A:A,'6月库存'!R:R) -> 5 | P17: =_xlfn.XLOOKUP(F17,'6月产品包'!B:B,'6月产品包'!S:S) -> 12500 | Q17: 12500 | R17: =_xlfn.XLOOKUP(F17,'6月产品包'!B:B,'6月产品包'!AD:AD) -> 126.3066 | S17: 245 | T17: =ROUND(S17*(1+0.25),0) -> 306 | U17: =$T17*(1-0.2) -> 244.8 | V17: 0.2 | W17: =(U17-R17)/U17 -> 0.48404167 | X17: =(U17*(1-Y17-Z17-AA17-AC17-AB17)-R17)/(U17*(1-Y17-Z17-AA17-AC17-AB17)) -> 0.31094767 | Y17: 0.04 | Z17: 0.1 | AA17: 0.049 | AB17: =$AB$1/U17 -> 0.0022058824 | AC17: 0.06 | AF17: 原价进 | AG17: =MAX(AH17:AN17) -> 13.2192 | AH17: =IF(U17>=50,MIN(MIN(U17*0.2,20)*0.3,6),0) -> 6 | AI17: =IF(U17>=200,MIN(MIN(U17*0.18,70)*0.3,21),0) -> 13.2192 | AJ17: =IF(U17>=380,MIN(MIN(U17*0.28,350)*0.3,105),0) -> 0 | AK17: =IF(U17>=380,MIN(MIN(U17*0.25,350)*0.3,105),0) -> 0 | AL17: =IF(U17>=380,MIN(MIN(U17*0.22,300)*0.3,90),0) -> 0 | AM17: =IF(U17>=250,MIN(MIN(U17*0.18,120)*0.3,36),0) -> 0 | AN17: =IF(U17>=180,MIN(MIN(U17*0.15,60)*0.3,18),0) -> 11.016
A18: 办公安防 | B18: 办公周边 | C18: =_xlfn.XLOOKUP(F18,'6月产品包'!B:B,'6月产品包'!H:H) -> 考勤机 | D18: =_xlfn.XLOOKUP(F18,'6月产品包'!B:B,'6月产品包'!O:O) -> 指纹考勤机 | E18: 3B-X1指纹考勤机 | F18: M2CC1530462 | G18: #N/A | H18: MD | I18: =_xlfn.XLOOKUP($F18,'6月库存'!A:A,'6月库存'!B:B) -> 正常销售 | K18: =_xlfn.XLOOKUP(E18,'[1]6月分配 '!$B:$B,'[1]6月分配 '!$K:$K) -> 156679 | L18: =IF(ISNUMBER(K18),"是",IF(ISNA(K18),"否","")) -> 是 | M18: =_xlfn.XLOOKUP(F18,'6月产品包'!B:B,'6月产品包'!J:J) -> 2023-09-11 | N18: =IF(DATEDIF(M18,TODAY(),"m")<6,"新品","老品") -> 老品 | O18: =_xlfn.XLOOKUP(F18,'6月库存'!A:A,'6月库存'!R:R) -> 2237 | P18: =_xlfn.XLOOKUP(F18,'6月产品包'!B:B,'6月产品包'!S:S) -> 466 | R18: =_xlfn.XLOOKUP(F18,'6月产品包'!B:B,'6月产品包'!AD:AD) -> 44.167 | S18: 88 | T18: =ROUND(S18*(1+0.25),0) -> 110 | U18: =$T18*(1-0.2) -> 88 | V18: 0.2 | W18: =(U18-R18)/U18 -> 0.49810227 | X18: =(U18*(1-Y18-Z18-AA18-AC18-AB18)-R18)/(U18*(1-Y18-Z18-AA18-AC18-AB18)) -> 0.32799282 | Y18: 0.038 | Z18: 0.1 | AA18: 0.049 | AB18: =$AB$1/U18 -> 0.0061363636 | AC18: 0.06 | AF18: 原价进 | AG18: =MAX(AH18:AN18) -> 5.28 | AH18: =IF(U18>=50,MIN(MIN(U18*0.2,20)*0.3,6),0) -> 5.28 | AI18: =IF(U18>=200,MIN(MIN(U18*0.18,70)*0.3,21),0) -> 0 | AJ18: =IF(U18>=380,MIN(MIN(U18*0.28,350)*0.3,105),0) -> 0 | AK18: =IF(U18>=380,MIN(MIN(U18*0.25,350)*0.3,105),0) -> 0 | AL18: =IF(U18>=380,MIN(MIN(U18*0.22,300)*0.3,90),0) -> 0 | AM18: =IF(U18>=250,MIN(MIN(U18*0.18,120)*0.3,36),0) -> 0 | AN18: =IF(U18>=180,MIN(MIN(U18*0.15,60)*0.3,18),0) -> 0
A19: =_xlfn.XLOOKUP(F19,'6月产品包'!B:B,'6月产品包'!F:F) -> 3C数码 | B19: =_xlfn.XLOOKUP(F19,'6月产品包'!B:B,'6月产品包'!G:G) -> 影像摄影 | C19: =_xlfn.XLOOKUP(F19,'6月产品包'!B:B,'6月产品包'!H:H) -> LED像素屏 | D19: =_xlfn.XLOOKUP(F19,'6月产品包'!B:B,'6月产品包'!O:O) -> 互动屏 | E19: =_xlfn.XLOOKUP(F19,'6月产品包'!B:B,'6月产品包'!C:C) -> 3C-led智能互动屏17.3cm*7cm | F19: T4CC2320725 | G19: 平销款 | H19: MD | I19: =_xlfn.XLOOKUP($F19,'6月库存'!A:A,'6月库存'!B:B) -> 正常销售 | K19: =_xlfn.XLOOKUP(E19,'[1]6月分配 '!$B:$B,'[1]6月分配 '!$K:$K) -> #N/A | L19: =IF(ISNUMBER(K19),"是",IF(ISNA(K19),"否","")) -> 否 | M19: =_xlfn.XLOOKUP(F19,'6月产品包'!B:B,'6月产品包'!J:J) -> 2025-07-10 | N19: =IF(DATEDIF(M19,TODAY(),"m")<6,"新品","老品") -> 老品 | O19: =_xlfn.XLOOKUP(F19,'6月库存'!A:A,'6月库存'!R:R) -> 157 | P19: =_xlfn.XLOOKUP(F19,'6月产品包'!B:B,'6月产品包'!S:S) -> 238 | Q19: 300 | R19: =_xlfn.XLOOKUP(F19,'6月产品包'!B:B,'6月产品包'!AD:AD) -> 20.9264 | S19: 41.5 | T19: =ROUND(S19*(1+0.25),0) -> 52 | U19: =$T19*(1-0.2) -> 41.6 | V19: 0.2 | W19: =(U19-R19)/U19 -> 0.49696154 | X19: =(U19*(1-Y19-Z19-AA19-AC19-AB19)-R19)/(U19*(1-Y19-Z19-AA19-AC19-AB19)) -> 0.31092437 | Y19: 0.038 | Z19: 0.11 | AA19: 0.049 | AB19: =$AB$1/U19 -> 0.012980769 | AC19: 0.06 | AF19: 不进 | AG19: =MAX(AH19:AN19) -> 0 | AH19: =IF(U19>=50,MIN(MIN(U19*0.2,20)*0.3,6),0) -> 0 | AI19: =IF(U19>=200,MIN(MIN(U19*0.18,70)*0.3,21),0) -> 0 | AJ19: =IF(U19>=380,MIN(MIN(U19*0.28,350)*0.3,105),0) -> 0 | AK19: =IF(U19>=380,MIN(MIN(U19*0.25,350)*0.3,105),0) -> 0 | AL19: =IF(U19>=380,MIN(MIN(U19*0.22,300)*0.3,90),0) -> 0 | AM19: =IF(U19>=250,MIN(MIN(U19*0.18,120)*0.3,36),0) -> 0 | AN19: =IF(U19>=180,MIN(MIN(U19*0.15,60)*0.3,18),0) -> 0
A20: 3C数码 | B20: 电脑周边 | C20: =_xlfn.XLOOKUP(F20,'6月产品包'!B:B,'6月产品包'!H:H) -> 显示器支架 | D20: =_xlfn.XLOOKUP(F20,'6月产品包'!B:B,'6月产品包'!O:O) -> 显示器支架单臂铁塑款 | E20: 3C-显示器支架单臂铁塑款 | F20: T4CC1270889 | G20: 引流款 | H20: ZQ | I20: =_xlfn.XLOOKUP($F20,'6月库存'!A:A,'6月库存'!B:B) -> 正常销售 | K20: =_xlfn.XLOOKUP(E20,'[1]6月分配 '!$B:$B,'[1]6月分配 '!$K:$K) -> #N/A | L20: =IF(ISNUMBER(K20),"是",IF(ISNA(K20),"否","")) -> 否 | M20: =_xlfn.XLOOKUP(F20,'6月产品包'!B:B,'6月产品包'!J:J) -> 2025-10-27 | N20: =IF(DATEDIF(M20,TODAY(),"m")<6,"新品","老品") -> 老品 | O20: =_xlfn.XLOOKUP(F20,'6月库存'!A:A,'6月库存'!R:R) -> 255 | P20: =_xlfn.XLOOKUP(F20,'6月产品包'!B:B,'6月产品包'!S:S) -> 2380 | R20: =_xlfn.XLOOKUP(F20,'6月产品包'!B:B,'6月产品包'!AD:AD) -> 25.2358 | S20: 56 | T20: =ROUND(S20*(1+0.25),0) -> 70 | U20: =$T20*(1-0.2) -> 56 | V20: 0.2 | W20: =(U20-R20)/U20 -> 0.54936071 | X20: =(U20*(1-Y20-Z20-AA20-AC20-AB20)-R20)/(U20*(1-Y20-Z20-AA20-AC20-AB20)) -> 0.38967302 | Y20: 0.038 | Z20: 0.105 | AA20: 0.049 | AB20: =$AB$1/U20 -> 0.0096428571 | AC20: 0.06 | AF20: 不进 | AG20: =MAX(AH20:AN20) -> 3.36 | AH20: =IF(U20>=50,MIN(MIN(U20*0.2,20)*0.3,6),0) -> 3.36 | AI20: =IF(U20>=200,MIN(MIN(U20*0.18,70)*0.3,21),0) -> 0 | AJ20: =IF(U20>=380,MIN(MIN(U20*0.28,350)*0.3,105),0) -> 0 | AK20: =IF(U20>=380,MIN(MIN(U20*0.25,350)*0.3,105),0) -> 0 | AL20: =IF(U20>=380,MIN(MIN(U20*0.22,300)*0.3,90),0) -> 0 | AM20: =IF(U20>=250,MIN(MIN(U20*0.18,120)*0.3,36),0) -> 0 | AN20: =IF(U20>=180,MIN(MIN(U20*0.15,60)*0.3,18),0) -> 0
A21: 3C数码 | B21: 电脑周边 | C21: =_xlfn.XLOOKUP(F21,'6月产品包'!B:B,'6月产品包'!H:H) -> 显示器支架 | D21: =_xlfn.XLOOKUP(F21,'6月产品包'!B:B,'6月产品包'!O:O) -> 显示器支架双臂铁塑款 | E21: 3C-显示器支架双臂铁塑款 | F21: T4CC1270890 | G21: 引流款 | H21: ZQ | I21: =_xlfn.XLOOKUP($F21,'6月库存'!A:A,'6月库存'!B:B) -> 正常销售 | K21: =_xlfn.XLOOKUP(E21,'[1]6月分配 '!$B:$B,'[1]6月分配 '!$K:$K) -> #N/A | L21: =IF(ISNUMBER(K21),"是",IF(ISNA(K21),"否","")) -> 否 | M21: =_xlfn.XLOOKUP(F21,'6月产品包'!B:B,'6月产品包'!J:J) -> 2025-10-27 | N21: =IF(DATEDIF(M21,TODAY(),"m")<6,"新品","老品") -> 老品 | O21: =_xlfn.XLOOKUP(F21,'6月库存'!A:A,'6月库存'!R:R) -> 36 | P21: =_xlfn.XLOOKUP(F21,'6月产品包'!B:B,'6月产品包'!S:S) -> 4480 | R21: =_xlfn.XLOOKUP(F21,'6月产品包'!B:B,'6月产品包'!AD:AD) -> 48.9346 | S21: 103 | T21: =ROUND(S21*(1+0.25),0) -> 129 | U21: =$T21*(1-0.2) -> 103.2 | V21: 0.2 | W21: =(U21-R21)/U21 -> 0.52582752 | X21: =(U21*(1-Y21-Z21-AA21-AC21-AB21)-R21)/(U21*(1-Y21-Z21-AA21-AC21-AB21)) -> 0.36161381 | Y21: 0.038 | Z21: 0.105 | AA21: 0.049 | AB21: =$AB$1/U21 -> 0.0052325581 | AC21: 0.06 | AF21: 不进 | AG21: =MAX(AH21:AN21) -> 6 | AH21: =IF(U21>=50,MIN(MIN(U21*0.2,20)*0.3,6),0) -> 6 | AI21: =IF(U21>=200,MIN(MIN(U21*0.18,70)*0.3,21),0) -> 0 | AJ21: =IF(U21>=380,MIN(MIN(U21*0.28,350)*0.3,105),0) -> 0 | AK21: =IF(U21>=380,MIN(MIN(U21*0.25,350)*0.3,105),0) -> 0 | AL21: =IF(U21>=380,MIN(MIN(U21*0.22,300)*0.3,90),0) -> 0 | AM21: =IF(U21>=250,MIN(MIN(U21*0.18,120)*0.3,36),0) -> 0 | AN21: =IF(U21>=180,MIN(MIN(U21*0.15,60)*0.3,18),0) -> 0
A22: 3C数码 | B22: 电脑周边 | C22: =_xlfn.XLOOKUP(F22,'6月产品包'!B:B,'6月产品包'!H:H) -> 显示器支架 | D22: =_xlfn.XLOOKUP(F22,'6月产品包'!B:B,'6月产品包'!O:O) -> 桌面显示器支架 | E22: 3C-桌面显示器支架钢化玻璃底座 | F22: T3CC1270279 | G22: 利润款 | H22: ZQ | I22: =_xlfn.XLOOKUP($F22,'6月库存'!A:A,'6月库存'!B:B) -> 正常销售 | K22: =_xlfn.XLOOKUP(E22,'[1]6月分配 '!$B:$B,'[1]6月分配 '!$K:$K) -> #N/A | L22: =IF(ISNUMBER(K22),"是",IF(ISNA(K22),"否","")) -> 否 | M22: =_xlfn.XLOOKUP(F22,'6月产品包'!B:B,'6月产品包'!J:J) -> 2024-11-12 | N22: =IF(DATEDIF(M22,TODAY(),"m")<6,"新品","老品") -> 老品 | O22: =_xlfn.XLOOKUP(F22,'6月库存'!A:A,'6月库存'!R:R) -> 36 | P22: =_xlfn.XLOOKUP(F22,'6月产品包'!B:B,'6月产品包'!S:S) -> 4674 | R22: =_xlfn.XLOOKUP(F22,'6月产品包'!B:B,'6月产品包'!AD:AD) -> 27.7356 | S22: 56 | T22: =ROUND(S22*(1+0.25),0) -> 70 | U22: =$T22*(1-0.2) -> 56 | V22: 0.2 | W22: =(U22-R22)/U22 -> 0.50472143 | X22: =(U22*(1-Y22-Z22-AA22-AC22-AB22)-R22)/(U22*(1-Y22-Z22-AA22-AC22-AB22)) -> 0.34947931 | Y22: 0.04 | Z22: 0.08 | AA22: 0.049 | AB22: =$AB$1/U22 -> 0.0096428571 | AC22: 0.06 | AF22: 不进 | AG22: =MAX(AH22:AN22) -> 3.36 | AH22: =IF(U22>=50,MIN(MIN(U22*0.2,20)*0.3,6),0) -> 3.36 | AI22: =IF(U22>=200,MIN(MIN(U22*0.18,70)*0.3,21),0) -> 0 | AJ22: =IF(U22>=380,MIN(MIN(U22*0.28,350)*0.3,105),0) -> 0 | AK22: =IF(U22>=380,MIN(MIN(U22*0.25,350)*0.3,105),0) -> 0 | AL22: =IF(U22>=380,MIN(MIN(U22*0.22,300)*0.3,90),0) -> 0 | AM22: =IF(U22>=250,MIN(MIN(U22*0.18,120)*0.3,36),0) -> 0 | AN22: =IF(U22>=180,MIN(MIN(U22*0.15,60)*0.3,18),0) -> 0
A23: 3C数码 | B23: 电脑周边 | C23: =_xlfn.XLOOKUP(F23,'6月产品包'!B:B,'6月产品包'!H:H) -> 显示器支架 | D23: =_xlfn.XLOOKUP(F23,'6月产品包'!B:B,'6月产品包'!O:O) -> 桌面显示器支架 | E23: 3C-桌面显示器支架钢化玻璃底座 | F23: T4CC1120279 | G23: 利润款 | H23: ZQ | I23: =_xlfn.XLOOKUP($F23,'6月库存'!A:A,'6月库存'!B:B) -> 正常销售 | K23: =_xlfn.XLOOKUP(E23,'[1]6月分配 '!$B:$B,'[1]6月分配 '!$K:$K) -> #N/A | L23: =IF(ISNUMBER(K23),"是",IF(ISNA(K23),"否","")) -> 否 | M23: =_xlfn.XLOOKUP(F23,'6月产品包'!B:B,'6月产品包'!J:J) -> 2025-05-27 | N23: =IF(DATEDIF(M23,TODAY(),"m")<6,"新品","老品") -> 老品 | O23: =_xlfn.XLOOKUP(F23,'6月库存'!A:A,'6月库存'!R:R) -> 78 | P23: =_xlfn.XLOOKUP(F23,'6月产品包'!B:B,'6月产品包'!S:S) -> 4674 | R23: =_xlfn.XLOOKUP(F23,'6月产品包'!B:B,'6月产品包'!AD:AD) -> 27.4676 | S23: 56 | T23: =ROUND(S23*(1+0.25),0) -> 70 | U23: =$T23*(1-0.2) -> 56 | V23: 0.2 | W23: =(U23-R23)/U23 -> 0.50950714 | X23: =(U23*(1-Y23-Z23-AA23-AC23-AB23)-R23)/(U23*(1-Y23-Z23-AA23-AC23-AB23)) -> 0.35576508 | Y23: 0.04 | Z23: 0.08 | AA23: 0.049 | AB23: =$AB$1/U23 -> 0.0096428571 | AC23: 0.06 | AF23: 不进 | AG23: =MAX(AH23:AN23) -> 3.36 | AH23: =IF(U23>=50,MIN(MIN(U23*0.2,20)*0.3,6),0) -> 3.36 | AI23: =IF(U23>=200,MIN(MIN(U23*0.18,70)*0.3,21),0) -> 0 | AJ23: =IF(U23>=380,MIN(MIN(U23*0.28,350)*0.3,105),0) -> 0 | AK23: =IF(U23>=380,MIN(MIN(U23*0.25,350)*0.3,105),0) -> 0 | AL23: =IF(U23>=380,MIN(MIN(U23*0.22,300)*0.3,90),0) -> 0 | AM23: =IF(U23>=250,MIN(MIN(U23*0.18,120)*0.3,36),0) -> 0 | AN23: =IF(U23>=180,MIN(MIN(U23*0.15,60)*0.3,18),0) -> 0
A24: 3C数码 | B24: 音响乐器 | C24: =_xlfn.XLOOKUP(F24,'6月产品包'!B:B,'6月产品包'!H:H) -> 未来吉他 | D24: =_xlfn.XLOOKUP(F24,'6月产品包'!B:B,'6月产品包'!O:O) -> 无弦吉他 | E24: 3C-无弦吉他 | F24: T4CC2420764 | G24: 利润款 | H24: ZQ | I24: =_xlfn.XLOOKUP($F24,'6月库存'!A:A,'6月库存'!B:B) -> 正常销售 | K24: =_xlfn.XLOOKUP(E24,'[1]6月分配 '!$B:$B,'[1]6月分配 '!$K:$K) -> 107362 | L24: =IF(ISNUMBER(K24),"是",IF(ISNA(K24),"否","")) -> 是 | M24: =_xlfn.XLOOKUP(F24,'6月产品包'!B:B,'6月产品包'!J:J) -> 2025-07-26 | N24: 新品 | O24: =_xlfn.XLOOKUP(F24,'6月库存'!A:A,'6月库存'!R:R) -> 172 | P24: =_xlfn.XLOOKUP(F24,'6月产品包'!B:B,'6月产品包'!S:S) -> 3000 | R24: =_xlfn.XLOOKUP(F24,'6月产品包'!B:B,'6月产品包'!AD:AD) -> 413.7546 | S24: 799 | T24: =ROUND(S24*(1+0.25),0) -> 999 | U24: =$T24*(1-0.18) -> 819.18 | V24: 0.18 | W24: =(U24-R24)/U24 -> 0.49491614 | X24: =(U24*(1-Y24-Z24-AA24-AC24-AB24)-R24)/(U24*(1-Y24-Z24-AA24-AC24-AB24)) -> 0.30557469 | Y24: 0.038 | Z24: 0.105 | AA24: 0.049 | AB24: =$AB$1/U24 -> 0.00065919578 | AC24: 0.08 | AD24: 0.06 | AF24: 原价进 | AG24: =MAX(AH24:AN24) -> 68.81112 | AH24: =IF(U24>=50,MIN(MIN(U24*0.2,20)*0.3,6),0) -> 6 | AI24: =IF(U24>=200,MIN(MIN(U24*0.18,70)*0.3,21),0) -> 21 | AJ24: =IF(U24>=380,MIN(MIN(U24*0.28,350)*0.3,105),0) -> 68.81112 | AK24: =IF(U24>=380,MIN(MIN(U24*0.25,350)*0.3,105),0) -> 61.4385 | AL24: =IF(U24>=380,MIN(MIN(U24*0.22,300)*0.3,90),0) -> 54.06588 | AM24: =IF(U24>=250,MIN(MIN(U24*0.18,120)*0.3,36),0) -> 36 | AN24: =IF(U24>=180,MIN(MIN(U24*0.15,60)*0.3,18),0) -> 18
A25: 办公安防 | B25: 办公周边 | C25: =_xlfn.XLOOKUP(F25,'6月产品包'!B:B,'6月产品包'!H:H) -> 点钞机 | D25: =_xlfn.XLOOKUP(F25,'6月产品包'!B:B,'6月产品包'!O:O) -> 点钞机 | E25: 3B-点钞机灰色 | F25: M4CC2580711 | G25: 引流款 | H25: ZQ | I25: =_xlfn.XLOOKUP($F25,'6月库存'!A:A,'6月库存'!B:B) -> 商品清仓 | K25: =_xlfn.XLOOKUP(E25,'[1]6月分配 '!$B:$B,'[1]6月分配 '!$K:$K) -> 83177 | L25: =IF(ISNUMBER(K25),"是",IF(ISNA(K25),"否","")) -> 是 | M25: =_xlfn.XLOOKUP(F25,'6月产品包'!B:B,'6月产品包'!J:J) -> 2025-10-16 | N25: =IF(DATEDIF(M25,TODAY(),"m")<6,"新品","老品") -> 老品 | O25: =_xlfn.XLOOKUP(F25,'6月库存'!A:A,'6月库存'!R:R) -> 1057 | P25: =_xlfn.XLOOKUP(F25,'6月产品包'!B:B,'6月产品包'!S:S) -> 5500 | R25: =_xlfn.XLOOKUP(F25,'6月产品包'!B:B,'6月产品包'!AD:AD) -> 123.6966 | S25: 220 | T25: =ROUND(S25*(1+0.25),0) -> 275 | U25: =$T25*(1-0.2) -> 220 | V25: 0.2 | W25: =(U25-R25)/U25 -> 0.43774273 | X25: =(U25*(1-Y25-Z25-AA25-AC25-AB25)-R25)/(U25*(1-Y25-Z25-AA25-AC25-AB25)) -> 0.25086846 | Y25: 0.038 | Z25: 0.1 | AA25: 0.049 | AB25: =$AB$1/U25 -> 0.0024545455 | AC25: 0.06 | AF25: 原价进 | AG25: =MAX(AH25:AN25) -> 11.88 | AH25: =IF(U25>=50,MIN(MIN(U25*0.2,20)*0.3,6),0) -> 6 | AI25: =IF(U25>=200,MIN(MIN(U25*0.18,70)*0.3,21),0) -> 11.88 | AJ25: =IF(U25>=380,MIN(MIN(U25*0.28,350)*0.3,105),0) -> 0 | AK25: =IF(U25>=380,MIN(MIN(U25*0.25,350)*0.3,105),0) -> 0 | AL25: =IF(U25>=380,MIN(MIN(U25*0.22,300)*0.3,90),0) -> 0 | AM25: =IF(U25>=250,MIN(MIN(U25*0.18,120)*0.3,36),0) -> 0 | AN25: =IF(U25>=180,MIN(MIN(U25*0.15,60)*0.3,18),0) -> 9.9
A26: 办公安防 | B26: 智能安防 | C26: =_xlfn.XLOOKUP(F26,'6月产品包'!B:B,'6月产品包'!H:H) -> 摄像头 | D26: =_xlfn.XLOOKUP(F26,'6月产品包'!B:B,'6月产品包'!O:O) -> 太阳能摄像头 | E26: 3B-户外太阳能单板摄像头WiFi版 | F26: T3CC1950595 | G26: 灭款 | H26: MD | I26: =_xlfn.XLOOKUP($F26,'6月库存'!A:A,'6月库存'!B:B) -> 商品清仓 | K26: =_xlfn.XLOOKUP(E26,'[1]6月分配 '!$B:$B,'[1]6月分配 '!$K:$K) -> #N/A | L26: =IF(ISNUMBER(K26),"是",IF(ISNA(K26),"否","")) -> 否 | M26: =_xlfn.XLOOKUP(F26,'6月产品包'!B:B,'6月产品包'!J:J) -> 2024-03-26 | N26: =IF(DATEDIF(M26,TODAY(),"m")<6,"新品","老品") -> 老品 | O26: =_xlfn.XLOOKUP(F26,'6月库存'!A:A,'6月库存'!R:R) -> 14 | P26: =_xlfn.XLOOKUP(F26,'6月产品包'!B:B,'6月产品包'!S:S) -> 1400 | R26: =_xlfn.XLOOKUP(F26,'6月产品包'!B:B,'6月产品包'!AD:AD) -> 69.8668 | S26: 102 | T26: =ROUND(S26*(1+0.25),0) -> 128 | U26: =$T26*(1-0.2) -> 102.4 | V26: 0.2 | W26: =(U26-R26)/U26 -> 0.31770703 | X26: =(U26*(1-Y26-Z26-AA26-AC26-AB26)-R26)/(U26*(1-Y26-Z26-AA26-AC26-AB26)) -> 0.13930856 | Y26: 0.038 | Z26: 0.105 | AA26: 0.049 | AB26: =$AB$1/U26 -> 0.0052734375 | AC26: 0.01 | AF26: 不进 | AG26: =MAX(AH26:AN26) -> 6 | AH26: =IF(U26>=50,MIN(MIN(U26*0.2,20)*0.3,6),0) -> 6 | AI26: =IF(U26>=200,MIN(MIN(U26*0.18,70)*0.3,21),0) -> 0 | AJ26: =IF(U26>=380,MIN(MIN(U26*0.28,350)*0.3,105),0) -> 0 | AK26: =IF(U26>=380,MIN(MIN(U26*0.25,350)*0.3,105),0) -> 0 | AL26: =IF(U26>=380,MIN(MIN(U26*0.22,300)*0.3,90),0) -> 0 | AM26: =IF(U26>=250,MIN(MIN(U26*0.18,120)*0.3,36),0) -> 0 | AN26: =IF(U26>=180,MIN(MIN(U26*0.15,60)*0.3,18),0) -> 0
A27: 3C数码 | B27: 音响乐器 | C27: =_xlfn.XLOOKUP(F27,'6月产品包'!B:B,'6月产品包'!H:H) -> 电子琴 | D27: =_xlfn.XLOOKUP(F27,'6月产品包'!B:B,'6月产品包'!O:O) -> 折叠电子琴61键 | E27: 3C-折叠带蓝牙带琴谱架电子琴61键 | F27: M4CC2450780 | G27: 平销款 | H27: ZQ | I27: =_xlfn.XLOOKUP($F27,'6月库存'!A:A,'6月库存'!B:B) -> 正常销售 | K27: =_xlfn.XLOOKUP(E27,'[1]6月分配 '!$B:$B,'[1]6月分配 '!$K:$K) -> 49772 | L27: =IF(ISNUMBER(K27),"是",IF(ISNA(K27),"否","")) -> 是 | M27: =_xlfn.XLOOKUP(F27,'6月产品包'!B:B,'6月产品包'!J:J) -> 2025-10-09 | N27: 老品 | O27: =_xlfn.XLOOKUP(F27,'6月库存'!A:A,'6月库存'!R:R) -> 271 | P27: =_xlfn.XLOOKUP(F27,'6月产品包'!B:B,'6月产品包'!S:S) -> 3300 | R27: =_xlfn.XLOOKUP(F27,'6月产品包'!B:B,'6月产品包'!AD:AD) -> 95.1142 | S27: 207 | T27: =ROUND(S27*(1+0.25),0) -> 259 | U27: =$T27*(1-0.2) -> 207.2 | V27: 0.2 | W27: =(U27-R27)/U27 -> 0.54095463 | X27: =(U27*(1-Y27-Z27-AA27-AC27-AB27)-R27)/(U27*(1-Y27-Z27-AA27-AC27-AB27)) -> 0.38415727 | Y27: 0.038 | Z27: 0.105 | AA27: 0.049 | AB27: =$AB$1/U27 -> 0.0026061776 | AC27: 0.06 | AF27: 原价进 | AG27: =MAX(AH27:AN27) -> 11.1888 | AH27: =IF(U27>=50,MIN(MIN(U27*0.2,20)*0.3,6),0) -> 6 | AI27: =IF(U27>=200,MIN(MIN(U27*0.18,70)*0.3,21),0) -> 11.1888 | AJ27: =IF(U27>=380,MIN(MIN(U27*0.28,350)*0.3,105),0) -> 0 | AK27: =IF(U27>=380,MIN(MIN(U27*0.25,350)*0.3,105),0) -> 0 | AL27: =IF(U27>=380,MIN(MIN(U27*0.22,300)*0.3,90),0) -> 0 | AM27: =IF(U27>=250,MIN(MIN(U27*0.18,120)*0.3,36),0) -> 0 | AN27: =IF(U27>=180,MIN(MIN(U27*0.15,60)*0.3,18),0) -> 9.324
A28: 办公安防 | B28: 智能安防 | C28: =_xlfn.XLOOKUP(F28,'6月产品包'!B:B,'6月产品包'!H:H) -> 路由器 | D28: =_xlfn.XLOOKUP(F28,'6月产品包'!B:B,'6月产品包'!O:O) -> P6000路由器 | E28: 3B-路由器P6000白色 | F28: M2CC0180514 | G28: #N/A | H28: MD | I28: =_xlfn.XLOOKUP($F28,'6月库存'!A:A,'6月库存'!B:B) -> 商品清仓 | K28: =_xlfn.XLOOKUP(E28,'[1]6月分配 '!$B:$B,'[1]6月分配 '!$K:$K) -> 46767 | L28: =IF(ISNUMBER(K28),"是",IF(ISNA(K28),"否","")) -> 是 | M28: =_xlfn.XLOOKUP(F28,'6月产品包'!B:B,'6月产品包'!J:J) -> 2023-07-25 | N28: =IF(DATEDIF(M28,TODAY(),"m")<6,"新品","老品") -> 老品 | O28: =_xlfn.XLOOKUP(F28,'6月库存'!A:A,'6月库存'!R:R) -> 361 | P28: =_xlfn.XLOOKUP(F28,'6月产品包'!B:B,'6月产品包'!S:S) -> 300 | R28: =_xlfn.XLOOKUP(F28,'6月产品包'!B:B,'6月产品包'!AD:AD) -> 54.1952 | S28: 108 | T28: =ROUND(S28*(1+0.25),0) -> 135 | U28: =$T28*(1-0.2) -> 108 | V28: 0.2 | W28: =(U28-R28)/U28 -> 0.49819259 | X28: =(U28*(1-Y28-Z28-AA28-AC28-AB28)-R28)/(U28*(1-Y28-Z28-AA28-AC28-AB28)) -> 0.32461991 | Y28: 0.038 | Z28: 0.105 | AA28: 0.049 | AB28: =$AB$1/U28 -> 0.005 | AC28: 0.06 | AF28: 不进 | AG28: =MAX(AH28:AN28) -> 6 | AH28: =IF(U28>=50,MIN(MIN(U28*0.2,20)*0.3,6),0) -> 6 | AI28: =IF(U28>=200,MIN(MIN(U28*0.18,70)*0.3,21),0) -> 0 | AJ28: =IF(U28>=380,MIN(MIN(U28*0.28,350)*0.3,105),0) -> 0 | AK28: =IF(U28>=380,MIN(MIN(U28*0.25,350)*0.3,105),0) -> 0 | AL28: =IF(U28>=380,MIN(MIN(U28*0.22,300)*0.3,90),0) -> 0 | AM28: =IF(U28>=250,MIN(MIN(U28*0.18,120)*0.3,36),0) -> 0 | AN28: =IF(U28>=180,MIN(MIN(U28*0.15,60)*0.3,18),0) -> 0
A29: 办公安防 | B29: 安防存储 | C29: =_xlfn.XLOOKUP(F29,'6月产品包'!B:B,'6月产品包'!H:H) -> 保险箱 | D29: =_xlfn.XLOOKUP(F29,'6月产品包'!B:B,'6月产品包'!O:O) -> 液晶保险箱 | E29: 3B-液晶面板保险柜45cm*38cm*30cm | F29: T4CC2610739 | G29: 利润款 | H29: ZQ | I29: =_xlfn.XLOOKUP($F29,'6月库存'!A:A,'6月库存'!B:B) -> 正常销售 | K29: =_xlfn.XLOOKUP(E29,'[1]6月分配 '!$B:$B,'[1]6月分配 '!$K:$K) -> 44452 | L29: =IF(ISNUMBER(K29),"是",IF(ISNA(K29),"否","")) -> 是 | M29: =_xlfn.XLOOKUP(F29,'6月产品包'!B:B,'6月产品包'!J:J) -> 2025-11-13 | N29: =IF(DATEDIF(M29,TODAY(),"m")<6,"新品","老品") -> 老品 | O29: =_xlfn.XLOOKUP(F29,'6月库存'!A:A,'6月库存'!R:R) -> 191 | P29: =_xlfn.XLOOKUP(F29,'6月产品包'!B:B,'6月产品包'!S:S) -> 13950 | R29: =_xlfn.XLOOKUP(F29,'6月产品包'!B:B,'6月产品包'!AD:AD) -> 160.6368 | S29: 350 | T29: =ROUND(S29*(1+0.25),0) -> 438 | U29: =$T29*(1-0.2) -> 350.4 | V29: 0.2 | W29: =(U29-R29)/U29 -> 0.54156164 | X29: =(U29*(1-Y29-Z29-AA29-AC29-AB29)-R29)/(U29*(1-Y29-Z29-AA29-AC29-AB29)) -> 0.38993556 | Y29: 0.038 | Z29: 0.1 | AA29: 0.049 | AB29: =$AB$1/U29 -> 0.0015410959 | AC29: 0.06 | AF29: 原价进 | AG29: =MAX(AH29:AN29) -> 18.9216 | AH29: =IF(U29>=50,MIN(MIN(U29*0.2,20)*0.3,6),0) -> 6 | AI29: =IF(U29>=200,MIN(MIN(U29*0.18,70)*0.3,21),0) -> 18.9216 | AJ29: =IF(U29>=380,MIN(MIN(U29*0.28,350)*0.3,105),0) -> 0 | AK29: =IF(U29>=380,MIN(MIN(U29*0.25,350)*0.3,105),0) -> 0 | AL29: =IF(U29>=380,MIN(MIN(U29*0.22,300)*0.3,90),0) -> 0 | AM29: =IF(U29>=250,MIN(MIN(U29*0.18,120)*0.3,36),0) -> 18.9216 | AN29: =IF(U29>=180,MIN(MIN(U29*0.15,60)*0.3,18),0) -> 15.768
A30: 3C数码 | B30: 电脑周边 | C30: =_xlfn.XLOOKUP(F30,'6月产品包'!B:B,'6月产品包'!H:H) -> 显示器支架 | D30: =_xlfn.XLOOKUP(F30,'6月产品包'!B:B,'6月产品包'!O:O) -> 立式显示器支架 | E30: 3C-立式显示器支架不带托盘 | F30: T3CC1270257 | G30: 灭款 | H30: ZQ | I30: =_xlfn.XLOOKUP($F30,'6月库存'!A:A,'6月库存'!B:B) -> 正常销售 | K30: =_xlfn.XLOOKUP(E30,'[1]6月分配 '!$B:$B,'[1]6月分配 '!$K:$K) -> #N/A | L30: =IF(ISNUMBER(K30),"是",IF(ISNA(K30),"否","")) -> 否 | M30: =_xlfn.XLOOKUP(F30,'6月产品包'!B:B,'6月产品包'!J:J) -> 2024-11-12 | N30: =IF(DATEDIF(M30,TODAY(),"m")<6,"新品","老品") -> 老品 | O30: =_xlfn.XLOOKUP(F30,'6月库存'!A:A,'6月库存'!R:R) -> 0 | P30: =_xlfn.XLOOKUP(F30,'6月产品包'!B:B,'6月产品包'!S:S) -> 5500 | R30: =_xlfn.XLOOKUP(F30,'6月产品包'!B:B,'6月产品包'!AD:AD) -> 62.0716 | S30: 109 | T30: =ROUND(S30*(1+0.25),0) -> 136 | U30: =$T30*(1-0.2) -> 108.8 | V30: 0.2 | W30: =(U30-R30)/U30 -> 0.42948897 | X30: =(U30*(1-Y30-Z30-AA30-AC30-AB30)-R30)/(U30*(1-Y30-Z30-AA30-AC30-AB30)) -> 0.24738343 | Y30: 0.038 | Z30: 0.09 | AA30: 0.049 | AB30: =$AB$1/U30 -> 0.0049632353 | AC30: 0.06 | AF30: 不进 | AG30: =MAX(AH30:AN30) -> 6 | AH30: =IF(U30>=50,MIN(MIN(U30*0.2,20)*0.3,6),0) -> 6 | AI30: =IF(U30>=200,MIN(MIN(U30*0.18,70)*0.3,21),0) -> 0 | AJ30: =IF(U30>=380,MIN(MIN(U30*0.28,350)*0.3,105),0) -> 0 | AK30: =IF(U30>=380,MIN(MIN(U30*0.25,350)*0.3,105),0) -> 0 | AL30: =IF(U30>=380,MIN(MIN(U30*0.22,300)*0.3,90),0) -> 0 | AM30: =IF(U30>=250,MIN(MIN(U30*0.18,120)*0.3,36),0) -> 0 | AN30: =IF(U30>=180,MIN(MIN(U30*0.15,60)*0.3,18),0) -> 0
A31: 3C数码 | B31: 电脑周边 | C31: =_xlfn.XLOOKUP(F31,'6月产品包'!B:B,'6月产品包'!H:H) -> 显示器支架 | D31: =_xlfn.XLOOKUP(F31,'6月产品包'!B:B,'6月产品包'!O:O) -> 气钢单臂显示器支架 | E31: 3C-电脑显示器支架 | F31: T3CC1270169 | G31: 平销款 | H31: ZQ | I31: =_xlfn.XLOOKUP($F31,'6月库存'!A:A,'6月库存'!B:B) -> 正常销售 | K31: =_xlfn.XLOOKUP(E31,'[1]6月分配 '!$B:$B,'[1]6月分配 '!$K:$K) -> #N/A | L31: =IF(ISNUMBER(K31),"是",IF(ISNA(K31),"否","")) -> 否 | M31: =_xlfn.XLOOKUP(F31,'6月产品包'!B:B,'6月产品包'!J:J) -> 2024-10-10 | N31: =IF(DATEDIF(M31,TODAY(),"m")<6,"新品","老品") -> 老品 | O31: =_xlfn.XLOOKUP(F31,'6月库存'!A:A,'6月库存'!R:R) -> 1582 | P31: =_xlfn.XLOOKUP(F31,'6月产品包'!B:B,'6月产品包'!S:S) -> 2331 | R31: =_xlfn.XLOOKUP(F31,'6月产品包'!B:B,'6月产品包'!AD:AD) -> 30.7284 | S31: 65 | T31: =ROUND(S31*(1+0.25),0) -> 81 | U31: =$T31*(1-0.2) -> 64.8 | V31: 0.2 | W31: =(U31-R31)/U31 -> 0.5257963 | X31: =(U31*(1-Y31-Z31-AA31-AC31-AB31)-R31)/(U31*(1-Y31-Z31-AA31-AC31-AB31)) -> 0.3588954 | Y31: 0.038 | Z31: 0.105 | AA31: 0.049 | AB31: =$AB$1/U31 -> 0.0083333333 | AC31: 0.06 | AF31: 不进 | AG31: =MAX(AH31:AN31) -> 3.888 | AH31: =IF(U31>=50,MIN(MIN(U31*0.2,20)*0.3,6),0) -> 3.888 | AI31: =IF(U31>=200,MIN(MIN(U31*0.18,70)*0.3,21),0) -> 0 | AJ31: =IF(U31>=380,MIN(MIN(U31*0.28,350)*0.3,105),0) -> 0 | AK31: =IF(U31>=380,MIN(MIN(U31*0.25,350)*0.3,105),0) -> 0 | AL31: =IF(U31>=380,MIN(MIN(U31*0.22,300)*0.3,90),0) -> 0 | AM31: =IF(U31>=250,MIN(MIN(U31*0.18,120)*0.3,36),0) -> 0 | AN31: =IF(U31>=180,MIN(MIN(U31*0.15,60)*0.3,18),0) -> 0
A32: 3C数码 | B32: 电脑周边 | C32: =_xlfn.XLOOKUP(F32,'6月产品包'!B:B,'6月产品包'!H:H) -> 电脑机箱 | D32: =_xlfn.XLOOKUP(F32,'6月产品包'!B:B,'6月产品包'!O:O) -> 电脑机箱T6风扇款 | E32: 3C-电脑机箱T6款白色3风扇 | F32: T4CC2351009 | G32: 平销款 | H32: ZQ | I32: =_xlfn.XLOOKUP($F32,'6月库存'!A:A,'6月库存'!B:B) -> 正常销售 | K32: =_xlfn.XLOOKUP(E32,'[1]6月分配 '!$B:$B,'[1]6月分配 '!$K:$K) -> #N/A | L32: =IF(ISNUMBER(K32),"是",IF(ISNA(K32),"否","")) -> 否 | M32: =_xlfn.XLOOKUP(F32,'6月产品包'!B:B,'6月产品包'!J:J) -> 2025-12-23 | N32: =IF(DATEDIF(M32,TODAY(),"m")<6,"新品","老品") -> 新品 | O32: =_xlfn.XLOOKUP(F32,'6月库存'!A:A,'6月库存'!R:R) -> 13 | P32: =_xlfn.XLOOKUP(F32,'6月产品包'!B:B,'6月产品包'!S:S) -> 5890 | R32: =_xlfn.XLOOKUP(F32,'6月产品包'!B:B,'6月产品包'!AD:AD) -> 117.2586 | S32: 215 | T32: =ROUND(S32*(1+0.25),0) -> 269 | U32: =$T32*(1-0.2) -> 215.2 | V32: 0.2 | W32: =(U32-R32)/U32 -> 0.45511803 | X32: =(U32*(1-Y32-Z32-AA32-AC32-AB32)-R32)/(U32*(1-Y32-Z32-AA32-AC32-AB32)) -> 0.28539198 | Y32: 0.04 | Z32: 0.086 | AA32: 0.049 | AB32: =$AB$1/U32 -> 0.0025092937 | AC32: 0.06 | AF32: 不进 | AG32: =MAX(AH32:AN32) -> 11.6208 | AH32: =IF(U32>=50,MIN(MIN(U32*0.2,20)*0.3,6),0) -> 6 | AI32: =IF(U32>=200,MIN(MIN(U32*0.18,70)*0.3,21),0) -> 11.6208 | AJ32: =IF(U32>=380,MIN(MIN(U32*0.28,350)*0.3,105),0) -> 0 | AK32: =IF(U32>=380,MIN(MIN(U32*0.25,350)*0.3,105),0) -> 0 | AL32: =IF(U32>=380,MIN(MIN(U32*0.22,300)*0.3,90),0) -> 0 | AM32: =IF(U32>=250,MIN(MIN(U32*0.18,120)*0.3,36),0) -> 0 | AN32: =IF(U32>=180,MIN(MIN(U32*0.15,60)*0.3,18),0) -> 9.684
A33: =_xlfn.XLOOKUP(F33,'6月产品包'!B:B,'6月产品包'!F:F) -> 3C数码 | B33: =_xlfn.XLOOKUP(F33,'6月产品包'!B:B,'6月产品包'!G:G) -> 影像摄影 | C33: =_xlfn.XLOOKUP(F33,'6月产品包'!B:B,'6月产品包'!H:H) -> 家用音视频设备*投影仪 | D33: =_xlfn.XLOOKUP(F33,'6月产品包'!B:B,'6月产品包'!O:O) -> 投影仪Z300 | E33: =_xlfn.XLOOKUP(F33,'6月产品包'!B:B,'6月产品包'!C:C) -> 3C-高亮自动对焦灯带投影仪Z300 | F33: M5CC1721048 | G33: 利润款 | H33: MD | I33: =_xlfn.XLOOKUP($F33,'6月库存'!A:A,'6月库存'!B:B) -> 正常销售 | K33: =_xlfn.XLOOKUP(E33,'[1]6月分配 '!$B:$B,'[1]6月分配 '!$K:$K) -> 40438 | L33: =IF(ISNUMBER(K33),"是",IF(ISNA(K33),"否","")) -> 是 | M33: =_xlfn.XLOOKUP(F33,'6月产品包'!B:B,'6月产品包'!J:J) -> 2026-04-13 | N33: =IF(DATEDIF(M33,TODAY(),"m")<6,"新品","老品") -> 新品 | O33: =_xlfn.XLOOKUP(F33,'6月库存'!A:A,'6月库存'!R:R) -> 74 | P33: =_xlfn.XLOOKUP(F33,'6月产品包'!B:B,'6月产品包'!S:S) -> 1800 | R33: =_xlfn.XLOOKUP(F33,'6月产品包'!B:B,'6月产品包'!AD:AD) -> 234.5404 | S33: 489 | T33: =ROUND(S33*(1+0.25),0) -> 611 | U33: =$T33*(1-0.2) -> 488.8 | V33: 0.2 | W33: =(U33-R33)/U33 -> 0.52017103 | X33: =(U33*(1-Y33-Z33-AA33-AC33-AB33)-R33)/(U33*(1-Y33-Z33-AA33-AC33-AB33)) -> 0.30949454 | Y33: 0.04 | Z33: 0.115 | AA33: 0.049 | AB33: =$AB$1/U33 -> 0.0011047463 | AC33: 0.1 | AD33: 0.08 | AE33: 0.05 | AF33: 0.18 | AG33: =MAX(AH33:AN33) -> 41.0592 | AH33: =IF(U33>=50,MIN(MIN(U33*0.2,20)*0.3,6),0) -> 6 | AI33: =IF(U33>=200,MIN(MIN(U33*0.18,70)*0.3,21),0) -> 21 | AJ33: =IF(U33>=380,MIN(MIN(U33*0.28,350)*0.3,105),0) -> 41.0592 | AK33: =IF(U33>=380,MIN(MIN(U33*0.25,350)*0.3,105),0) -> 36.66 | AL33: =IF(U33>=380,MIN(MIN(U33*0.22,300)*0.3,90),0) -> 32.2608 | AM33: =IF(U33>=250,MIN(MIN(U33*0.18,120)*0.3,36),0) -> 26.3952 | AN33: =IF(U33>=180,MIN(MIN(U33*0.15,60)*0.3,18),0) -> 18
A34: 3C数码 | B34: 电脑周边 | C34: =_xlfn.XLOOKUP(F34,'6月产品包'!B:B,'6月产品包'!H:H) -> 显示器支架 | D34: =_xlfn.XLOOKUP(F34,'6月产品包'!B:B,'6月产品包'!O:O) -> 双臂显示器支架 | E34: 3C-双臂带托盘显示器支架 | F34: T2CC1270162 | G34: 平销款 | H34: ZQ | I34: =_xlfn.XLOOKUP($F34,'6月库存'!A:A,'6月库存'!B:B) -> 正常销售 | K34: =_xlfn.XLOOKUP(E34,'[1]6月分配 '!$B:$B,'[1]6月分配 '!$K:$K) -> #N/A | L34: =IF(ISNUMBER(K34),"是",IF(ISNA(K34),"否","")) -> 否 | M34: =_xlfn.XLOOKUP(F34,'6月产品包'!B:B,'6月产品包'!J:J) -> 2024-01-01 | N34: =IF(DATEDIF(M34,TODAY(),"m")<6,"新品","老品") -> 老品 | O34: =_xlfn.XLOOKUP(F34,'6月库存'!A:A,'6月库存'!R:R) -> 278 | P34: =_xlfn.XLOOKUP(F34,'6月产品包'!B:B,'6月产品包'!S:S) -> 4000 | R34: =_xlfn.XLOOKUP(F34,'6月产品包'!B:B,'6月产品包'!AD:AD) -> 41.9572 | S34: 78 | T34: =ROUND(S34*(1+0.25),0) -> 98 | U34: =$T34*(1-0.2) -> 78.4 | V34: 0.2 | W34: =(U34-R34)/U34 -> 0.46483163 | X34: =(U34*(1-Y34-Z34-AA34-AC34-AB34)-R34)/(U34*(1-Y34-Z34-AA34-AC34-AB34)) -> 0.27788487 | Y34: 0.038 | Z34: 0.105 | AA34: 0.049 | AB34: =$AB$1/U34 -> 0.0068877551 | AC34: 0.06 | AF34: 不进 | AG34: =MAX(AH34:AN34) -> 4.704 | AH34: =IF(U34>=50,MIN(MIN(U34*0.2,20)*0.3,6),0) -> 4.704 | AI34: =IF(U34>=200,MIN(MIN(U34*0.18,70)*0.3,21),0) -> 0 | AJ34: =IF(U34>=380,MIN(MIN(U34*0.28,350)*0.3,105),0) -> 0 | AK34: =IF(U34>=380,MIN(MIN(U34*0.25,350)*0.3,105),0) -> 0 | AL34: =IF(U34>=380,MIN(MIN(U34*0.22,300)*0.3,90),0) -> 0 | AM34: =IF(U34>=250,MIN(MIN(U34*0.18,120)*0.3,36),0) -> 0 | AN34: =IF(U34>=180,MIN(MIN(U34*0.15,60)*0.3,18),0) -> 0
A35: 3C数码 | B35: 电视设备 | C35: =_xlfn.XLOOKUP(F35,'6月产品包'!B:B,'6月产品包'!H:H) -> 电视支架 | D35: =_xlfn.XLOOKUP(F35,'6月产品包'!B:B,'6月产品包'!O:O) -> 移动电视支架 | E35: 3C-32英寸到55英寸带中托可移动电视支架 | F35: T4CC1120706 | G35: 平销款 | H35: ZQ | I35: =_xlfn.XLOOKUP($F35,'6月库存'!A:A,'6月库存'!B:B) -> 正常销售 | K35: =_xlfn.XLOOKUP(E35,'[1]6月分配 '!$B:$B,'[1]6月分配 '!$K:$K) -> 38775 | L35: =IF(ISNUMBER(K35),"是",IF(ISNA(K35),"否","")) -> 是 | M35: =_xlfn.XLOOKUP(F35,'6月产品包'!B:B,'6月产品包'!J:J) -> 2025-04-24 | N35: 老品 | O35: =_xlfn.XLOOKUP(F35,'6月库存'!A:A,'6月库存'!R:R) -> 453 | P35: =_xlfn.XLOOKUP(F35,'6月产品包'!B:B,'6月产品包'!S:S) -> 9400 | R35: =_xlfn.XLOOKUP(F35,'6月产品包'!B:B,'6月产品包'!AD:AD) -> 71.5082 | S35: 129 | T35: =ROUND(S35*(1+0.25),0) -> 161 | U35: =$T35*(1-0.2) -> 128.8 | V35: 0.2 | W35: =(U35-R35)/U35 -> 0.44481211 | X35: =(U35*(1-Y35-Z35-AA35-AC35-AB35)-R35)/(U35*(1-Y35-Z35-AA35-AC35-AB35)) -> 0.26834155 | Y35: 0.038 | Z35: 0.09 | AA35: 0.049 | AB35: =$AB$1/U35 -> 0.0041925466 | AC35: 0.06 | AF35: 原价进 | AG35: =MAX(AH35:AN35) -> 6 | AH35: =IF(U35>=50,MIN(MIN(U35*0.2,20)*0.3,6),0) -> 6 | AI35: =IF(U35>=200,MIN(MIN(U35*0.18,70)*0.3,21),0) -> 0 | AJ35: =IF(U35>=380,MIN(MIN(U35*0.28,350)*0.3,105),0) -> 0 | AK35: =IF(U35>=380,MIN(MIN(U35*0.25,350)*0.3,105),0) -> 0 | AL35: =IF(U35>=380,MIN(MIN(U35*0.22,300)*0.3,90),0) -> 0 | AM35: =IF(U35>=250,MIN(MIN(U35*0.18,120)*0.3,36),0) -> 0 | AN35: =IF(U35>=180,MIN(MIN(U35*0.15,60)*0.3,18),0) -> 0
A36: 办公安防 | B36: 安防存储 | C36: =_xlfn.XLOOKUP(F36,'6月产品包'!B:B,'6月产品包'!H:H) -> 保险柜 | D36: =_xlfn.XLOOKUP(F36,'6月产品包'!B:B,'6月产品包'!O:O) -> XT保险箱密码款 | E36: 3B-XT保险箱45*38*32cm灰白色密码款 | F36: T4CC2610979 | G36: 利润款 | H36: ZQ | I36: =_xlfn.XLOOKUP($F36,'6月库存'!A:A,'6月库存'!B:B) -> 正常销售 | K36: =_xlfn.XLOOKUP(E36,'[1]6月分配 '!$B:$B,'[1]6月分配 '!$K:$K) -> 36560 | L36: =IF(ISNUMBER(K36),"是",IF(ISNA(K36),"否","")) -> 是 | M36: =_xlfn.XLOOKUP(F36,'6月产品包'!B:B,'6月产品包'!J:J) -> 2025-12-02 | N36: =IF(DATEDIF(M36,TODAY(),"m")<6,"新品","老品") -> 老品 | O36: =_xlfn.XLOOKUP(F36,'6月库存'!A:A,'6月库存'!R:R) -> 95 | P36: =_xlfn.XLOOKUP(F36,'6月产品包'!B:B,'6月产品包'!S:S) -> 15000 | R36: =_xlfn.XLOOKUP(F36,'6月产品包'!B:B,'6月产品包'!AD:AD) -> 157.6556 | S36: 339 | T36: =ROUND(S36*(1+0.25),0) -> 424 | U36: =$T36*(1-0.2) -> 339.2 | V36: 0.2 | W36: =(U36-R36)/U36 -> 0.53521344 | X36: =(U36*(1-Y36-Z36-AA36-AC36-AB36)-R36)/(U36*(1-Y36-Z36-AA36-AC36-AB36)) -> 0.38956966 | Y36: 0.038 | Z36: 0.09 | AA36: 0.049 | AB36: =$AB$1/U36 -> 0.0015919811 | AC36: 0.06 | AF36: 原价进 | AG36: =MAX(AH36:AN36) -> 18.3168 | AH36: =IF(U36>=50,MIN(MIN(U36*0.2,20)*0.3,6),0) -> 6 | AI36: =IF(U36>=200,MIN(MIN(U36*0.18,70)*0.3,21),0) -> 18.3168 | AJ36: =IF(U36>=380,MIN(MIN(U36*0.28,350)*0.3,105),0) -> 0 | AK36: =IF(U36>=380,MIN(MIN(U36*0.25,350)*0.3,105),0) -> 0 | AL36: =IF(U36>=380,MIN(MIN(U36*0.22,300)*0.3,90),0) -> 0 | AM36: =IF(U36>=250,MIN(MIN(U36*0.18,120)*0.3,36),0) -> 18.3168 | AN36: =IF(U36>=180,MIN(MIN(U36*0.15,60)*0.3,18),0) -> 15.264
A37: 办公安防 | B37: 智能安防 | C37: =_xlfn.XLOOKUP(F37,'6月产品包'!B:B,'6月产品包'!H:H) -> 密码锁 | D37: =_xlfn.XLOOKUP(F37,'6月产品包'!B:B,'6月产品包'!O:O) -> R4A房间门锁单锁舌五功能带APP | E37: 3B-R4A房间门锁单锁舌五功能带APP | F37: T4CC2530877 | G37: 利润款 | H37: ZQ | I37: =_xlfn.XLOOKUP($F37,'6月库存'!A:A,'6月库存'!B:B) -> 正常销售 | K37: =_xlfn.XLOOKUP(E37,'[1]6月分配 '!$B:$B,'[1]6月分配 '!$K:$K) -> #N/A | L37: =IF(ISNUMBER(K37),"是",IF(ISNA(K37),"否","")) -> 否 | M37: =_xlfn.XLOOKUP(F37,'6月产品包'!B:B,'6月产品包'!J:J) -> 2025-10-30 | N37: =IF(DATEDIF(M37,TODAY(),"m")<6,"新品","老品") -> 老品 | O37: =_xlfn.XLOOKUP(F37,'6月库存'!A:A,'6月库存'!R:R) -> 1 | P37: =_xlfn.XLOOKUP(F37,'6月产品包'!B:B,'6月产品包'!S:S) -> 1631 | R37: =_xlfn.XLOOKUP(F37,'6月产品包'!B:B,'6月产品包'!AD:AD) -> 79.663 | S37: 169 | T37: =ROUND(S37*(1+0.25),0) -> 211 | U37: =$T37*(1-0.2) -> 168.8 | V37: 0.2 | W37: =(U37-R37)/U37 -> 0.5280628 | X37: =(U37*(1-Y37-Z37-AA37-AC37-AB37)-R37)/(U37*(1-Y37-Z37-AA37-AC37-AB37)) -> 0.35773463 | Y37: 0.038 | Z37: 0.115 | AA37: 0.049 | AB37: =$AB$1/U37 -> 0.0031990521 | AC37: 0.06 | AF37: 不进 | AG37: =MAX(AH37:AN37) -> 6 | AH37: =IF(U37>=50,MIN(MIN(U37*0.2,20)*0.3,6),0) -> 6 | AI37: =IF(U37>=200,MIN(MIN(U37*0.18,70)*0.3,21),0) -> 0 | AJ37: =IF(U37>=380,MIN(MIN(U37*0.28,350)*0.3,105),0) -> 0 | AK37: =IF(U37>=380,MIN(MIN(U37*0.25,350)*0.3,105),0) -> 0 | AL37: =IF(U37>=380,MIN(MIN(U37*0.22,300)*0.3,90),0) -> 0 | AM37: =IF(U37>=250,MIN(MIN(U37*0.18,120)*0.3,36),0) -> 0 | AN37: =IF(U37>=180,MIN(MIN(U37*0.15,60)*0.3,18),0) -> 0
A38: 3C数码 | B38: 电脑周边 | C38: =_xlfn.XLOOKUP(F38,'6月产品包'!B:B,'6月产品包'!H:H) -> 电脑机箱 | D38: =_xlfn.XLOOKUP(F38,'6月产品包'!B:B,'6月产品包'!O:O) -> 电脑机箱T6款 | E38: 3C-电脑机箱T6款白色 | F38: T4CC2351007 | G38: 平销款 | H38: ZQ | I38: =_xlfn.XLOOKUP($F38,'6月库存'!A:A,'6月库存'!B:B) -> 正常销售 | K38: =_xlfn.XLOOKUP(E38,'[1]6月分配 '!$B:$B,'[1]6月分配 '!$K:$K) -> #N/A | L38: =IF(ISNUMBER(K38),"是",IF(ISNA(K38),"否","")) -> 否 | M38: =_xlfn.XLOOKUP(F38,'6月产品包'!B:B,'6月产品包'!J:J) -> 2025-12-23 | N38: =IF(DATEDIF(M38,TODAY(),"m")<6,"新品","老品") -> 新品 | O38: =_xlfn.XLOOKUP(F38,'6月库存'!A:A,'6月库存'!R:R) -> 5 | P38: =_xlfn.XLOOKUP(F38,'6月产品包'!B:B,'6月产品包'!S:S) -> 5250 | R38: =_xlfn.XLOOKUP(F38,'6月产品包'!B:B,'6月产品包'!AD:AD) -> 91.8836 | S38: 178 | T38: =ROUND(S38*(1+0.25),0) -> 223 | U38: =$T38*(1-0.2) -> 178.4 | V38: 0.2 | W38: =(U38-R38)/U38 -> 0.4849574 | X38: =(U38*(1-Y38-Z38-AA38-AC38-AB38)-R38)/(U38*(1-Y38-Z38-AA38-AC38-AB38)) -> 0.32406721 | Y38: 0.04 | Z38: 0.086 | AA38: 0.049 | AB38: =$AB$1/U38 -> 0.0030269058 | AC38: 0.06 | AF38: 不进 | AG38: =MAX(AH38:AN38) -> 6 | AH38: =IF(U38>=50,MIN(MIN(U38*0.2,20)*0.3,6),0) -> 6 | AI38: =IF(U38>=200,MIN(MIN(U38*0.18,70)*0.3,21),0) -> 0 | AJ38: =IF(U38>=380,MIN(MIN(U38*0.28,350)*0.3,105),0) -> 0 | AK38: =IF(U38>=380,MIN(MIN(U38*0.25,350)*0.3,105),0) -> 0 | AL38: =IF(U38>=380,MIN(MIN(U38*0.22,300)*0.3,90),0) -> 0 | AM38: =IF(U38>=250,MIN(MIN(U38*0.18,120)*0.3,36),0) -> 0 | AN38: =IF(U38>=180,MIN(MIN(U38*0.15,60)*0.3,18),0) -> 0
A39: 办公安防 | B39: 安防存储 | C39: =_xlfn.XLOOKUP(F39,'6月产品包'!B:B,'6月产品包'!H:H) -> 保险箱 | D39: =_xlfn.XLOOKUP(F39,'6月产品包'!B:B,'6月产品包'!O:O) -> 液晶面板保险柜密码A15款 | E39: 3B-液晶面板保险柜密码A15款 | F39: T4CC2610898 | G39: 利润款 | H39: MD | I39: =_xlfn.XLOOKUP($F39,'6月库存'!A:A,'6月库存'!B:B) -> 正常销售 | K39: =_xlfn.XLOOKUP(E39,'[1]6月分配 '!$B:$B,'[1]6月分配 '!$K:$K) -> 29786 | L39: =IF(ISNUMBER(K39),"是",IF(ISNA(K39),"否","")) -> 是 | M39: =_xlfn.XLOOKUP(F39,'6月产品包'!B:B,'6月产品包'!J:J) -> 2025-10-27 | N39: =IF(DATEDIF(M39,TODAY(),"m")<6,"新品","老品") -> 老品 | O39: =_xlfn.XLOOKUP(F39,'6月库存'!A:A,'6月库存'!R:R) -> 204 | P39: =_xlfn.XLOOKUP(F39,'6月产品包'!B:B,'6月产品包'!S:S) -> 15000 | R39: =_xlfn.XLOOKUP(F39,'6月产品包'!B:B,'6月产品包'!AD:AD) -> 134.9718 | S39: 290 | T39: =ROUND(S39*(1+0.25),0) -> 363 | U39: =$T39*(1-0.2) -> 290.4 | V39: 0.2 | W39: =(U39-R39)/U39 -> 0.53522107 | X39: =(U39*(1-Y39-Z39-AA39-AC39-AB39)-R39)/(U39*(1-Y39-Z39-AA39-AC39-AB39)) -> 0.3812357 | Y39: 0.038 | Z39: 0.1 | AA39: 0.049 | AB39: =$AB$1/U39 -> 0.0018595041 | AC39: 0.06 | AF39: 原价进 | AG39: =MAX(AH39:AN39) -> 15.6816 | AH39: =IF(U39>=50,MIN(MIN(U39*0.2,20)*0.3,6),0) -> 6 | AI39: =IF(U39>=200,MIN(MIN(U39*0.18,70)*0.3,21),0) -> 15.6816 | AJ39: =IF(U39>=380,MIN(MIN(U39*0.28,350)*0.3,105),0) -> 0 | AK39: =IF(U39>=380,MIN(MIN(U39*0.25,350)*0.3,105),0) -> 0 | AL39: =IF(U39>=380,MIN(MIN(U39*0.22,300)*0.3,90),0) -> 0 | AM39: =IF(U39>=250,MIN(MIN(U39*0.18,120)*0.3,36),0) -> 15.6816 | AN39: =IF(U39>=180,MIN(MIN(U39*0.15,60)*0.3,18),0) -> 13.068
